Workbook

Sheet etat_receveur

Sheet BUS
X2: شهر | DY2: شهر
D5: matin
A6: JOUR | B6: A01 | E6: A02 | H6: A03 | K6: A04 | N6: A05 | Q6: A06 | T6: A07 | W6: A08 | Z6: A09 | AC6: A10 | AF6: A11 | AI6: A12 | AL6: A13 | AO6: A14 | AR6: A15 | AU6: A16 | AX6: A17 | BA6: A18 | BD6: A19 | BG6: A20 | BJ6: A21 | BM6: A22 | BP6: A23 | BS6: A24 | BV6: A25 | BY6: A26 | CB6: A27 | CE6: A28 | CH6: A29 | CK6: A30 | CN6: A31 | CQ6: A32 | CT6: A33 | CW6: A34 | CZ6: A35 | DC6: A36 | DF6: A37 | DI6: A38 | DL6: A39 | DO6: A40 | DR6: A41 | DU6: A42 | DX6: A43 | EA6: A44 | ED6: A45 | EG6: A46 | EJ6: A47 | EM6: A48 | EP6: A49 | ES6: A50 | EV6: A51 | EY6: A52 | FB6: A53 | FE6: A54 | FH6: A55 | FK6: A56 | FN6: A57 | FQ6: A58 | FT6: A59 | FW6: A60 | FZ6: A61 | GC6: A62 | GF6: A63 | GI6: A64 | GL6: A65 | GO6: A66 | GR6: A67 | GU6: A68 | GX6: A69 | HA6: A70 | HD6: TOTAL PAR TARIF
B7: 20DA | C7: 25DA | D7: 30DA | E7: 20DA | F7: 25DA | G7: 30DA | H7: 20DA | I7: 25DA | J7: 30DA | K7: 20DA | L7: 25DA | M7: 30DA | N7: 20DA | O7: 25DA | P7: 30DA | Q7: 20DA | R7: 25DA | S7: 30DA | T7: 20DA | U7: 25DA | V7: 30DA | W7: 20DA | X7: 25DA | Y7: 30DA | Z7: 20DA | AA7: 25DA | AB7: 30DA | AC7: 20DA | AD7: 25DA | AE7: 30DA | AF7: 20DA | AG7: 25DA | AH7: 30DA | AI7: 20DA | AJ7: 25DA | AK7: 30DA | AL7: 20DA | AM7: 25DA | AN7: 30DA | AO7: 20DA | AP7: 25DA | AQ7: 30DA | AR7: 20DA | AS7: 25DA | AT7: 30DA | AU7: 20DA | AV7: 25DA | AW7: 30DA | AX7: 20DA | AY7: 25DA | AZ7: 30DA | BA7: 20DA | BB7: 25DA | BC7: 30DA | BD7: 20DA | BE7: 25DA | BF7: 30DA | BG7: 20DA | BH7: 25DA | BI7: 30DA | BJ7: 20DA | BK7: 25DA | BL7: 30DA | BM7: 20DA | BN7: 25DA | BO7: 30DA | BP7: 20DA | BQ7: 25DA | BR7: 30DA | BS7: 20DA | BT7: 25DA | BU7: 30DA | BV7: 20DA | BW7: 25DA | BX7: 30DA | BY7: 20DA | BZ7: 25DA | CA7: 30DA | CB7: 20DA | CC7: 25DA | CD7: 30DA | CE7: 20DA | CF7: 25DA | CG7: 30DA | CH7: 20DA | CI7: 25DA | CJ7: 30DA | CK7: 20DA | CL7: 25DA | CM7: 30DA | CN7: 20DA | CO7: 25DA | CP7: 30DA | CQ7: 20DA | CR7: 25DA | CS7: 30DA | CT7: 20DA | CU7: 25DA | CV7: 30DA | CW7: 20DA | CX7: 25DA | CY7: 30DA | CZ7: 20DA | DA7: 25DA | DB7: 30DA | DC7: 20DA | DD7: 25DA | DE7: 30DA | DF7: 20DA | DG7: 25DA | DH7: 30DA | DI7: 20DA | DJ7: 25DA | DK7: 30DA | DL7: 20DA | DM7: 25DA | DN7: 30DA | DO7: 20DA | DP7: 25DA | DQ7: 30DA | DR7: 20DA | DS7: 25DA | DT7: 30DA | DU7: 20DA | DV7: 25DA | DW7: 30DA | DX7: 20DA | DY7: 25DA | DZ7: 30DA | EA7: 20DA | EB7: 25DA | EC7: 30DA | ED7: 20DA | EE7: 25DA | EF7: 30DA | EG7: 20DA | EH7: 25DA | EI7: 30DA | EJ7: 20DA | EK7: 25DA | EL7: 30DA | EM7: 20DA | EN7: 25DA | EO7: 30DA | EP7: 20DA | EQ7: 25DA | ER7: 30DA | ES7: 20DA | ET7: 25DA | EU7: 30DA | EV7: 20DA | EW7: 25DA | EX7: 30DA | EY7: 20DA | EZ7: 25DA | FA7: 30DA | FB7: 20DA | FC7: 25DA | FD7: 30DA | FE7: 20DA | FF7: 25DA | FG7: 30DA | FH7: 20DA | FI7: 25DA | FJ7: 30DA | FK7: 20DA | FL7: 25DA | FM7: 30DA | FN7: 20DA | FO7: 25DA | FP7: 30DA | FQ7: 20DA | FR7: 25DA | FS7: 30DA | FT7: 20DA | FU7: 25DA | FV7: 30DA | FW7: 20DA | FX7: 25DA | FY7: 30DA | FZ7: 20DA | GA7: 25DA | GB7: 30DA | GC7: 20DA | GD7: 25DA | GE7: 30DA | GF7: 20DA | GG7: 25DA | GH7: 30DA | GI7: 20DA | GJ7: 25DA | GK7: 30DA | GL7: 20DA | GM7: 25DA | GN7: 30DA | GO7: 20DA | GP7: 25DA | GQ7: 30DA | GR7: 20DA | GS7: 25DA | GT7: 30DA | GU7: 20DA | GV7: 25DA | GW7: 30DA | GX7: 20DA | GY7: 25DA | GZ7: 30DA | HA7: 20DA | HB7: 25DA | HC7: 30DA | HD7: 20DA | HE7: 25DA | HF7: 30DA
A8: 1 | HD8: =+B8+E8+H8+K8+N8+Q8+T8+W8+Z8+AC8+AF8+AI8+AL8+AO8+AR8+AU8+AX8+BA8+BD8+BG8+BJ8+BM8+BP8+BS8+BV8+BY8+CB8+CE8+CH8+CK8+CN8+CZ8+CQ8+CT8+CW8+DC8+DF8+DI8+DL8+DO8+DR8+DU8+DX8+EA8+ED8+EG8+EJ8+EM8+EP8+ES8+EV8+EY8+FB8+FE8+FH8+FK8+FN8+FQ8+FT8+FW8+FZ8+GC8+GF8+GI8+GL8+GO8+GR8+GU8+GX8+HA8 -> 0 | HE8: =+C8+F8+I8+L8+O8+R8+U8+X8+AA8+AD8+AG8+AJ8+AM8+AP8+AS8+AV8+AY8+BB8+BE8+BH8+BK8+BN8+BQ8+BT8+BW8+BZ8+CC8+CF8+CI8+CL8+CO8+DA8+CR8+CU8+CX8+DD8+DG8+DJ8+DM8+DP8+DS8+DV8+DY8+EB8+EE8+EH8+EK8+EN8+EQ8+ET8+EW8+EZ8+FC8+FF8+FI8+FL8+FO8+FR8+FU8+FX8+GA8+GD8+GG8+GJ8+GM8+GP8+GS8+GV8+GY8+HB8 -> 0 | HF8: =+D8+G8+J8+M8+P8+S8+V8+Y8+AE8+AH8+AK8+AQ8+AT8+AW8+AZ8+BC8+BF8+BI8+BL8+BO8+BR8+BU8+BX8+CA8+CD8+CG8+CJ8+CM8+CP8+DB8+AB8+AN8+CS8+CV8+CY8+DE8+DH8+DK8+DN8+DQ8+DT8+DW8+DZ8+EC8+EF8+EI8+EL8+EO8+ER8+EU8+EX8+FA8+FD8+FG8+FJ8+FM8+FP8+FS8+FV8+FY8+GB8+GE8+GH8+GK8+GN8+GQ8+GT8+GW8+GZ8+HC8 -> 0
A9: 2 | HD9: =+B9+E9+H9+K9+N9+Q9+T9+W9+Z9+AC9+AF9+AI9+AL9+AO9+AR9+AU9+AX9+BA9+BD9+BG9+BJ9+BM9+BP9+BS9+BV9+BY9+CB9+CE9+CH9+CK9+CN9+CZ9+CQ9+CT9+CW9+DC9+DF9+DI9+DL9+DO9+DR9+DU9+DX9+EA9+ED9+EG9+EJ9+EM9+EP9+ES9+EV9+EY9+FB9+FE9+FH9+FK9+FN9+FQ9+FT9+FW9+FZ9+GC9+GF9+GI9+GL9+GO9+GR9+GU9+GX9+HA9 -> 0 | HE9: =+C9+F9+I9+L9+O9+R9+U9+X9+AA9+AD9+AG9+AJ9+AM9+AP9+AS9+AV9+AY9+BB9+BE9+BH9+BK9+BN9+BQ9+BT9+BW9+BZ9+CC9+CF9+CI9+CL9+CO9+DA9+CR9+CU9+CX9+DD9+DG9+DJ9+DM9+DP9+DS9+DV9+DY9+EB9+EE9+EH9+EK9+EN9+EQ9+ET9+EW9+EZ9+FC9+FF9+FI9+FL9+FO9+FR9+FU9+FX9+GA9+GD9+GG9+GJ9+GM9+GP9+GS9+GV9+GY9+HB9 -> 0 | HF9: =+D9+G9+J9+M9+P9+S9+V9+Y9+AE9+AH9+AK9+AQ9+AT9+AW9+AZ9+BC9+BF9+BI9+BL9+BO9+BR9+BU9+BX9+CA9+CD9+CG9+CJ9+CM9+CP9+DB9+AB9+AN9+CS9+CV9+CY9+DE9+DH9+DK9+DN9+DQ9+DT9+DW9+DZ9+EC9+EF9+EI9+EL9+EO9+ER9+EU9+EX9+FA9+FD9+FG9+FJ9+FM9+FP9+FS9+FV9+FY9+GB9+GE9+GH9+GK9+GN9+GQ9+GT9+GW9+GZ9+HC9 -> 0
A10: 3 | HD10: =+B10+E10+H10+K10+N10+Q10+T10+W10+Z10+AC10+AF10+AI10+AL10+AO10+AR10+AU10+AX10+BA10+BD10+BG10+BJ10+BM10+BP10+BS10+BV10+BY10+CB10+CE10+CH10+CK10+CN10+CZ10+CQ10+CT10+CW10+DC10+DF10+DI10+DL10+DO10+DR10+DU10+DX10+EA10+ED10+EG10+EJ10+EM10+EP10+ES10+EV10+EY10+FB10+FE10+FH10+FK10+FN10+FQ10+FT10+FW10+FZ10+GC10+GF10+GI10+GL10+GO10+GR10+GU10+GX10+HA10 -> 0 | HE10: =+C10+F10+I10+L10+O10+R10+U10+X10+AA10+AD10+AG10+AJ10+AM10+AP10+AS10+AV10+AY10+BB10+BE10+BH10+BK10+BN10+BQ10+BT10+BW10+BZ10+CC10+CF10+CI10+CL10+CO10+DA10+CR10+CU10+CX10+DD10+DG10+DJ10+DM10+DP10+DS10+DV10+DY10+EB10+EE10+EH10+EK10+EN10+EQ10+ET10+EW10+EZ10+FC10+FF10+FI10+FL10+FO10+FR10+FU10+FX10+GA10+GD10+GG10+GJ10+GM10+GP10+GS10+GV10+GY10+HB10 -> 0 | HF10: =+D10+G10+J10+M10+P10+S10+V10+Y10+AE10+AH10+AK10+AQ10+AT10+AW10+AZ10+BC10+BF10+BI10+BL10+BO10+BR10+BU10+BX10+CA10+CD10+CG10+CJ10+CM10+CP10+DB10+AB10+AN10+CS10+CV10+CY10+DE10+DH10+DK10+DN10+DQ10+DT10+DW10+DZ10+EC10+EF10+EI10+EL10+EO10+ER10+EU10+EX10+FA10+FD10+FG10+FJ10+FM10+FP10+FS10+FV10+FY10+GB10+GE10+GH10+GK10+GN10+GQ10+GT10+GW10+GZ10+HC10 -> 0
A11: 4 | HD11: =+B11+E11+H11+K11+N11+Q11+T11+W11+Z11+AC11+AF11+AI11+AL11+AO11+AR11+AU11+AX11+BA11+BD11+BG11+BJ11+BM11+BP11+BS11+BV11+BY11+CB11+CE11+CH11+CK11+CN11+CZ11+CQ11+CT11+CW11+DC11+DF11+DI11+DL11+DO11+DR11+DU11+DX11+EA11+ED11+EG11+EJ11+EM11+EP11+ES11+EV11+EY11+FB11+FE11+FH11+FK11+FN11+FQ11+FT11+FW11+FZ11+GC11+GF11+GI11+GL11+GO11+GR11+GU11+GX11+HA11 -> 0 | HE11: =+C11+F11+I11+L11+O11+R11+U11+X11+AA11+AD11+AG11+AJ11+AM11+AP11+AS11+AV11+AY11+BB11+BE11+BH11+BK11+BN11+BQ11+BT11+BW11+BZ11+CC11+CF11+CI11+CL11+CO11+DA11+CR11+CU11+CX11+DD11+DG11+DJ11+DM11+DP11+DS11+DV11+DY11+EB11+EE11+EH11+EK11+EN11+EQ11+ET11+EW11+EZ11+FC11+FF11+FI11+FL11+FO11+FR11+FU11+FX11+GA11+GD11+GG11+GJ11+GM11+GP11+GS11+GV11+GY11+HB11 -> 0 | HF11: =+D11+G11+J11+M11+P11+S11+V11+Y11+AE11+AH11+AK11+AQ11+AT11+AW11+AZ11+BC11+BF11+BI11+BL11+BO11+BR11+BU11+BX11+CA11+CD11+CG11+CJ11+CM11+CP11+DB11+AB11+AN11+CS11+CV11+CY11+DE11+DH11+DK11+DN11+DQ11+DT11+DW11+DZ11+EC11+EF11+EI11+EL11+EO11+ER11+EU11+EX11+FA11+FD11+FG11+FJ11+FM11+FP11+FS11+FV11+FY11+GB11+GE11+GH11+GK11+GN11+GQ11+GT11+GW11+GZ11+HC11 -> 0
A12: 5 | HD12: =+B12+E12+H12+K12+N12+Q12+T12+W12+Z12+AC12+AF12+AI12+AL12+AO12+AR12+AU12+AX12+BA12+BD12+BG12+BJ12+BM12+BP12+BS12+BV12+BY12+CB12+CE12+CH12+CK12+CN12+CZ12+CQ12+CT12+CW12+DC12+DF12+DI12+DL12+DO12+DR12+DU12+DX12+EA12+ED12+EG12+EJ12+EM12+EP12+ES12+EV12+EY12+FB12+FE12+FH12+FK12+FN12+FQ12+FT12+FW12+FZ12+GC12+GF12+GI12+GL12+GO12+GR12+GU12+GX12+HA12 -> 0 | HE12: =+C12+F12+I12+L12+O12+R12+U12+X12+AA12+AD12+AG12+AJ12+AM12+AP12+AS12+AV12+AY12+BB12+BE12+BH12+BK12+BN12+BQ12+BT12+BW12+BZ12+CC12+CF12+CI12+CL12+CO12+DA12+CR12+CU12+CX12+DD12+DG12+DJ12+DM12+DP12+DS12+DV12+DY12+EB12+EE12+EH12+EK12+EN12+EQ12+ET12+EW12+EZ12+FC12+FF12+FI12+FL12+FO12+FR12+FU12+FX12+GA12+GD12+GG12+GJ12+GM12+GP12+GS12+GV12+GY12+HB12 -> 0 | HF12: =+D12+G12+J12+M12+P12+S12+V12+Y12+AE12+AH12+AK12+AQ12+AT12+AW12+AZ12+BC12+BF12+BI12+BL12+BO12+BR12+BU12+BX12+CA12+CD12+CG12+CJ12+CM12+CP12+DB12+AB12+AN12+CS12+CV12+CY12+DE12+DH12+DK12+DN12+DQ12+DT12+DW12+DZ12+EC12+EF12+EI12+EL12+EO12+ER12+EU12+EX12+FA12+FD12+FG12+FJ12+FM12+FP12+FS12+FV12+FY12+GB12+GE12+GH12+GK12+GN12+GQ12+GT12+GW12+GZ12+HC12 -> 0
A13: 6 | HD13: =+B13+E13+H13+K13+N13+Q13+T13+W13+Z13+AC13+AF13+AI13+AL13+AO13+AR13+AU13+AX13+BA13+BD13+BG13+BJ13+BM13+BP13+BS13+BV13+BY13+CB13+CE13+CH13+CK13+CN13+CZ13+CQ13+CT13+CW13+DC13+DF13+DI13+DL13+DO13+DR13+DU13+DX13+EA13+ED13+EG13+EJ13+EM13+EP13+ES13+EV13+EY13+FB13+FE13+FH13+FK13+FN13+FQ13+FT13+FW13+FZ13+GC13+GF13+GI13+GL13+GO13+GR13+GU13+GX13+HA13 -> 0 | HE13: =+C13+F13+I13+L13+O13+R13+U13+X13+AA13+AD13+AG13+AJ13+AM13+AP13+AS13+AV13+AY13+BB13+BE13+BH13+BK13+BN13+BQ13+BT13+BW13+BZ13+CC13+CF13+CI13+CL13+CO13+DA13+CR13+CU13+CX13+DD13+DG13+DJ13+DM13+DP13+DS13+DV13+DY13+EB13+EE13+EH13+EK13+EN13+EQ13+ET13+EW13+EZ13+FC13+FF13+FI13+FL13+FO13+FR13+FU13+FX13+GA13+GD13+GG13+GJ13+GM13+GP13+GS13+GV13+GY13+HB13 -> 0 | HF13: =+D13+G13+J13+M13+P13+S13+V13+Y13+AE13+AH13+AK13+AQ13+AT13+AW13+AZ13+BC13+BF13+BI13+BL13+BO13+BR13+BU13+BX13+CA13+CD13+CG13+CJ13+CM13+CP13+DB13+AB13+AN13+CS13+CV13+CY13+DE13+DH13+DK13+DN13+DQ13+DT13+DW13+DZ13+EC13+EF13+EI13+EL13+EO13+ER13+EU13+EX13+FA13+FD13+FG13+FJ13+FM13+FP13+FS13+FV13+FY13+GB13+GE13+GH13+GK13+GN13+GQ13+GT13+GW13+GZ13+HC13 -> 0
A14: 7 | HD14: =+B14+E14+H14+K14+N14+Q14+T14+W14+Z14+AC14+AF14+AI14+AL14+AO14+AR14+AU14+AX14+BA14+BD14+BG14+BJ14+BM14+BP14+BS14+BV14+BY14+CB14+CE14+CH14+CK14+CN14+CZ14+CQ14+CT14+CW14+DC14+DF14+DI14+DL14+DO14+DR14+DU14+DX14+EA14+ED14+EG14+EJ14+EM14+EP14+ES14+EV14+EY14+FB14+FE14+FH14+FK14+FN14+FQ14+FT14+FW14+FZ14+GC14+GF14+GI14+GL14+GO14+GR14+GU14+GX14+HA14 -> 0 | HE14: =+C14+F14+I14+L14+O14+R14+U14+X14+AA14+AD14+AG14+AJ14+AM14+AP14+AS14+AV14+AY14+BB14+BE14+BH14+BK14+BN14+BQ14+BT14+BW14+BZ14+CC14+CF14+CI14+CL14+CO14+DA14+CR14+CU14+CX14+DD14+DG14+DJ14+DM14+DP14+DS14+DV14+DY14+EB14+EE14+EH14+EK14+EN14+EQ14+ET14+EW14+EZ14+FC14+FF14+FI14+FL14+FO14+FR14+FU14+FX14+GA14+GD14+GG14+GJ14+GM14+GP14+GS14+GV14+GY14+HB14 -> 0 | HF14: =+D14+G14+J14+M14+P14+S14+V14+Y14+AE14+AH14+AK14+AQ14+AT14+AW14+AZ14+BC14+BF14+BI14+BL14+BO14+BR14+BU14+BX14+CA14+CD14+CG14+CJ14+CM14+CP14+DB14+AB14+AN14+CS14+CV14+CY14+DE14+DH14+DK14+DN14+DQ14+DT14+DW14+DZ14+EC14+EF14+EI14+EL14+EO14+ER14+EU14+EX14+FA14+FD14+FG14+FJ14+FM14+FP14+FS14+FV14+FY14+GB14+GE14+GH14+GK14+GN14+GQ14+GT14+GW14+GZ14+HC14 -> 0
A15: 8 | HD15: =+B15+E15+H15+K15+N15+Q15+T15+W15+Z15+AC15+AF15+AI15+AL15+AO15+AR15+AU15+AX15+BA15+BD15+BG15+BJ15+BM15+BP15+BS15+BV15+BY15+CB15+CE15+CH15+CK15+CN15+CZ15+CQ15+CT15+CW15+DC15+DF15+DI15+DL15+DO15+DR15+DU15+DX15+EA15+ED15+EG15+EJ15+EM15+EP15+ES15+EV15+EY15+FB15+FE15+FH15+FK15+FN15+FQ15+FT15+FW15+FZ15+GC15+GF15+GI15+GL15+GO15+GR15+GU15+GX15+HA15 -> 0 | HE15: =+C15+F15+I15+L15+O15+R15+U15+X15+AA15+AD15+AG15+AJ15+AM15+AP15+AS15+AV15+AY15+BB15+BE15+BH15+BK15+BN15+BQ15+BT15+BW15+BZ15+CC15+CF15+CI15+CL15+CO15+DA15+CR15+CU15+CX15+DD15+DG15+DJ15+DM15+DP15+DS15+DV15+DY15+EB15+EE15+EH15+EK15+EN15+EQ15+ET15+EW15+EZ15+FC15+FF15+FI15+FL15+FO15+FR15+FU15+FX15+GA15+GD15+GG15+GJ15+GM15+GP15+GS15+GV15+GY15+HB15 -> 0 | HF15: =+D15+G15+J15+M15+P15+S15+V15+Y15+AE15+AH15+AK15+AQ15+AT15+AW15+AZ15+BC15+BF15+BI15+BL15+BO15+BR15+BU15+BX15+CA15+CD15+CG15+CJ15+CM15+CP15+DB15+AB15+AN15+CS15+CV15+CY15+DE15+DH15+DK15+DN15+DQ15+DT15+DW15+DZ15+EC15+EF15+EI15+EL15+EO15+ER15+EU15+EX15+FA15+FD15+FG15+FJ15+FM15+FP15+FS15+FV15+FY15+GB15+GE15+GH15+GK15+GN15+GQ15+GT15+GW15+GZ15+HC15 -> 0
A16: 9 | HD16: =+B16+E16+H16+K16+N16+Q16+T16+W16+Z16+AC16+AF16+AI16+AL16+AO16+AR16+AU16+AX16+BA16+BD16+BG16+BJ16+BM16+BP16+BS16+BV16+BY16+CB16+CE16+CH16+CK16+CN16+CZ16+CQ16+CT16+CW16+DC16+DF16+DI16+DL16+DO16+DR16+DU16+DX16+EA16+ED16+EG16+EJ16+EM16+EP16+ES16+EV16+EY16+FB16+FE16+FH16+FK16+FN16+FQ16+FT16+FW16+FZ16+GC16+GF16+GI16+GL16+GO16+GR16+GU16+GX16+HA16 -> 0 | HE16: =+C16+F16+I16+L16+O16+R16+U16+X16+AA16+AD16+AG16+AJ16+AM16+AP16+AS16+AV16+AY16+BB16+BE16+BH16+BK16+BN16+BQ16+BT16+BW16+BZ16+CC16+CF16+CI16+CL16+CO16+DA16+CR16+CU16+CX16+DD16+DG16+DJ16+DM16+DP16+DS16+DV16+DY16+EB16+EE16+EH16+EK16+EN16+EQ16+ET16+EW16+EZ16+FC16+FF16+FI16+FL16+FO16+FR16+FU16+FX16+GA16+GD16+GG16+GJ16+GM16+GP16+GS16+GV16+GY16+HB16 -> 0 | HF16: =+D16+G16+J16+M16+P16+S16+V16+Y16+AE16+AH16+AK16+AQ16+AT16+AW16+AZ16+BC16+BF16+BI16+BL16+BO16+BR16+BU16+BX16+CA16+CD16+CG16+CJ16+CM16+CP16+DB16+AB16+AN16+CS16+CV16+CY16+DE16+DH16+DK16+DN16+DQ16+DT16+DW16+DZ16+EC16+EF16+EI16+EL16+EO16+ER16+EU16+EX16+FA16+FD16+FG16+FJ16+FM16+FP16+FS16+FV16+FY16+GB16+GE16+GH16+GK16+GN16+GQ16+GT16+GW16+GZ16+HC16 -> 0
A17: 10 | HD17: =+B17+E17+H17+K17+N17+Q17+T17+W17+Z17+AC17+AF17+AI17+AL17+AO17+AR17+AU17+AX17+BA17+BD17+BG17+BJ17+BM17+BP17+BS17+BV17+BY17+CB17+CE17+CH17+CK17+CN17+CZ17+CQ17+CT17+CW17+DC17+DF17+DI17+DL17+DO17+DR17+DU17+DX17+EA17+ED17+EG17+EJ17+EM17+EP17+ES17+EV17+EY17+FB17+FE17+FH17+FK17+FN17+FQ17+FT17+FW17+FZ17+GC17+GF17+GI17+GL17+GO17+GR17+GU17+GX17+HA17 -> 0 | HE17: =+C17+F17+I17+L17+O17+R17+U17+X17+AA17+AD17+AG17+AJ17+AM17+AP17+AS17+AV17+AY17+BB17+BE17+BH17+BK17+BN17+BQ17+BT17+BW17+BZ17+CC17+CF17+CI17+CL17+CO17+DA17+CR17+CU17+CX17+DD17+DG17+DJ17+DM17+DP17+DS17+DV17+DY17+EB17+EE17+EH17+EK17+EN17+EQ17+ET17+EW17+EZ17+FC17+FF17+FI17+FL17+FO17+FR17+FU17+FX17+GA17+GD17+GG17+GJ17+GM17+GP17+GS17+GV17+GY17+HB17 -> 0 | HF17: =+D17+G17+J17+M17+P17+S17+V17+Y17+AE17+AH17+AK17+AQ17+AT17+AW17+AZ17+BC17+BF17+BI17+BL17+BO17+BR17+BU17+BX17+CA17+CD17+CG17+CJ17+CM17+CP17+DB17+AB17+AN17+CS17+CV17+CY17+DE17+DH17+DK17+DN17+DQ17+DT17+DW17+DZ17+EC17+EF17+EI17+EL17+EO17+ER17+EU17+EX17+FA17+FD17+FG17+FJ17+FM17+FP17+FS17+FV17+FY17+GB17+GE17+GH17+GK17+GN17+GQ17+GT17+GW17+GZ17+HC17 -> 0
A18: 11 | HD18: =+B18+E18+H18+K18+N18+Q18+T18+W18+Z18+AC18+AF18+AI18+AL18+AO18+AR18+AU18+AX18+BA18+BD18+BG18+BJ18+BM18+BP18+BS18+BV18+BY18+CB18+CE18+CH18+CK18+CN18+CZ18+CQ18+CT18+CW18+DC18+DF18+DI18+DL18+DO18+DR18+DU18+DX18+EA18+ED18+EG18+EJ18+EM18+EP18+ES18+EV18+EY18+FB18+FE18+FH18+FK18+FN18+FQ18+FT18+FW18+FZ18+GC18+GF18+GI18+GL18+GO18+GR18+GU18+GX18+HA18 -> 0 | HE18: =+C18+F18+I18+L18+O18+R18+U18+X18+AA18+AD18+AG18+AJ18+AM18+AP18+AS18+AV18+AY18+BB18+BE18+BH18+BK18+BN18+BQ18+BT18+BW18+BZ18+CC18+CF18+CI18+CL18+CO18+DA18+CR18+CU18+CX18+DD18+DG18+DJ18+DM18+DP18+DS18+DV18+DY18+EB18+EE18+EH18+EK18+EN18+EQ18+ET18+EW18+EZ18+FC18+FF18+FI18+FL18+FO18+FR18+FU18+FX18+GA18+GD18+GG18+GJ18+GM18+GP18+GS18+GV18+GY18+HB18 -> 0 | HF18: =+D18+G18+J18+M18+P18+S18+V18+Y18+AE18+AH18+AK18+AQ18+AT18+AW18+AZ18+BC18+BF18+BI18+BL18+BO18+BR18+BU18+BX18+CA18+CD18+CG18+CJ18+CM18+CP18+DB18+AB18+AN18+CS18+CV18+CY18+DE18+DH18+DK18+DN18+DQ18+DT18+DW18+DZ18+EC18+EF18+EI18+EL18+EO18+ER18+EU18+EX18+FA18+FD18+FG18+FJ18+FM18+FP18+FS18+FV18+FY18+GB18+GE18+GH18+GK18+GN18+GQ18+GT18+GW18+GZ18+HC18 -> 0
A19: 12 | HD19: =+B19+E19+H19+K19+N19+Q19+T19+W19+Z19+AC19+AF19+AI19+AL19+AO19+AR19+AU19+AX19+BA19+BD19+BG19+BJ19+BM19+BP19+BS19+BV19+BY19+CB19+CE19+CH19+CK19+CN19+CZ19+CQ19+CT19+CW19+DC19+DF19+DI19+DL19+DO19+DR19+DU19+DX19+EA19+ED19+EG19+EJ19+EM19+EP19+ES19+EV19+EY19+FB19+FE19+FH19+FK19+FN19+FQ19+FT19+FW19+FZ19+GC19+GF19+GI19+GL19+GO19+GR19+GU19+GX19+HA19 -> 0 | HE19: =+C19+F19+I19+L19+O19+R19+U19+X19+AA19+AD19+AG19+AJ19+AM19+AP19+AS19+AV19+AY19+BB19+BE19+BH19+BK19+BN19+BQ19+BT19+BW19+BZ19+CC19+CF19+CI19+CL19+CO19+DA19+CR19+CU19+CX19+DD19+DG19+DJ19+DM19+DP19+DS19+DV19+DY19+EB19+EE19+EH19+EK19+EN19+EQ19+ET19+EW19+EZ19+FC19+FF19+FI19+FL19+FO19+FR19+FU19+FX19+GA19+GD19+GG19+GJ19+GM19+GP19+GS19+GV19+GY19+HB19 -> 0 | HF19: =+D19+G19+J19+M19+P19+S19+V19+Y19+AE19+AH19+AK19+AQ19+AT19+AW19+AZ19+BC19+BF19+BI19+BL19+BO19+BR19+BU19+BX19+CA19+CD19+CG19+CJ19+CM19+CP19+DB19+AB19+AN19+CS19+CV19+CY19+DE19+DH19+DK19+DN19+DQ19+DT19+DW19+DZ19+EC19+EF19+EI19+EL19+EO19+ER19+EU19+EX19+FA19+FD19+FG19+FJ19+FM19+FP19+FS19+FV19+FY19+GB19+GE19+GH19+GK19+GN19+GQ19+GT19+GW19+GZ19+HC19 -> 0
... A33: 26 | HD33: =+B33+E33+H33+K33+N33+Q33+T33+W33+Z33+AC33+AF33+AI33+AL33+AO33+AR33+AU33+AX33+BA33+BD33+BG33+BJ33+BM33+BP33+BS33+BV33+BY33+CB33+CE33+CH33+CK33+CN33+CZ33+CQ33+CT33+CW33+DC33+DF33+DI33+DL33+DO33+DR33+DU33+DX33+EA33+ED33+EG33+EJ33+EM33+EP33+ES33+EV33+EY33+FB33+FE33+FH33+FK33+FN33+FQ33+FT33+FW33+FZ33+GC33+GF33+GI33+GL33+GO33+GR33+GU33+GX33+HA33 -> 0 | HE33: =+C33+F33+I33+L33+O33+R33+U33+X33+AA33+AD33+AG33+AJ33+AM33+AP33+AS33+AV33+AY33+BB33+BE33+BH33+BK33+BN33+BQ33+BT33+BW33+BZ33+CC33+CF33+CI33+CL33+CO33+DA33+CR33+CU33+CX33+DD33+DG33+DJ33+DM33+DP33+DS33+DV33+DY33+EB33+EE33+EH33+EK33+EN33+EQ33+ET33+EW33+EZ33+FC33+FF33+FI33+FL33+FO33+FR33+FU33+FX33+GA33+GD33+GG33+GJ33+GM33+GP33+GS33+GV33+GY33+HB33 -> 0 | HF33: =+D33+G33+J33+M33+P33+S33+V33+Y33+AE33+AH33+AK33+AQ33+AT33+AW33+AZ33+BC33+BF33+BI33+BL33+BO33+BR33+BU33+BX33+CA33+CD33+CG33+CJ33+CM33+CP33+DB33+AB33+AN33+CS33+CV33+CY33+DE33+DH33+DK33+DN33+DQ33+DT33+DW33+DZ33+EC33+EF33+EI33+EL33+EO33+ER33+EU33+EX33+FA33+FD33+FG33+FJ33+FM33+FP33+FS33+FV33+FY33+GB33+GE33+GH33+GK33+GN33+GQ33+GT33+GW33+GZ33+HC33 -> 0
A34: 27 | HD34: =+B34+E34+H34+K34+N34+Q34+T34+W34+Z34+AC34+AF34+AI34+AL34+AO34+AR34+AU34+AX34+BA34+BD34+BG34+BJ34+BM34+BP34+BS34+BV34+BY34+CB34+CE34+CH34+CK34+CN34+CZ34+CQ34+CT34+CW34+DC34+DF34+DI34+DL34+DO34+DR34+DU34+DX34+EA34+ED34+EG34+EJ34+EM34+EP34+ES34+EV34+EY34+FB34+FE34+FH34+FK34+FN34+FQ34+FT34+FW34+FZ34+GC34+GF34+GI34+GL34+GO34+GR34+GU34+GX34+HA34 -> 0 | HE34: =+C34+F34+I34+L34+O34+R34+U34+X34+AA34+AD34+AG34+AJ34+AM34+AP34+AS34+AV34+AY34+BB34+BE34+BH34+BK34+BN34+BQ34+BT34+BW34+BZ34+CC34+CF34+CI34+CL34+CO34+DA34+CR34+CU34+CX34+DD34+DG34+DJ34+DM34+DP34+DS34+DV34+DY34+EB34+EE34+EH34+EK34+EN34+EQ34+ET34+EW34+EZ34+FC34+FF34+FI34+FL34+FO34+FR34+FU34+FX34+GA34+GD34+GG34+GJ34+GM34+GP34+GS34+GV34+GY34+HB34 -> 0 | HF34: =+D34+G34+J34+M34+P34+S34+V34+Y34+AE34+AH34+AK34+AQ34+AT34+AW34+AZ34+BC34+BF34+BI34+BL34+BO34+BR34+BU34+BX34+CA34+CD34+CG34+CJ34+CM34+CP34+DB34+AB34+AN34+CS34+CV34+CY34+DE34+DH34+DK34+DN34+DQ34+DT34+DW34+DZ34+EC34+EF34+EI34+EL34+EO34+ER34+EU34+EX34+FA34+FD34+FG34+FJ34+FM34+FP34+FS34+FV34+FY34+GB34+GE34+GH34+GK34+GN34+GQ34+GT34+GW34+GZ34+HC34 -> 0 | HG34: =SUM(B34:DB34) -> 0
A35: 28 | HD35: =+B35+E35+H35+K35+N35+Q35+T35+W35+Z35+AC35+AF35+AI35+AL35+AO35+AR35+AU35+AX35+BA35+BD35+BG35+BJ35+BM35+BP35+BS35+BV35+BY35+CB35+CE35+CH35+CK35+CN35+CZ35+CQ35+CT35+CW35+DC35+DF35+DI35+DL35+DO35+DR35+DU35+DX35+EA35+ED35+EG35+EJ35+EM35+EP35+ES35+EV35+EY35+FB35+FE35+FH35+FK35+FN35+FQ35+FT35+FW35+FZ35+GC35+GF35+GI35+GL35+GO35+GR35+GU35+GX35+HA35 -> 0 | HE35: =+C35+F35+I35+L35+O35+R35+U35+X35+AA35+AD35+AG35+AJ35+AM35+AP35+AS35+AV35+AY35+BB35+BE35+BH35+BK35+BN35+BQ35+BT35+BW35+BZ35+CC35+CF35+CI35+CL35+CO35+DA35+CR35+CU35+CX35+DD35+DG35+DJ35+DM35+DP35+DS35+DV35+DY35+EB35+EE35+EH35+EK35+EN35+EQ35+ET35+EW35+EZ35+FC35+FF35+FI35+FL35+FO35+FR35+FU35+FX35+GA35+GD35+GG35+GJ35+GM35+GP35+GS35+GV35+GY35+HB35 -> 0 | HF35: =+D35+G35+J35+M35+P35+S35+V35+Y35+AE35+AH35+AK35+AQ35+AT35+AW35+AZ35+BC35+BF35+BI35+BL35+BO35+BR35+BU35+BX35+CA35+CD35+CG35+CJ35+CM35+CP35+DB35+AB35+AN35+CS35+CV35+CY35+DE35+DH35+DK35+DN35+DQ35+DT35+DW35+DZ35+EC35+EF35+EI35+EL35+EO35+ER35+EU35+EX35+FA35+FD35+FG35+FJ35+FM35+FP35+FS35+FV35+FY35+GB35+GE35+GH35+GK35+GN35+GQ35+GT35+GW35+GZ35+HC35 -> 0 | HG35: =SUM(B35:DB35) -> 0
A36: 29 | HD36: =+B36+E36+H36+K36+N36+Q36+T36+W36+Z36+AC36+AF36+AI36+AL36+AO36+AR36+AU36+AX36+BA36+BD36+BG36+BJ36+BM36+BP36+BS36+BV36+BY36+CB36+CE36+CH36+CK36+CN36+CZ36+CQ36+CT36+CW36+DC36+DF36+DI36+DL36+DO36+DR36+DU36+DX36+EA36+ED36+EG36+EJ36+EM36+EP36+ES36+EV36+EY36+FB36+FE36+FH36+FK36+FN36+FQ36+FT36+FW36+FZ36+GC36+GF36+GI36+GL36+GO36+GR36+GU36+GX36+HA36 -> 0 | HE36: =+C36+F36+I36+L36+O36+R36+U36+X36+AA36+AD36+AG36+AJ36+AM36+AP36+AS36+AV36+AY36+BB36+BE36+BH36+BK36+BN36+BQ36+BT36+BW36+BZ36+CC36+CF36+CI36+CL36+CO36+DA36+CR36+CU36+CX36+DD36+DG36+DJ36+DM36+DP36+DS36+DV36+DY36+EB36+EE36+EH36+EK36+EN36+EQ36+ET36+EW36+EZ36+FC36+FF36+FI36+FL36+FO36+FR36+FU36+FX36+GA36+GD36+GG36+GJ36+GM36+GP36+GS36+GV36+GY36+HB36 -> 0 | HF36: =+D36+G36+J36+M36+P36+S36+V36+Y36+AE36+AH36+AK36+AQ36+AT36+AW36+AZ36+BC36+BF36+BI36+BL36+BO36+BR36+BU36+BX36+CA36+CD36+CG36+CJ36+CM36+CP36+DB36+AB36+AN36+CS36+CV36+CY36+DE36+DH36+DK36+DN36+DQ36+DT36+DW36+DZ36+EC36+EF36+EI36+EL36+EO36+ER36+EU36+EX36+FA36+FD36+FG36+FJ36+FM36+FP36+FS36+FV36+FY36+GB36+GE36+GH36+GK36+GN36+GQ36+GT36+GW36+GZ36+HC36 -> 0 | HG36: =SUM(B36:DB36) -> 0
A37: 30 | HD37: =+B37+E37+H37+K37+N37+Q37+T37+W37+Z37+AC37+AF37+AI37+AL37+AO37+AR37+AU37+AX37+BA37+BD37+BG37+BJ37+BM37+BP37+BS37+BV37+BY37+CB37+CE37+CH37+CK37+CN37+CZ37+CQ37+CT37+CW37+DC37+DF37+DI37+DL37+DO37+DR37+DU37+DX37+EA37+ED37+EG37+EJ37+EM37+EP37+ES37+EV37+EY37+FB37+FE37+FH37+FK37+FN37+FQ37+FT37+FW37+FZ37+GC37+GF37+GI37+GL37+GO37+GR37+GU37+GX37+HA37 -> 0 | HE37: =+C37+F37+I37+L37+O37+R37+U37+X37+AA37+AD37+AG37+AJ37+AM37+AP37+AS37+AV37+AY37+BB37+BE37+BH37+BK37+BN37+BQ37+BT37+BW37+BZ37+CC37+CF37+CI37+CL37+CO37+DA37+CR37+CU37+CX37+DD37+DG37+DJ37+DM37+DP37+DS37+DV37+DY37+EB37+EE37+EH37+EK37+EN37+EQ37+ET37+EW37+EZ37+FC37+FF37+FI37+FL37+FO37+FR37+FU37+FX37+GA37+GD37+GG37+GJ37+GM37+GP37+GS37+GV37+GY37+HB37 -> 0 | HF37: =+D37+G37+J37+M37+P37+S37+V37+Y37+AE37+AH37+AK37+AQ37+AT37+AW37+AZ37+BC37+BF37+BI37+BL37+BO37+BR37+BU37+BX37+CA37+CD37+CG37+CJ37+CM37+CP37+DB37+AB37+AN37+CS37+CV37+CY37+DE37+DH37+DK37+DN37+DQ37+DT37+DW37+DZ37+EC37+EF37+EI37+EL37+EO37+ER37+EU37+EX37+FA37+FD37+FG37+FJ37+FM37+FP37+FS37+FV37+FY37+GB37+GE37+GH37+GK37+GN37+GQ37+GT37+GW37+GZ37+HC37 -> 0 | HG37: =SUM(B37:DB37) -> 0
A38: 31 | HD38: =+B38+E38+H38+K38+N38+Q38+T38+W38+Z38+AC38+AF38+AI38+AL38+AO38+AR38+AU38+AX38+BA38+BD38+BG38+BJ38+BM38+BP38+BS38+BV38+BY38+CB38+CE38+CH38+CK38+CN38+CZ38+CQ38+CT38+CW38+DC38+DF38+DI38+DL38+DO38+DR38+DU38+DX38+EA38+ED38+EG38+EJ38+EM38+EP38+ES38+EV38+EY38+FB38+FE38+FH38+FK38+FN38+FQ38+FT38+FW38+FZ38+GC38+GF38+GI38+GL38+GO38+GR38+GU38+GX38+HA38 -> 0 | HE38: =+C38+F38+I38+L38+O38+R38+U38+X38+AA38+AD38+AG38+AJ38+AM38+AP38+AS38+AV38+AY38+BB38+BE38+BH38+BK38+BN38+BQ38+BT38+BW38+BZ38+CC38+CF38+CI38+CL38+CO38+DA38+CR38+CU38+CX38+DD38+DG38+DJ38+DM38+DP38+DS38+DV38+DY38+EB38+EE38+EH38+EK38+EN38+EQ38+ET38+EW38+EZ38+FC38+FF38+FI38+FL38+FO38+FR38+FU38+FX38+GA38+GD38+GG38+GJ38+GM38+GP38+GS38+GV38+GY38+HB38 -> 0 | HF38: =+D38+G38+J38+M38+P38+S38+V38+Y38+AE38+AH38+AK38+AQ38+AT38+AW38+AZ38+BC38+BF38+BI38+BL38+BO38+BR38+BU38+BX38+CA38+CD38+CG38+CJ38+CM38+CP38+DB38+AB38+AN38+CS38+CV38+CY38+DE38+DH38+DK38+DN38+DQ38+DT38+DW38+DZ38+EC38+EF38+EI38+EL38+EO38+ER38+EU38+EX38+FA38+FD38+FG38+FJ38+FM38+FP38+FS38+FV38+FY38+GB38+GE38+GH38+GK38+GN38+GQ38+GT38+GW38+GZ38+HC38 -> 0
B39: =SUM(B8:B38) -> 0 | C39: =SUM(C8:C38) -> 0 | D39: =SUM(D8:D38) -> 0 | E39: =SUM(E8:E38) -> 0 | F39: =SUM(F8:F38) -> 0 | G39: =SUM(G8:G38) -> 0 | H39: =SUM(H8:H38) -> 0 | I39: =SUM(I8:I38) -> 0 | ... HF39: =SUM(HF8:HF38) -> 0
D41: soir
A42: JOUR | B42: A01 | E42: A02 | H42: A03 | K42: A04 | N42: A05 | Q42: A06 | T42: A07 | W42: A08 | Z42: A09 | AC42: A10 | AF42: A11 | AI42: A12 | AL42: A13 | AO42: A14 | AR42: A15 | AU42: A16 | AX42: A17 | BA42: A18 | BD42: A19 | BG42: A20 | BJ42: A21 | BM42: A22 | BP42: A23 | BS42: A24 | BV42: A25 | BY42: A26 | CB42: A27 | CE42: A28 | CH42: A29 | CK42: A30 | CN42: A31 | CQ42: A32 | CT42: A33 | CW42: A34 | CZ42: A35 | DC42: A36 | DF42: A37 | DI42: A38 | DL42: A39 | DO42: A40 | DR42: A41 | DU42: A42 | DX42: A43 | EA42: A44 | ED42: A45 | EG42: A46 | EJ42: A47 | EM42: A48 | EP42: A49 | ES42: A50 | EV42: A51 | EY42: A52 | FB42: A53 | FE42: A54 | FH42: A55 | FK42: A56 | FN42: A57 | FQ42: A58 | FT42: A59 | FW42: A60 | FZ42: A61 | GC42: A62 | GF42: A63 | GI42: A64 | GL42: A65 | GO42: A66 | GR42: A67 | GU42: A68 | GX42: A69 | HA42: A70 | HD42: TOTAL PAR TARIF
B43: 20DA | C43: 25DA | D43: 30DA | E43: 20DA | F43: 25DA | G43: 30DA | H43: 20DA | I43: 25DA | J43: 30DA | K43: 20DA | L43: 25DA | M43: 30DA | N43: 20DA | O43: 25DA | P43: 30DA | Q43: 20DA | R43: 25DA | S43: 30DA | T43: 20DA | U43: 25DA | V43: 30DA | W43: 20DA | X43: 25DA | Y43: 30DA | Z43: 20DA | AA43: 25DA | AB43: 30DA | AC43: 20DA | AD43: 25DA | AE43: 30DA | AF43: 20DA | AG43: 25DA | AH43: 30DA | AI43: 20DA | AJ43: 25DA | AK43: 30DA | AL43: 20DA | AM43: 25DA | AN43: 30DA | AO43: 20DA | AP43: 25DA | AQ43: 30DA | AR43: 20DA | AS43: 25DA | AT43: 30DA | AU43: 20DA | AV43: 25DA | AW43: 30DA | AX43: 20DA | AY43: 25DA | AZ43: 30DA | BA43: 20DA | BB43: 25DA | BC43: 30DA | BD43: 20DA | BE43: 25DA | BF43: 30DA | BG43: 20DA | BH43: 25DA | BI43: 30DA | BJ43: 20DA | BK43: 25DA | BL43: 30DA | BM43: 20DA | BN43: 25DA | BO43: 30DA | BP43: 20DA | BQ43: 25DA | BR43: 30DA | BS43: 20DA | BT43: 25DA | BU43: 30DA | BV43: 20DA | BW43: 25DA | BX43: 30DA | BY43: 20DA | BZ43: 25DA | CA43: 30DA | CB43: 20DA | CC43: 25DA | CD43: 30DA | CE43: 20DA | CF43: 25DA | CG43: 30DA | CH43: 20DA | CI43: 25DA | CJ43: 30DA | CK43: 20DA | CL43: 25DA | CM43: 30DA | CN43: 20DA | CO43: 25DA | CP43: 30DA | CQ43: 20DA | CR43: 25DA | CS43: 30DA | CT43: 20DA | CU43: 25DA | CV43: 30DA | CW43: 20DA | CX43: 25DA | CY43: 30DA | CZ43: 20DA | DA43: 25DA | DB43: 30DA | DC43: 20DA | DD43: 25DA | DE43: 30DA | DF43: 20DA | DG43: 25DA | DH43: 30DA | DI43: 20DA | DJ43: 25DA | DK43: 30DA | DL43: 20DA | DM43: 25DA | DN43: 30DA | DO43: 20DA | DP43: 25DA | DQ43: 30DA | DR43: 20DA | DS43: 25DA | DT43: 30DA | DU43: 20DA | DV43: 25DA | DW43: 30DA | DX43: 20DA | DY43: 25DA | DZ43: 30DA | EA43: 20DA | EB43: 25DA | EC43: 30DA | ED43: 20DA | EE43: 25DA | EF43: 30DA | EG43: 20DA | EH43: 25DA | EI43: 30DA | EJ43: 20DA | EK43: 25DA | EL43: 30DA | EM43: 20DA | EN43: 25DA | EO43: 30DA | EP43: 20DA | EQ43: 25DA | ER43: 30DA | ES43: 20DA | ET43: 25DA | EU43: 30DA | EV43: 20DA | EW43: 25DA | EX43: 30DA | EY43: 20DA | EZ43: 25DA | FA43: 30DA | FB43: 20DA | FC43: 25DA | FD43: 30DA | FE43: 20DA | FF43: 25DA | FG43: 30DA | FH43: 20DA | FI43: 25DA | FJ43: 30DA | FK43: 20DA | FL43: 25DA | FM43: 30DA | FN43: 20DA | FO43: 25DA | FP43: 30DA | FQ43: 20DA | FR43: 25DA | FS43: 30DA | FT43: 20DA | FU43: 25DA | FV43: 30DA | FW43: 20DA | FX43: 25DA | FY43: 30DA | FZ43: 20DA | GA43: 25DA | GB43: 30DA | GC43: 20DA | GD43: 25DA | GE43: 30DA | GF43: 20DA | GG43: 25DA | GH43: 30DA | GI43: 20DA | GJ43: 25DA | GK43: 30DA | GL43: 20DA | GM43: 25DA | GN43: 30DA | GO43: 20DA | GP43: 25DA | GQ43: 30DA | GR43: 20DA | GS43: 25DA | GT43: 30DA | GU43: 20DA | GV43: 25DA | GW43: 30DA | GX43: 20DA | GY43: 25DA | GZ43: 30DA | HA43: 20DA | HB43: 25DA | HC43: 30DA | HD43: 20DA | HE43: 25DA | HF43: 30DA
A44: 1 | HD44: =+B44+E44+H44+K44+N44+Q44+T44+W44+Z44+AC44+AF44+AI44+AL44+AO44+AR44+AU44+AX44+BA44+BD44+BG44+BJ44+BM44+BP44+BS44+BV44+BY44+CB44+CE44+CH44+CK44+CN44+CZ44+CQ44+CT44+CW44+DC44+DF44+DI44+DL44+DO44+DR44+DU44+DX44+EA44+ED44+EG44+EJ44+EM44+EP44+ES44+EV44+EY44+FB44+FE44+FH44+FK44+FN44+FQ44+FT44+FW44+FZ44+GC44+GF44+GI44+GL44+GO44+GR44+GU44+GX44+HA44 -> 0 | HE44: =+C44+F44+I44+L44+O44+R44+U44+X44+AA44+AD44+AG44+AJ44+AM44+AP44+AS44+AV44+AY44+BB44+BE44+BH44+BK44+BN44+BQ44+BT44+BW44+BZ44+CC44+CF44+CI44+CL44+CO44+DA44+CR44+CU44+CX44+DD44+DG44+DJ44+DM44+DP44+DS44+DV44+DY44+EB44+EE44+EH44+EK44+EN44+EQ44+ET44+EW44+EZ44+FC44+FF44+FI44+FL44+FO44+FR44+FU44+FX44+GA44+GD44+GG44+GJ44+GM44+GP44+GS44+GV44+GY44+HB44 -> 0 | HF44: =+D44+G44+J44+M44+P44+S44+V44+Y44+AE44+AH44+AK44+AQ44+AT44+AW44+AZ44+BC44+BF44+BI44+BL44+BO44+BR44+BU44+BX44+CA44+CD44+CG44+CJ44+CM44+CP44+DB44+AB44+AN44+CS44+CV44+CY44+DE44+DH44+DK44+DN44+DQ44+DT44+DW44+DZ44+EC44+EF44+EI44+EL44+EO44+ER44+EU44+EX44+FA44+FD44+FG44+FJ44+FM44+FP44+FS44+FV44+FY44+GB44+GE44+GH44+GK44+GN44+GQ44+GT44+GW44+GZ44+HC44 -> 0
A45: 2 | HD45: =+B45+E45+H45+K45+N45+Q45+T45+W45+Z45+AC45+AF45+AI45+AL45+AO45+AR45+AU45+AX45+BA45+BD45+BG45+BJ45+BM45+BP45+BS45+BV45+BY45+CB45+CE45+CH45+CK45+CN45+CZ45+CQ45+CT45+CW45+DC45+DF45+DI45+DL45+DO45+DR45+DU45+DX45+EA45+ED45+EG45+EJ45+EM45+EP45+ES45+EV45+EY45+FB45+FE45+FH45+FK45+FN45+FQ45+FT45+FW45+FZ45+GC45+GF45+GI45+GL45+GO45+GR45+GU45+GX45+HA45 -> 0 | HE45: =+C45+F45+I45+L45+O45+R45+U45+X45+AA45+AD45+AG45+AJ45+AM45+AP45+AS45+AV45+AY45+BB45+BE45+BH45+BK45+BN45+BQ45+BT45+BW45+BZ45+CC45+CF45+CI45+CL45+CO45+DA45+CR45+CU45+CX45+DD45+DG45+DJ45+DM45+DP45+DS45+DV45+DY45+EB45+EE45+EH45+EK45+EN45+EQ45+ET45+EW45+EZ45+FC45+FF45+FI45+FL45+FO45+FR45+FU45+FX45+GA45+GD45+GG45+GJ45+GM45+GP45+GS45+GV45+GY45+HB45 -> 0 | HF45: =+D45+G45+J45+M45+P45+S45+V45+Y45+AE45+AH45+AK45+AQ45+AT45+AW45+AZ45+BC45+BF45+BI45+BL45+BO45+BR45+BU45+BX45+CA45+CD45+CG45+CJ45+CM45+CP45+DB45+AB45+AN45+CS45+CV45+CY45+DE45+DH45+DK45+DN45+DQ45+DT45+DW45+DZ45+EC45+EF45+EI45+EL45+EO45+ER45+EU45+EX45+FA45+FD45+FG45+FJ45+FM45+FP45+FS45+FV45+FY45+GB45+GE45+GH45+GK45+GN45+GQ45+GT45+GW45+GZ45+HC45 -> 0
A46: 3 | HD46: =+B46+E46+H46+K46+N46+Q46+T46+W46+Z46+AC46+AF46+AI46+AL46+AO46+AR46+AU46+AX46+BA46+BD46+BG46+BJ46+BM46+BP46+BS46+BV46+BY46+CB46+CE46+CH46+CK46+CN46+CZ46+CQ46+CT46+CW46+DC46+DF46+DI46+DL46+DO46+DR46+DU46+DX46+EA46+ED46+EG46+EJ46+EM46+EP46+ES46+EV46+EY46+FB46+FE46+FH46+FK46+FN46+FQ46+FT46+FW46+FZ46+GC46+GF46+GI46+GL46+GO46+GR46+GU46+GX46+HA46 -> 0 | HE46: =+C46+F46+I46+L46+O46+R46+U46+X46+AA46+AD46+AG46+AJ46+AM46+AP46+AS46+AV46+AY46+BB46+BE46+BH46+BK46+BN46+BQ46+BT46+BW46+BZ46+CC46+CF46+CI46+CL46+CO46+DA46+CR46+CU46+CX46+DD46+DG46+DJ46+DM46+DP46+DS46+DV46+DY46+EB46+EE46+EH46+EK46+EN46+EQ46+ET46+EW46+EZ46+FC46+FF46+FI46+FL46+FO46+FR46+FU46+FX46+GA46+GD46+GG46+GJ46+GM46+GP46+GS46+GV46+GY46+HB46 -> 0 | HF46: =+D46+G46+J46+M46+P46+S46+V46+Y46+AE46+AH46+AK46+AQ46+AT46+AW46+AZ46+BC46+BF46+BI46+BL46+BO46+BR46+BU46+BX46+CA46+CD46+CG46+CJ46+CM46+CP46+DB46+AB46+AN46+CS46+CV46+CY46+DE46+DH46+DK46+DN46+DQ46+DT46+DW46+DZ46+EC46+EF46+EI46+EL46+EO46+ER46+EU46+EX46+FA46+FD46+FG46+FJ46+FM46+FP46+FS46+FV46+FY46+GB46+GE46+GH46+GK46+GN46+GQ46+GT46+GW46+GZ46+HC46 -> 0
A47: 4 | HD47: =+B47+E47+H47+K47+N47+Q47+T47+W47+Z47+AC47+AF47+AI47+AL47+AO47+AR47+AU47+AX47+BA47+BD47+BG47+BJ47+BM47+BP47+BS47+BV47+BY47+CB47+CE47+CH47+CK47+CN47+CZ47+CQ47+CT47+CW47+DC47+DF47+DI47+DL47+DO47+DR47+DU47+DX47+EA47+ED47+EG47+EJ47+EM47+EP47+ES47+EV47+EY47+FB47+FE47+FH47+FK47+FN47+FQ47+FT47+FW47+FZ47+GC47+GF47+GI47+GL47+GO47+GR47+GU47+GX47+HA47 -> 0 | HE47: =+C47+F47+I47+L47+O47+R47+U47+X47+AA47+AD47+AG47+AJ47+AM47+AP47+AS47+AV47+AY47+BB47+BE47+BH47+BK47+BN47+BQ47+BT47+BW47+BZ47+CC47+CF47+CI47+CL47+CO47+DA47+CR47+CU47+CX47+DD47+DG47+DJ47+DM47+DP47+DS47+DV47+DY47+EB47+EE47+EH47+EK47+EN47+EQ47+ET47+EW47+EZ47+FC47+FF47+FI47+FL47+FO47+FR47+FU47+FX47+GA47+GD47+GG47+GJ47+GM47+GP47+GS47+GV47+GY47+HB47 -> 0 | HF47: =+D47+G47+J47+M47+P47+S47+V47+Y47+AE47+AH47+AK47+AQ47+AT47+AW47+AZ47+BC47+BF47+BI47+BL47+BO47+BR47+BU47+BX47+CA47+CD47+CG47+CJ47+CM47+CP47+DB47+AB47+AN47+CS47+CV47+CY47+DE47+DH47+DK47+DN47+DQ47+DT47+DW47+DZ47+EC47+EF47+EI47+EL47+EO47+ER47+EU47+EX47+FA47+FD47+FG47+FJ47+FM47+FP47+FS47+FV47+FY47+GB47+GE47+GH47+GK47+GN47+GQ47+GT47+GW47+GZ47+HC47 -> 0
A48: 5 | HD48: =+B48+E48+H48+K48+N48+Q48+T48+W48+Z48+AC48+AF48+AI48+AL48+AO48+AR48+AU48+AX48+BA48+BD48+BG48+BJ48+BM48+BP48+BS48+BV48+BY48+CB48+CE48+CH48+CK48+CN48+CZ48+CQ48+CT48+CW48+DC48+DF48+DI48+DL48+DO48+DR48+DU48+DX48+EA48+ED48+EG48+EJ48+EM48+EP48+ES48+EV48+EY48+FB48+FE48+FH48+FK48+FN48+FQ48+FT48+FW48+FZ48+GC48+GF48+GI48+GL48+GO48+GR48+GU48+GX48+HA48 -> 0 | HE48: =+C48+F48+I48+L48+O48+R48+U48+X48+AA48+AD48+AG48+AJ48+AM48+AP48+AS48+AV48+AY48+BB48+BE48+BH48+BK48+BN48+BQ48+BT48+BW48+BZ48+CC48+CF48+CI48+CL48+CO48+DA48+CR48+CU48+CX48+DD48+DG48+DJ48+DM48+DP48+DS48+DV48+DY48+EB48+EE48+EH48+EK48+EN48+EQ48+ET48+EW48+EZ48+FC48+FF48+FI48+FL48+FO48+FR48+FU48+FX48+GA48+GD48+GG48+GJ48+GM48+GP48+GS48+GV48+GY48+HB48 -> 0 | HF48: =+D48+G48+J48+M48+P48+S48+V48+Y48+AE48+AH48+AK48+AQ48+AT48+AW48+AZ48+BC48+BF48+BI48+BL48+BO48+BR48+BU48+BX48+CA48+CD48+CG48+CJ48+CM48+CP48+DB48+AB48+AN48+CS48+CV48+CY48+DE48+DH48+DK48+DN48+DQ48+DT48+DW48+DZ48+EC48+EF48+EI48+EL48+EO48+ER48+EU48+EX48+FA48+FD48+FG48+FJ48+FM48+FP48+FS48+FV48+FY48+GB48+GE48+GH48+GK48+GN48+GQ48+GT48+GW48+GZ48+HC48 -> 0
A49: 6 | HD49: =+B49+E49+H49+K49+N49+Q49+T49+W49+Z49+AC49+AF49+AI49+AL49+AO49+AR49+AU49+AX49+BA49+BD49+BG49+BJ49+BM49+BP49+BS49+BV49+BY49+CB49+CE49+CH49+CK49+CN49+CZ49+CQ49+CT49+CW49+DC49+DF49+DI49+DL49+DO49+DR49+DU49+DX49+EA49+ED49+EG49+EJ49+EM49+EP49+ES49+EV49+EY49+FB49+FE49+FH49+FK49+FN49+FQ49+FT49+FW49+FZ49+GC49+GF49+GI49+GL49+GO49+GR49+GU49+GX49+HA49 -> 0 | HE49: =+C49+F49+I49+L49+O49+R49+U49+X49+AA49+AD49+AG49+AJ49+AM49+AP49+AS49+AV49+AY49+BB49+BE49+BH49+BK49+BN49+BQ49+BT49+BW49+BZ49+CC49+CF49+CI49+CL49+CO49+DA49+CR49+CU49+CX49+DD49+DG49+DJ49+DM49+DP49+DS49+DV49+DY49+EB49+EE49+EH49+EK49+EN49+EQ49+ET49+EW49+EZ49+FC49+FF49+FI49+FL49+FO49+FR49+FU49+FX49+GA49+GD49+GG49+GJ49+GM49+GP49+GS49+GV49+GY49+HB49 -> 0 | HF49: =+D49+G49+J49+M49+P49+S49+V49+Y49+AE49+AH49+AK49+AQ49+AT49+AW49+AZ49+BC49+BF49+BI49+BL49+BO49+BR49+BU49+BX49+CA49+CD49+CG49+CJ49+CM49+CP49+DB49+AB49+AN49+CS49+CV49+CY49+DE49+DH49+DK49+DN49+DQ49+DT49+DW49+DZ49+EC49+EF49+EI49+EL49+EO49+ER49+EU49+EX49+FA49+FD49+FG49+FJ49+FM49+FP49+FS49+FV49+FY49+GB49+GE49+GH49+GK49+GN49+GQ49+GT49+GW49+GZ49+HC49 -> 0
A50: 7 | HD50: =+B50+E50+H50+K50+N50+Q50+T50+W50+Z50+AC50+AF50+AI50+AL50+AO50+AR50+AU50+AX50+BA50+BD50+BG50+BJ50+BM50+BP50+BS50+BV50+BY50+CB50+CE50+CH50+CK50+CN50+CZ50+CQ50+CT50+CW50+DC50+DF50+DI50+DL50+DO50+DR50+DU50+DX50+EA50+ED50+EG50+EJ50+EM50+EP50+ES50+EV50+EY50+FB50+FE50+FH50+FK50+FN50+FQ50+FT50+FW50+FZ50+GC50+GF50+GI50+GL50+GO50+GR50+GU50+GX50+HA50 -> 0 | HE50: =+C50+F50+I50+L50+O50+R50+U50+X50+AA50+AD50+AG50+AJ50+AM50+AP50+AS50+AV50+AY50+BB50+BE50+BH50+BK50+BN50+BQ50+BT50+BW50+BZ50+CC50+CF50+CI50+CL50+CO50+DA50+CR50+CU50+CX50+DD50+DG50+DJ50+DM50+DP50+DS50+DV50+DY50+EB50+EE50+EH50+EK50+EN50+EQ50+ET50+EW50+EZ50+FC50+FF50+FI50+FL50+FO50+FR50+FU50+FX50+GA50+GD50+GG50+GJ50+GM50+GP50+GS50+GV50+GY50+HB50 -> 0 | HF50: =+D50+G50+J50+M50+P50+S50+V50+Y50+AE50+AH50+AK50+AQ50+AT50+AW50+AZ50+BC50+BF50+BI50+BL50+BO50+BR50+BU50+BX50+CA50+CD50+CG50+CJ50+CM50+CP50+DB50+AB50+AN50+CS50+CV50+CY50+DE50+DH50+DK50+DN50+DQ50+DT50+DW50+DZ50+EC50+EF50+EI50+EL50+EO50+ER50+EU50+EX50+FA50+FD50+FG50+FJ50+FM50+FP50+FS50+FV50+FY50+GB50+GE50+GH50+GK50+GN50+GQ50+GT50+GW50+GZ50+HC50 -> 0
A51: 8 | HD51: =+B51+E51+H51+K51+N51+Q51+T51+W51+Z51+AC51+AF51+AI51+AL51+AO51+AR51+AU51+AX51+BA51+BD51+BG51+BJ51+BM51+BP51+BS51+BV51+BY51+CB51+CE51+CH51+CK51+CN51+CZ51+CQ51+CT51+CW51+DC51+DF51+DI51+DL51+DO51+DR51+DU51+DX51+EA51+ED51+EG51+EJ51+EM51+EP51+ES51+EV51+EY51+FB51+FE51+FH51+FK51+FN51+FQ51+FT51+FW51+FZ51+GC51+GF51+GI51+GL51+GO51+GR51+GU51+GX51+HA51 -> 0 | HE51: =+C51+F51+I51+L51+O51+R51+U51+X51+AA51+AD51+AG51+AJ51+AM51+AP51+AS51+AV51+AY51+BB51+BE51+BH51+BK51+BN51+BQ51+BT51+BW51+BZ51+CC51+CF51+CI51+CL51+CO51+DA51+CR51+CU51+CX51+DD51+DG51+DJ51+DM51+DP51+DS51+DV51+DY51+EB51+EE51+EH51+EK51+EN51+EQ51+ET51+EW51+EZ51+FC51+FF51+FI51+FL51+FO51+FR51+FU51+FX51+GA51+GD51+GG51+GJ51+GM51+GP51+GS51+GV51+GY51+HB51 -> 0 | HF51: =+D51+G51+J51+M51+P51+S51+V51+Y51+AE51+AH51+AK51+AQ51+AT51+AW51+AZ51+BC51+BF51+BI51+BL51+BO51+BR51+BU51+BX51+CA51+CD51+CG51+CJ51+CM51+CP51+DB51+AB51+AN51+CS51+CV51+CY51+DE51+DH51+DK51+DN51+DQ51+DT51+DW51+DZ51+EC51+EF51+EI51+EL51+EO51+ER51+EU51+EX51+FA51+FD51+FG51+FJ51+FM51+FP51+FS51+FV51+FY51+GB51+GE51+GH51+GK51+GN51+GQ51+GT51+GW51+GZ51+HC51 -> 0
A52: 9 | HD52: =+B52+E52+H52+K52+N52+Q52+T52+W52+Z52+AC52+AF52+AI52+AL52+AO52+AR52+AU52+AX52+BA52+BD52+BG52+BJ52+BM52+BP52+BS52+BV52+BY52+CB52+CE52+CH52+CK52+CN52+CZ52+CQ52+CT52+CW52+DC52+DF52+DI52+DL52+DO52+DR52+DU52+DX52+EA52+ED52+EG52+EJ52+EM52+EP52+ES52+EV52+EY52+FB52+FE52+FH52+FK52+FN52+FQ52+FT52+FW52+FZ52+GC52+GF52+GI52+GL52+GO52+GR52+GU52+GX52+HA52 -> 0 | HE52: =+C52+F52+I52+L52+O52+R52+U52+X52+AA52+AD52+AG52+AJ52+AM52+AP52+AS52+AV52+AY52+BB52+BE52+BH52+BK52+BN52+BQ52+BT52+BW52+BZ52+CC52+CF52+CI52+CL52+CO52+DA52+CR52+CU52+CX52+DD52+DG52+DJ52+DM52+DP52+DS52+DV52+DY52+EB52+EE52+EH52+EK52+EN52+EQ52+ET52+EW52+EZ52+FC52+FF52+FI52+FL52+FO52+FR52+FU52+FX52+GA52+GD52+GG52+GJ52+GM52+GP52+GS52+GV52+GY52+HB52 -> 0 | HF52: =+D52+G52+J52+M52+P52+S52+V52+Y52+AE52+AH52+AK52+AQ52+AT52+AW52+AZ52+BC52+BF52+BI52+BL52+BO52+BR52+BU52+BX52+CA52+CD52+CG52+CJ52+CM52+CP52+DB52+AB52+AN52+CS52+CV52+CY52+DE52+DH52+DK52+DN52+DQ52+DT52+DW52+DZ52+EC52+EF52+EI52+EL52+EO52+ER52+EU52+EX52+FA52+FD52+FG52+FJ52+FM52+FP52+FS52+FV52+FY52+GB52+GE52+GH52+GK52+GN52+GQ52+GT52+GW52+GZ52+HC52 -> 0
A53: 10 | HD53: =+B53+E53+H53+K53+N53+Q53+T53+W53+Z53+AC53+AF53+AI53+AL53+AO53+AR53+AU53+AX53+BA53+BD53+BG53+BJ53+BM53+BP53+BS53+BV53+BY53+CB53+CE53+CH53+CK53+CN53+CZ53+CQ53+CT53+CW53+DC53+DF53+DI53+DL53+DO53+DR53+DU53+DX53+EA53+ED53+EG53+EJ53+EM53+EP53+ES53+EV53+EY53+FB53+FE53+FH53+FK53+FN53+FQ53+FT53+FW53+FZ53+GC53+GF53+GI53+GL53+GO53+GR53+GU53+GX53+HA53 -> 0 | HE53: =+C53+F53+I53+L53+O53+R53+U53+X53+AA53+AD53+AG53+AJ53+AM53+AP53+AS53+AV53+AY53+BB53+BE53+BH53+BK53+BN53+BQ53+BT53+BW53+BZ53+CC53+CF53+CI53+CL53+CO53+DA53+CR53+CU53+CX53+DD53+DG53+DJ53+DM53+DP53+DS53+DV53+DY53+EB53+EE53+EH53+EK53+EN53+EQ53+ET53+EW53+EZ53+FC53+FF53+FI53+FL53+FO53+FR53+FU53+FX53+GA53+GD53+GG53+GJ53+GM53+GP53+GS53+GV53+GY53+HB53 -> 0 | HF53: =+D53+G53+J53+M53+P53+S53+V53+Y53+AE53+AH53+AK53+AQ53+AT53+AW53+AZ53+BC53+BF53+BI53+BL53+BO53+BR53+BU53+BX53+CA53+CD53+CG53+CJ53+CM53+CP53+DB53+AB53+AN53+CS53+CV53+CY53+DE53+DH53+DK53+DN53+DQ53+DT53+DW53+DZ53+EC53+EF53+EI53+EL53+EO53+ER53+EU53+EX53+FA53+FD53+FG53+FJ53+FM53+FP53+FS53+FV53+FY53+GB53+GE53+GH53+GK53+GN53+GQ53+GT53+GW53+GZ53+HC53 -> 0
A54: 11 | HD54: =+B54+E54+H54+K54+N54+Q54+T54+W54+Z54+AC54+AF54+AI54+AL54+AO54+AR54+AU54+AX54+BA54+BD54+BG54+BJ54+BM54+BP54+BS54+BV54+BY54+CB54+CE54+CH54+CK54+CN54+CZ54+CQ54+CT54+CW54+DC54+DF54+DI54+DL54+DO54+DR54+DU54+DX54+EA54+ED54+EG54+EJ54+EM54+EP54+ES54+EV54+EY54+FB54+FE54+FH54+FK54+FN54+FQ54+FT54+FW54+FZ54+GC54+GF54+GI54+GL54+GO54+GR54+GU54+GX54+HA54 -> 0 | HE54: =+C54+F54+I54+L54+O54+R54+U54+X54+AA54+AD54+AG54+AJ54+AM54+AP54+AS54+AV54+AY54+BB54+BE54+BH54+BK54+BN54+BQ54+BT54+BW54+BZ54+CC54+CF54+CI54+CL54+CO54+DA54+CR54+CU54+CX54+DD54+DG54+DJ54+DM54+DP54+DS54+DV54+DY54+EB54+EE54+EH54+EK54+EN54+EQ54+ET54+EW54+EZ54+FC54+FF54+FI54+FL54+FO54+FR54+FU54+FX54+GA54+GD54+GG54+GJ54+GM54+GP54+GS54+GV54+GY54+HB54 -> 0 | HF54: =+D54+G54+J54+M54+P54+S54+V54+Y54+AE54+AH54+AK54+AQ54+AT54+AW54+AZ54+BC54+BF54+BI54+BL54+BO54+BR54+BU54+BX54+CA54+CD54+CG54+CJ54+CM54+CP54+DB54+AB54+AN54+CS54+CV54+CY54+DE54+DH54+DK54+DN54+DQ54+DT54+DW54+DZ54+EC54+EF54+EI54+EL54+EO54+ER54+EU54+EX54+FA54+FD54+FG54+FJ54+FM54+FP54+FS54+FV54+FY54+GB54+GE54+GH54+GK54+GN54+GQ54+GT54+GW54+GZ54+HC54 -> 0
A55: 12 | HD55: =+B55+E55+H55+K55+N55+Q55+T55+W55+Z55+AC55+AF55+AI55+AL55+AO55+AR55+AU55+AX55+BA55+BD55+BG55+BJ55+BM55+BP55+BS55+BV55+BY55+CB55+CE55+CH55+CK55+CN55+CZ55+CQ55+CT55+CW55+DC55+DF55+DI55+DL55+DO55+DR55+DU55+DX55+EA55+ED55+EG55+EJ55+EM55+EP55+ES55+EV55+EY55+FB55+FE55+FH55+FK55+FN55+FQ55+FT55+FW55+FZ55+GC55+GF55+GI55+GL55+GO55+GR55+GU55+GX55+HA55 -> 0 | HE55: =+C55+F55+I55+L55+O55+R55+U55+X55+AA55+AD55+AG55+AJ55+AM55+AP55+AS55+AV55+AY55+BB55+BE55+BH55+BK55+BN55+BQ55+BT55+BW55+BZ55+CC55+CF55+CI55+CL55+CO55+DA55+CR55+CU55+CX55+DD55+DG55+DJ55+DM55+DP55+DS55+DV55+DY55+EB55+EE55+EH55+EK55+EN55+EQ55+ET55+EW55+EZ55+FC55+FF55+FI55+FL55+FO55+FR55+FU55+FX55+GA55+GD55+GG55+GJ55+GM55+GP55+GS55+GV55+GY55+HB55 -> 0 | HF55: =+D55+G55+J55+M55+P55+S55+V55+Y55+AE55+AH55+AK55+AQ55+AT55+AW55+AZ55+BC55+BF55+BI55+BL55+BO55+BR55+BU55+BX55+CA55+CD55+CG55+CJ55+CM55+CP55+DB55+AB55+AN55+CS55+CV55+CY55+DE55+DH55+DK55+DN55+DQ55+DT55+DW55+DZ55+EC55+EF55+EI55+EL55+EO55+ER55+EU55+EX55+FA55+FD55+FG55+FJ55+FM55+FP55+FS55+FV55+FY55+GB55+GE55+GH55+GK55+GN55+GQ55+GT55+GW55+GZ55+HC55 -> 0
... A69: 26 | HD69: =+B69+E69+H69+K69+N69+Q69+T69+W69+Z69+AC69+AF69+AI69+AL69+AO69+AR69+AU69+AX69+BA69+BD69+BG69+BJ69+BM69+BP69+BS69+BV69+BY69+CB69+CE69+CH69+CK69+CN69+CZ69+CQ69+CT69+CW69+DC69+DF69+DI69+DL69+DO69+DR69+DU69+DX69+EA69+ED69+EG69+EJ69+EM69+EP69+ES69+EV69+EY69+FB69+FE69+FH69+FK69+FN69+FQ69+FT69+FW69+FZ69+GC69+GF69+GI69+GL69+GO69+GR69+GU69+GX69+HA69 -> 0 | HE69: =+C69+F69+I69+L69+O69+R69+U69+X69+AA69+AD69+AG69+AJ69+AM69+AP69+AS69+AV69+AY69+BB69+BE69+BH69+BK69+BN69+BQ69+BT69+BW69+BZ69+CC69+CF69+CI69+CL69+CO69+DA69+CR69+CU69+CX69+DD69+DG69+DJ69+DM69+DP69+DS69+DV69+DY69+EB69+EE69+EH69+EK69+EN69+EQ69+ET69+EW69+EZ69+FC69+FF69+FI69+FL69+FO69+FR69+FU69+FX69+GA69+GD69+GG69+GJ69+GM69+GP69+GS69+GV69+GY69+HB69 -> 0 | HF69: =+D69+G69+J69+M69+P69+S69+V69+Y69+AE69+AH69+AK69+AQ69+AT69+AW69+AZ69+BC69+BF69+BI69+BL69+BO69+BR69+BU69+BX69+CA69+CD69+CG69+CJ69+CM69+CP69+DB69+AB69+AN69+CS69+CV69+CY69+DE69+DH69+DK69+DN69+DQ69+DT69+DW69+DZ69+EC69+EF69+EI69+EL69+EO69+ER69+EU69+EX69+FA69+FD69+FG69+FJ69+FM69+FP69+FS69+FV69+FY69+GB69+GE69+GH69+GK69+GN69+GQ69+GT69+GW69+GZ69+HC69 -> 0
A70: 27 | HD70: =+B70+E70+H70+K70+N70+Q70+T70+W70+Z70+AC70+AF70+AI70+AL70+AO70+AR70+AU70+AX70+BA70+BD70+BG70+BJ70+BM70+BP70+BS70+BV70+BY70+CB70+CE70+CH70+CK70+CN70+CZ70+CQ70+CT70+CW70+DC70+DF70+DI70+DL70+DO70+DR70+DU70+DX70+EA70+ED70+EG70+EJ70+EM70+EP70+ES70+EV70+EY70+FB70+FE70+FH70+FK70+FN70+FQ70+FT70+FW70+FZ70+GC70+GF70+GI70+GL70+GO70+GR70+GU70+GX70+HA70 -> 0 | HE70: =+C70+F70+I70+L70+O70+R70+U70+X70+AA70+AD70+AG70+AJ70+AM70+AP70+AS70+AV70+AY70+BB70+BE70+BH70+BK70+BN70+BQ70+BT70+BW70+BZ70+CC70+CF70+CI70+CL70+CO70+DA70+CR70+CU70+CX70+DD70+DG70+DJ70+DM70+DP70+DS70+DV70+DY70+EB70+EE70+EH70+EK70+EN70+EQ70+ET70+EW70+EZ70+FC70+FF70+FI70+FL70+FO70+FR70+FU70+FX70+GA70+GD70+GG70+GJ70+GM70+GP70+GS70+GV70+GY70+HB70 -> 0 | HF70: =+D70+G70+J70+M70+P70+S70+V70+Y70+AE70+AH70+AK70+AQ70+AT70+AW70+AZ70+BC70+BF70+BI70+BL70+BO70+BR70+BU70+BX70+CA70+CD70+CG70+CJ70+CM70+CP70+DB70+AB70+AN70+CS70+CV70+CY70+DE70+DH70+DK70+DN70+DQ70+DT70+DW70+DZ70+EC70+EF70+EI70+EL70+EO70+ER70+EU70+EX70+FA70+FD70+FG70+FJ70+FM70+FP70+FS70+FV70+FY70+GB70+GE70+GH70+GK70+GN70+GQ70+GT70+GW70+GZ70+HC70 -> 0 | HG70: =SUM(B70:DA70) -> 0
...

Sheet LIGNE
A1: matin
A2: JOUR | B2: LIGNE 1B | G2: LIGNE 16 | M2: LIGNE 09 | S2: LIGNE 11 | Y2: LIGNE 27 | AD2: LIGNE 26 | AN2: LIGNE 28 | AV2: LIGNE 03 | AZ2: LIGNE 25 | BF2: LAC | CD2: LIGNE4B | CJ2: LIGNE5B | CP2: LIGNE25B | CV2: LIGNE23 | DB2: TOTAL
B3: 20DA | C3: 20DA | D3: 20DA | E3: 20DA | F3: 20DA | G3: 20DA | H3: 20DA | I3: 20DA | J3: 20DA | K3: 20DA | L3: 20DA | M3: 20DA | N3: 20DA | O3: 20DA | P3: 20DA | Q3: 20DA | R3: 20DA | S3: 20DA | T3: 20DA | U3: 20DA | V3: 20DA | W3: 20DA | X3: 20DA | Y3: 20DA | Z3: 20DA | AA3: 20DA | AB3: 20DA | AC3: 20DA | AD3: 20DA | AE3: 30DA | AF3: 20DA | AG3: 30DA | AH3: 20DA | AI3: 30DA | AJ3: 20DA | AK3: 30DA | AL3: 20DA | AM3: 30DA | AN3: 20DA | AO3: 25DA | AP3: 20DA | AQ3: 25DA | AR3: 20DA | AS3: 25DA | AT3: 20DA | AU3: 25DA | AV3: 20DA | AW3: 20DA | AX3: 20DA | AY3: 20DA | AZ3: 20DA | BA3: 20DA | BB3: 20DA | BC3: 20DA | BD3: 20DA | BE3: 20DA | BF3: 20DA | BG3: 25DA | BH3: 30DA | BI3: 20DA | BJ3: 25DA | BK3: 30DA | BL3: 20DA | BM3: 25DA | BN3: 30DA | BO3: 20DA | BP3: 25DA | BQ3: 30DA | BR3: 20DA | BS3: 25DA | BT3: 30DA | BU3: 20DA | BV3: 25DA | BW3: 30DA | BX3: 20DA | BY3: 25DA | BZ3: 30DA | CA3: 20DA | CB3: 25DA | CC3: 30DA | CD3: 20DA | CE3: 20DA | CF3: 20DA | CG3: 20DA | CH3: 20DA | CI3: 20DA | CJ3: 20DA | CK3: 20DA | CL3: 20DA | CM3: 20DA | CN3: 20DA | CO3: 20DA | CP3: 20DA | CQ3: 20DA | CR3: 20DA | CS3: 20DA | CT3: 20DA | CU3: 20DA | CV3: 20DA | CW3: 20DA | CX3: 20DA | CY3: 20DA | CZ3: 20DA | DA3: 20DA
A4: 1 | DB4: =SUM(B4:DA4) -> 0
A5: 2 | DB5: =SUM(B5:DA5) -> 0
A6: 3 | DB6: =SUM(B6:DA6) -> 0
A7: 4 | DB7: =SUM(B7:DA7) -> 0
A8: 5 | DB8: =SUM(B8:DA8) -> 0
A9: 6 | DB9: =SUM(B9:DA9) -> 0
A10: 7 | DB10: =SUM(B10:DA10) -> 0
A11: 8 | DB11: =SUM(B11:DA11) -> 0
A12: 9 | DB12: =SUM(B12:DA12) -> 0
A13: 10 | DB13: =SUM(B13:DA13) -> 0
A14: 11 | DB14: =SUM(B14:DA14) -> 0
A15: 12 | DB15: =SUM(B15:DA15) -> 0
... A34: 31 | DB34: =SUM(B34:DA34) -> 0
B35: =SUM(B4:B34) -> 0 | C35: =SUM(C4:C34) -> 0 | D35: =SUM(D4:D34) -> 0 | E35: =SUM(E4:E34) -> 0 | F35: =SUM(F4:F34) -> 0 | G35: =SUM(G4:G34) -> 0 | H35: =SUM(H4:H34) -> 0 | I35: =SUM(I4:I34) -> 0 | ... DB35: =SUM(DB4:DB34) -> 0
G37: soir
A38: JOUR | B38: LIGNE 1B | G38: LIGNE 16 | M38: LIGNE 09 | S38: LIGNE 11 | Y38: LIGNE 27 | AD38: LIGNE 26 | AN38: LIGNE 28 | AV38: LIGNE 03 | AZ38: LIGNE 25 | BF38: LAC | CD38: LIGNE4B | CJ38: LIGNE5B | CP38: LIGNE25B | CV38: LIGNE23 | DB38: TOTAL
B39: 20DA | C39: 20DA | D39: 20DA | E39: 20DA | F39: 20DA | G39: 20DA | H39: 20DA | I39: 20DA | J39: 20DA | K39: 20DA | L39: 20DA | M39: 20DA | N39: 20DA | O39: 20DA | P39: 20DA | Q39: 20DA | R39: 20DA | S39: 20DA | T39: 20DA | U39: 20DA | V39: 20DA | W39: 20DA | X39: 20DA | Y39: 20DA | Z39: 20DA | AA39: 20DA | AB39: 20DA | AC39: 20DA | AD39: 20DA | AE39: 30DA | AF39: 20DA | AG39: 30DA | AH39: 20DA | AI39: 30DA | AJ39: 20DA | AK39: 30DA | AL39: 20DA | AM39: 30DA | AN39: 20DA | AO39: 25DA | AP39: 20DA | AQ39: 25DA | AR39: 20DA | AS39: 25DA | AT39: 20DA | AU39: 25DA | AV39: 20DA | AW39: 20DA | AX39: 20DA | AY39: 20DA | AZ39: 20DA | BA39: 20DA | BB39: 20DA | BC39: 20DA | BD39: 20DA | BE39: 20DA | BF39: 20DA | BG39: 25DA | BH39: 30DA | BI39: 20DA | BJ39: 25DA | BK39: 30DA | BL39: 20DA | BM39: 25DA | BN39: 30DA | BO39: 20DA | BP39: 25DA | BQ39: 30DA | BR39: 20DA | BS39: 25DA | BT39: 30DA | BU39: 20DA | BV39: 25DA | BW39: 30DA | BX39: 20DA | BY39: 25DA | BZ39: 30DA | CA39: 20DA | CB39: 25DA | CC39: 30DA | CD39: 20DA | CE39: 20DA | CF39: 20DA | CG39: 20DA | CH39: 20DA | CI39: 20DA | CJ39: 20DA | CK39: 20DA | CL39: 20DA | CM39: 20DA | CN39: 20DA | CO39: 20DA | CP39: 20DA | CQ39: 20DA | CR39: 20DA | CS39: 20DA | CT39: 20DA | CU39: 20DA | CV39: 20DA | CW39: 20DA | CX39: 20DA | CY39: 20DA | CZ39: 20DA | DA39: 20DA
A40: 1 | DB40: =SUM(B40:DA40) -> 0
A41: 2 | DB41: =SUM(B41:DA41) -> 0
A42: 3 | DB42: =SUM(B42:DA42) -> 0
A43: 4 | DB43: =SUM(B43:DA43) -> 0
A44: 5 | DB44: =SUM(B44:DA44) -> 0
A45: 6 | DB45: =SUM(B45:DA45) -> 0
A46: 7 | DB46: =SUM(B46:DA46) -> 0
A47: 8 | DB47: =SUM(B47:DA47) -> 0
A48: 9 | DB48: =SUM(B48:DA48) -> 0
A49: 10 | DB49: =SUM(B49:DA49) -> 0
A50: 11 | DB50: =SUM(B50:DA50) -> 0
A51: 12 | DB51: =SUM(B51:DA51) -> 0
... A70: 31 | DB70: =SUM(B70:DA70) -> 0
B71: =SUM(B40:B70) -> 0 | C71: =SUM(C40:C70) -> 0 | D71: =SUM(D40:D70) -> 0 | E71: =SUM(E40:E70) -> 0 | F71: =SUM(F40:F70) -> 0 | G71: =SUM(G40:G70) -> 0 | H71: =SUM(H40:H70) -> 0 | I71: =SUM(I40:I70) -> 0 | ... DA71: =SUM(DA40:DA70) -> 0 | DB71: =SUM(B71:DA71) -> 0
G72: nuit
A73: JOUR | B73: LIGNE 1B | G73: LIGNE 16 | M73: LIGNE 09 | S73: LIGNE 11 | Y73: LIGNE 27 | AD73: LIGNE 26 | AN73: LIGNE 28 | AV73: LIGNE 03 | AZ73: LIGNE 25 | BF73: LAC | CD73: LIGNE4B | CJ73: LIGNE5B | CP73: LIGNE25B | CV73: LIGNE23 | DB73: TOTAL
B74: 20DA | C74: 20DA | D74: 20DA | E74: 20DA | F74: 20DA | G74: 20DA | H74: 20DA | I74: 20DA | J74: 20DA | K74: 20DA | L74: 20DA | M74: 20DA | N74: 20DA | O74: 20DA | P74: 20DA | Q74: 20DA | R74: 20DA | S74: 20DA | T74: 20DA | U74: 20DA | V74: 20DA | W74: 20DA | X74: 20DA | Y74: 20DA | Z74: 20DA | AA74: 20DA | AB74: 20DA | AC74: 20DA | AD74: 20DA | AE74: 30DA | AF74: 20DA | AG74: 30DA | AH74: 20DA | AI74: 30DA | AJ74: 20DA | AK74: 30DA | AL74: 20DA | AM74: 30DA | AN74: 20DA | AO74: 25DA | AP74: 20DA | AQ74: 25DA | AR74: 20DA | AS74: 25DA | AT74: 20DA | AU74: 25DA | AV74: 20DA | AW74: 20DA | AX74: 20DA | AY74: 20DA | AZ74: 20DA | BA74: 20DA | BB74: 20DA | BC74: 20DA | BD74: 20DA | BE74: 20DA | BF74: 20DA | BG74: 25DA | BH74: 30DA | BI74: 20DA | BJ74: 25DA | BK74: 30DA | BL74: 20DA | BM74: 25DA | BN74: 30DA | BO74: 20DA | BP74: 25DA | BQ74: 30DA | BR74: 20DA | BS74: 25DA | BT74: 30DA | BU74: 20DA | BV74: 25DA | BW74: 30DA | BX74: 20DA | BY74: 25DA | BZ74: 30DA | CA74: 20DA | CB74: 25DA | CC74: 30DA | CD74: 20DA | CE74: 20DA | CF74: 20DA | CG74: 20DA | CH74: 20DA | CI74: 20DA | CJ74: 20DA | CK74: 20DA | CL74: 20DA | CM74: 20DA | CN74: 20DA | CO74: 20DA | CP74: 20DA | CQ74: 20DA | CR74: 20DA | CS74: 20DA | CT74: 20DA | CU74: 20DA | CV74: 20DA | CW74: 20DA | CX74: 20DA | CY74: 20DA | CZ74: 20DA | DA74: 20DA
A75: 1 | DB75: =SUM(B75:DA75) -> 0
A76: 2 | DB76: =SUM(B76:DA76) -> 0
A77: 3 | DB77: =SUM(B77:DA77) -> 0
...

Sheet RETAION-BUS
A3: MATIN | BU3: soir | EO3: NUIT
A4: JOUR | B4: A01 | C4: A02 | D4: A03 | E4: A04 | F4: A05 | G4: A06 | H4: A07 | I4: A08 | J4: A09 | K4: A10 | L4: A11 | M4: A12 | N4: A13 | O4: A14 | P4: A15 | Q4: A16 | R4: A17 | S4: A18 | T4: A19 | U4: A20 | V4: A21 | W4: A22 | X4: A23 | Y4: A24 | Z4: A25 | AA4: A26 | AB4: A27 | AC4: A28 | AD4: A29 | AE4: A30 | AF4: A31 | AG4: A32 | AH4: A33 | AI4: A34 | AJ4: A35 | AK4: A36 | AL4: A37 | AM4: A38 | AN4: A39 | AO4: A40 | AP4: A41 | AQ4: A42 | AR4: A43 | AS4: A44 | AT4: A45 | AU4: A46 | AV4: A47 | AW4: A48 | AX4: A49 | AY4: A50 | AZ4: A51 | BA4: A52 | BB4: A53 | BC4: A54 | BD4: A55 | BE4: A56 | BF4: A57 | BG4: A58 | BH4: A59 | BI4: A60 | BJ4: A61 | BK4: A62 | BL4: A63 | BM4: A64 | BN4: A65 | BO4: A66 | BP4: A67 | BQ4: A68 | BR4: A69 | BS4: A70 | BT4: TOTAL | BU4: JOUR | BV4: A01 | BW4: A02 | BX4: A03 | BY4: A04 | BZ4: A05 | CA4: A06 | CB4: A07 | CC4: A08 | CD4: A09 | CE4: A10 | CF4: A11 | CG4: A12 | CH4: A13 | CI4: A14 | CJ4: A15 | CK4: A16 | CL4: A17 | CM4: A18 | CN4: A19 | CO4: A20 | CP4: A21 | CQ4: A22 | CR4: A23 | CS4: A24 | CT4: A25 | CU4: A26 | CV4: A27 | CW4: A28 | CX4: A29 | CY4: A30 | CZ4: A31 | DA4: A32 | DB4: A33 | DC4: A34 | DD4: A35 | DE4: A36 | DF4: A37 | DG4: A38 | DH4: A39 | DI4: A40 | DJ4: A41 | DK4: A42 | DL4: A43 | DM4: A44 | DN4: A45 | DO4: A46 | DP4: A47 | DQ4: A48 | DR4: A49 | DS4: A50 | DT4: A51 | DU4: A52 | DV4: A53 | DW4: A54 | DX4: A55 | DY4: A56 | DZ4: A57 | EA4: A58 | EB4: A59 | EC4: A60 | ED4: A61 | EE4: A62 | EF4: A63 | EG4: A64 | EH4: A65 | EI4: A66 | EJ4: A67 | EK4: A68 | EL4: A69 | EM4: A70 | EN4: TOTAL | EO4: JOUR | EP4: A01 | EQ4: A02 | ER4: A03 | ES4: A04 | ET4: A05 | EU4: A06 | EV4: A07 | EW4: A08 | EX4: A09 | EY4: A10 | EZ4: A11 | FA4: A12 | FB4: A13 | FC4: A14 | FD4: A15 | FE4: A16 | FF4: A17 | FG4: A18 | FH4: A19 | FI4: A20 | FJ4: A21 | FK4: A22 | FL4: A23 | FM4: A24 | FN4: A25 | FO4: A26 | FP4: A27 | FQ4: A28 | FR4: A29 | FS4: A30 | FT4: A31 | FU4: A32 | FV4: A33 | FW4: A34 | FX4: A35 | FY4: A36 | FZ4: A37 | GA4: A38 | GB4: A39 | GC4: A40 | GD4: A41 | GE4: A42 | GF4: A43 | GG4: A44 | GH4: A45 | GI4: A46 | GJ4: A47 | GK4: A48 | GL4: A49 | GM4: A50 | GN4: A51 | GO4: A52 | GP4: A53 | GQ4: A54 | GR4: A55 | GS4: A56 | GT4: A57 | GU4: A58 | GV4: A59 | GW4: A60 | GX4: A61 | GY4: A62 | GZ4: A63 | HA4: A64 | HB4: A65 | HC4: A66 | HD4: A67 | HE4: A68 | HF4: A69 | HG4: A70 | HH4: TOTAL
A5: 1 | BT5: =SUM(B5:BS5) -> 0 | BU5: 1 | EN5: =SUM(BV5:EM5) -> 0 | EO5: 1 | HH5: =SUM(EP5:HG5) -> 0
A6: 2 | BT6: =SUM(B6:BS6) -> 0 | BU6: 2 | EN6: =SUM(BV6:EM6) -> 0 | EO6: 2 | HH6: =SUM(EP6:HG6) -> 0
A7: 3 | BT7: =SUM(B7:BS7) -> 0 | BU7: 3 | EN7: =SUM(BV7:EM7) -> 0 | EO7: 3 | HH7: =SUM(EP7:HG7) -> 0
A8: 4 | BT8: =SUM(B8:BS8) -> 0 | BU8: 4 | EN8: =SUM(BV8:EM8) -> 0 | EO8: 4 | HH8: =SUM(EP8:HG8) -> 0
A9: 5 | BT9: =SUM(B9:BS9) -> 0 | BU9: 5 | EN9: =SUM(BV9:EM9) -> 0 | EO9: 5 | HH9: =SUM(EP9:HG9) -> 0
A10: 6 | BT10: =SUM(B10:BS10) -> 0 | BU10: 6 | EN10: =SUM(BV10:EM10) -> 0 | EO10: 6 | HH10: =SUM(EP10:HG10) -> 0
A11: 7 | BT11: =SUM(B11:BS11) -> 0 | BU11: 7 | EN11: =SUM(BV11:EM11) -> 0 | EO11: 7 | HH11: =SUM(EP11:HG11) -> 0
A12: 8 | BT12: =SUM(B12:BS12) -> 0 | BU12: 8 | EN12: =SUM(BV12:EM12) -> 0 | EO12: 8 | HH12: =SUM(EP12:HG12) -> 0
A13: 9 | BT13: =SUM(B13:BS13) -> 0 | BU13: 9 | EN13: =SUM(BV13:EM13) -> 0 | EO13: 9 | HH13: =SUM(EP13:HG13) -> 0
A14: 10 | BT14: =SUM(B14:BS14) -> 0 | BU14: 10 | EN14: =SUM(BV14:EM14) -> 0 | EO14: 10 | HH14: =SUM(EP14:HG14) -> 0
A15: 11 | BT15: =SUM(B15:BS15) -> 0 | BU15: 11 | EN15: =SUM(BV15:EM15) -> 0 | EO15: 11 | HH15: =SUM(EP15:HG15) -> 0
A16: 12 | BT16: =SUM(B16:BS16) -> 0 | BU16: 12 | EN16: =SUM(BV16:EM16) -> 0 | EO16: 12 | HH16: =SUM(EP16:HG16) -> 0
... A35: 31 | BT35: =SUM(B35:BS35) -> 0 | BU35: 31 | EN35: =SUM(BV35:EM35) -> 0 | EO35: 31 | HH35: =SUM(EP35:HG35) -> 0
A36: T | B36: =SUM(B5:B35) -> 0 | C36: =SUM(C5:C35) -> 0 | D36: =SUM(D5:D35) -> 0 | E36: =SUM(E5:E35) -> 0 | F36: =SUM(F5:F35) -> 0 | G36: =SUM(G5:G35) -> 0 | H36: =SUM(H5:H35) -> 0 | I36: =SUM(I5:I35) -> 0 | ... BT36: =SUM(BT5:BT35) -> 0 | BU36: T | BV36: =SUM(BV5:BV35) -> 0 | BW36: =SUM(BW5:BW35) -> 0 | BX36: =SUM(BX5:BX35) -> 0 | BY36: =SUM(BY5:BY35) -> 0 | BZ36: =SUM(BZ5:BZ35) -> 0 | CA36: =SUM(CA5:CA35) -> 0 | CB36: =SUM(CB5:CB35) -> 0 | CC36: =SUM(CC5:CC35) -> 0 | ... EN36: =SUM(EN5:EN35) -> 0 | EO36: T | EP36: =SUM(EP5:EP35) -> 0 | EQ36: =SUM(EQ5:EQ35) -> 0 | ER36: =SUM(ER5:ER35) -> 0 | ES36: =SUM(ES5:ES35) -> 0 | ET36: =SUM(ET5:ET35) -> 0 | EU36: =SUM(EU5:EU35) -> 0 | EV36: =SUM(EV5:EV35) -> 0 | EW36: =SUM(EW5:EW35) -> 0 | ... HH36: =SUM(HH5:HH35) -> 0
D38: NOMBRE DE ROTATIONS | M38: =+BT36+EN36+HH36 -> 0
D40: NOMBRE DE PLACES OFFERTES | M40: =+M38*200 -> 0

Sheet ROTATION-LIGNE
A2: MATIN | BN2: SOIR | EA2: NUIT
A3: JOUR | B3: LIGNE 1B | E3: LIGNE 16 | J3: LIGNE 09 | N3: LIGNE 11 | S3: LIGNE 27 | X3: LIGNE 26 | AC3: LIGNE 28 | AG3: LIGNE 03b | AK3: LIGNE 25 | AQ3: LAC | AW3: LIGNE 4b | BA3: LIGNE 5b | BE3: LIGNE 25b | BI3: LIGNE 23 | BM3: TOTAL | BN3: JOUR | BO3: LIGNE 1B | BR3: LIGNE 16 | BW3: LIGNE 09 | CA3: LIGNE 11 | CF3: LIGNE 27 | CK3: LIGNE 26 | CP3: LIGNE 28 | CT3: LIGNE 03b | CX3: LIGNE25 | DD3: lac | DJ3: LIGNE 4b | DN3: LIGNE 5b | DR3: LIGNE 25b | DV3: LIGNE 23 | DZ3: TOTAL | EA3: JOUR | EB3: LIGNE 1B | EE3: LIGNE 16 | EJ3: LIGNE 09 | EN3: LIGNE 11 | ES3: LIGNE 27 | EX3: LIGNE 26 | FC3: LIGNE 28 | FG3: LIGNE 03b | FK3: LIGNE25 | FQ3: lac | FW3: LIGNE 4b | GA3: LIGNE 5b | GE3: LIGNE 25b | GI3: LIGNE 23 | GM3: TOTAL | GO3: TOTAL BUS | GP3: TOTAL LIGNE | GQ3: ECART
B4: BUS 01 | C4: BUS 02 | D4: BUS 03 | E4: BUS 01 | F4: BUS 02 | G4: BUS 03 | H4: BUS 04 | I4: BUS 05 | J4: BUS 01 | K4: BUS 02 | L4: BUS 03 | M4: BUS 04 | N4: BUS 01 | O4: BUS 02 | P4: BUS 03 | Q4: BUS 04 | R4: BUS 05 | S4: BUS 01 | T4: BUS 02 | U4: BUS 03 | V4: BUS 04 | W4: BUS 05 | X4: BUS 01 | Y4: BUS 02 | Z4: BUS 03 | AA4: BUS 04 | AB4: BUS 05 | AC4: BUS 01 | AD4: BUS 02 | AE4: BUS 03 | AF4: BUS 04 | AG4: BUS 01 | AH4: BUS 02 | AI4: BUS 03 | AJ4: BUS 04 | AK4: BUS 01 | AL4: BUS 02 | AM4: BUS 03 | AN4: BUS 04 | AO4: BUS 05 | AP4: BUS 06 | AQ4: BUS 01 | AR4: BUS 02 | AS4: BUS 03 | AT4: BUS 04 | AU4: BUS 05 | AV4: BUS 06 | AW4: BUS 01 | AX4: BUS 02 | AY4: BUS 03 | AZ4: BUS 04 | BA4: BUS 01 | BB4: BUS 02 | BC4: BUS 03 | BD4: BUS 04 | BE4: BUS 01 | BF4: BUS 02 | BG4: BUS 03 | BH4: BUS 04 | BI4: BUS 01 | BJ4: BUS 02 | BK4: BUS 03 | BL4: BUS 04 | BO4: BUS 01 | BP4: BUS 02 | BQ4: BUS 03 | BR4: BUS 01 | BS4: BUS 02 | BT4: BUS 03 | BU4: BUS 04 | BV4: BUS 04 | BW4: BUS 01 | BX4: BUS 02 | BY4: BUS 03 | BZ4: BUS 04 | CA4: BUS 01 | CB4: BUS 02 | CC4: BUS 03 | CD4: BUS 04 | CE4: BUS05 | CF4: BUS 01 | CG4: BUS 02 | CH4: BUS 03 | CI4: BUS 04 | CJ4: BUS 05 | CK4: BUS 01 | CL4: BUS 02 | CM4: BUS 03 | CN4: BUS 04 | CO4: BUS 05 | CP4: BUS 01 | CQ4: BUS 02 | CR4: BUS 03 | CS4: BUS 04 | CT4: BUS 01 | CU4: BUS 02 | CV4: BUS 03 | CW4: BUS 04 | CX4: BUS 01 | CY4: BUS 02 | CZ4: BUS 03 | DA4: BUS 04 | DB4: BUS 05 | DC4: BUS 06 | DD4: BUS 01 | DE4: BUS 02 | DF4: BUS 03 | DG4: BUS 04 | DH4: BUS 05 | DI4: BUS 06 | DJ4: BUS 01 | DK4: BUS 02 | DL4: BUS 03 | DM4: BUS 04 | DN4: BUS 01 | DO4: BUS 02 | DP4: BUS 03 | DQ4: BUS 04 | DR4: BUS 01 | DS4: BUS 02 | DT4: BUS 03 | DU4: BUS 04 | DV4: BUS 01 | DW4: BUS 02 | DX4: BUS 03 | DY4: BUS 04 | EB4: BUS 01 | EC4: BUS 02 | ED4: BUS 03 | EE4: BUS 01 | EF4: BUS 02 | EG4: BUS 03 | EH4: BUS 04 | EI4: BUS 04 | EJ4: BUS 01 | EK4: BUS 02 | EL4: BUS 03 | EM4: BUS 04 | EN4: BUS 01 | EO4: BUS 02 | EP4: BUS 03 | EQ4: BUS 04 | ER4: BUS05 | ES4: BUS 01 | ET4: BUS 02 | EU4: BUS 03 | EV4: BUS 04 | EW4: BUS 05 | EX4: BUS 01 | EY4: BUS 02 | EZ4: BUS 03 | FA4: BUS 04 | FB4: BUS 05 | FC4: BUS 01 | FD4: BUS 02 | FE4: BUS 03 | FF4: BUS 04 | FG4: BUS 01 | FH4: BUS 02 | FI4: BUS 03 | FJ4: BUS 04 | FK4: BUS 01 | FL4: BUS 02 | FM4: BUS 03 | FN4: BUS 04 | FO4: BUS 05 | FP4: BUS 06 | FQ4: BUS 01 | FR4: BUS 02 | FS4: BUS 03 | FT4: BUS 04 | FU4: BUS 05 | FV4: BUS 06 | FW4: BUS 01 | FX4: BUS 02 | FY4: BUS 03 | FZ4: BUS 04 | GA4: BUS 01 | GB4: BUS 02 | GC4: BUS 03 | GD4: BUS 04 | GE4: BUS 01 | GF4: BUS 02 | GG4: BUS 03 | GH4: BUS 04 | GI4: BUS 01 | GJ4: BUS 02 | GK4: BUS 03 | GL4: BUS 04
A5: 1 | BM5: =SUM(B5:BL5) -> 0 | BN5: 1 | DZ5: =SUM(BO5:DY5) -> 0 | EA5: 1 | GM5: =SUM(EB5:GL5) -> 0 | GO5: =+'RETAION-BUS'!BT5+'RETAION-BUS'!EN5+'RETAION-BUS'!HH5 -> 0 | GP5: =+DZ5+BM5+GM5 -> 0 | GQ5: =+GO5-GP5 -> 0
A6: 2 | BM6: =SUM(B6:BL6) -> 0 | BN6: 2 | DZ6: =SUM(BO6:DY6) -> 0 | EA6: 2 | GM6: =SUM(EB6:GL6) -> 0 | GO6: =+'RETAION-BUS'!BT6+'RETAION-BUS'!EN6+'RETAION-BUS'!HH6 -> 0 | GP6: =+DZ6+BM6+GM6 -> 0 | GQ6: =+GO6-GP6 -> 0
A7: 3 | BM7: =SUM(B7:BL7) -> 0 | BN7: 3 | DZ7: =SUM(BO7:DY7) -> 0 | EA7: 3 | GM7: =SUM(EB7:GL7) -> 0 | GO7: =+'RETAION-BUS'!BT7+'RETAION-BUS'!EN7+'RETAION-BUS'!HH7 -> 0 | GP7: =+DZ7+BM7+GM7 -> 0 | GQ7: =+GO7-GP7 -> 0
A8: 4 | BM8: =SUM(B8:BL8) -> 0 | BN8: 4 | DZ8: =SUM(BO8:DY8) -> 0 | EA8: 4 | GM8: =SUM(EB8:GL8) -> 0 | GO8: =+'RETAION-BUS'!BT8+'RETAION-BUS'!EN8+'RETAION-BUS'!HH8 -> 0 | GP8: =+DZ8+BM8+GM8 -> 0 | GQ8: =+GO8-GP8 -> 0
A9: 5 | BM9: =SUM(B9:BL9) -> 0 | BN9: 5 | DZ9: =SUM(BO9:DY9) -> 0 | EA9: 5 | GM9: =SUM(EB9:GL9) -> 0 | GO9: =+'RETAION-BUS'!BT9+'RETAION-BUS'!EN9+'RETAION-BUS'!HH9 -> 0 | GP9: =+DZ9+BM9+GM9 -> 0 | GQ9: =+GO9-GP9 -> 0
A10: 6 | BM10: =SUM(B10:BL10) -> 0 | BN10: 6 | DZ10: =SUM(BO10:DY10) -> 0 | EA10: 6 | GM10: =SUM(EB10:GL10) -> 0 | GO10: =+'RETAION-BUS'!BT10+'RETAION-BUS'!EN10+'RETAION-BUS'!HH10 -> 0 | GP10: =+DZ10+BM10+GM10 -> 0 | GQ10: =+GO10-GP10 -> 0
A11: 7 | BM11: =SUM(B11:BL11) -> 0 | BN11: 7 | DZ11: =SUM(BO11:DY11) -> 0 | EA11: 7 | GM11: =SUM(EB11:GL11) -> 0 | GO11: =+'RETAION-BUS'!BT11+'RETAION-BUS'!EN11+'RETAION-BUS'!HH11 -> 0 | GP11: =+DZ11+BM11+GM11 -> 0 | GQ11: =+GO11-GP11 -> 0
A12: 8 | BM12: =SUM(B12:BL12) -> 0 | BN12: 8 | DZ12: =SUM(BO12:DY12) -> 0 | EA12: 8 | GM12: =SUM(EB12:GL12) -> 0 | GO12: =+'RETAION-BUS'!BT12+'RETAION-BUS'!EN12+'RETAION-BUS'!HH12 -> 0 | GP12: =+DZ12+BM12+GM12 -> 0 | GQ12: =+GO12-GP12 -> 0
A13: 9 | BM13: =SUM(B13:BL13) -> 0 | BN13: 9 | DZ13: =SUM(BO13:DY13) -> 0 | EA13: 9 | GM13: =SUM(EB13:GL13) -> 0 | GO13: =+'RETAION-BUS'!BT13+'RETAION-BUS'!EN13+'RETAION-BUS'!HH13 -> 0 | GP13: =+DZ13+BM13+GM13 -> 0 | GQ13: =+GO13-GP13 -> 0
A14: 10 | BM14: =SUM(B14:BL14) -> 0 | BN14: 10 | DZ14: =SUM(BO14:DY14) -> 0 | EA14: 10 | GM14: =SUM(EB14:GL14) -> 0 | GO14: =+'RETAION-BUS'!BT14+'RETAION-BUS'!EN14+'RETAION-BUS'!HH14 -> 0 | GP14: =+DZ14+BM14+GM14 -> 0 | GQ14: =+GO14-GP14 -> 0
A15: 11 | BM15: =SUM(B15:BL15) -> 0 | BN15: 11 | DZ15: =SUM(BO15:DY15) -> 0 | EA15: 11 | GM15: =SUM(EB15:GL15) -> 0 | GO15: =+'RETAION-BUS'!BT15+'RETAION-BUS'!EN15+'RETAION-BUS'!HH15 -> 0 | GP15: =+DZ15+BM15+GM15 -> 0 | GQ15: =+GO15-GP15 -> 0
A16: 12 | BM16: =SUM(B16:BL16) -> 0 | BN16: 12 | DZ16: =SUM(BO16:DY16) -> 0 | EA16: 12 | GM16: =SUM(EB16:GL16) -> 0 | GO16: =+'RETAION-BUS'!BT16+'RETAION-BUS'!EN16+'RETAION-BUS'!HH16 -> 0 | GP16: =+DZ16+BM16+GM16 -> 0 | GQ16: =+GO16-GP16 -> 0
... A35: 31 | BM35: =SUM(B35:BL35) -> 0 | BN35: 31 | DZ35: =SUM(BO35:DY35) -> 0 | EA35: 31 | GM35: =SUM(EB35:GL35) -> 0 | GO35: =+'RETAION-BUS'!BT35+'RETAION-BUS'!EN35+'RETAION-BUS'!HH35 -> 0 | GP35: =+DZ35+BM35+GM35 -> 0 | GQ35: =+GO35-GP35 -> 0
