Workbook

Sheet etat_receveur

Sheet BUS
X2: شهر
D5: matin
A6: JOUR | B6: A01 | E6: A02 | H6: A03 | K6: A04 | N6: A05 | Q6: A06 | T6: A07 | W6: A08 | Z6: A09 | AC6: A10 | AF6: A11 | AI6: A12 | AL6: A13 | AO6: A14 | AR6: A15 | AU6: A16 | AX6: A17 | BA6: A18 | BD6: A19 | BG6: A20 | BJ6: A21 | BM6: A22 | BP6: A23 | BS6: A24 | BV6: A25 | BY6: A26 | CB6: A27 | CE6: A28 | CH6: A29 | CK6: A30 | CN6: A31 | CQ6: A32 | CT6: A33 | CW6: A34 | CZ6: A35 | DC6: TOTAL PAR TARIF
B7: 20DA | C7: 25DA | D7: 30DA | E7: 20DA | F7: 25DA | G7: 30DA | H7: 20DA | I7: 25DA | J7: 30DA | K7: 20DA | L7: 25DA | M7: 30DA | N7: 20DA | O7: 25DA | P7: 30DA | Q7: 20DA | R7: 25DA | S7: 30DA | T7: 20DA | U7: 25DA | V7: 30DA | W7: 20DA | X7: 25DA | Y7: 30DA | Z7: 20DA | AA7: 25DA | AB7: 30DA | AC7: 20DA | AD7: 25DA | AE7: 30DA | AF7: 20DA | AG7: 25DA | AH7: 30DA | AI7: 20DA | AJ7: 25DA | AK7: 30DA | AL7: 20DA | AM7: 25DA | AN7: 30DA | AO7: 20DA | AP7: 25DA | AQ7: 30DA | AR7: 20DA | AS7: 25DA | AT7: 30DA | AU7: 20DA | AV7: 25DA | AW7: 30DA | AX7: 20DA | AY7: 25DA | AZ7: 30DA | BA7: 20DA | BB7: 25DA | BC7: 30DA | BD7: 20DA | BE7: 25DA | BF7: 30DA | BG7: 20DA | BH7: 25DA | BI7: 30DA | BJ7: 20DA | BK7: 25DA | BL7: 30DA | BM7: 20DA | BN7: 25DA | BO7: 30DA | BP7: 20DA | BQ7: 25DA | BR7: 30DA | BS7: 20DA | BT7: 25DA | BU7: 30DA | BV7: 20DA | BW7: 25DA | BX7: 30DA | BY7: 20DA | BZ7: 25DA | CA7: 30DA | CB7: 20DA | CC7: 25DA | CD7: 30DA | CE7: 20DA | CF7: 25DA | CG7: 30DA | CH7: 20DA | CI7: 25DA | CJ7: 30DA | CK7: 20DA | CL7: 25DA | CM7: 30DA | CN7: 20DA | CO7: 25DA | CP7: 30DA | CQ7: 20DA | CR7: 25DA | CS7: 30DA | CT7: 20DA | CU7: 25DA | CV7: 30DA | CW7: 20DA | CX7: 25DA | CY7: 30DA | CZ7: 20DA | DA7: 25DA | DB7: 30DA | DC7: 20DA | DD7: 25DA | DE7: 30DA
A8: 1 | DC8: =+B8+E8+H8+K8+N8+Q8+T8+W8+Z8+AC8+AF8+AI8+AL8+AO8+AR8+AU8+AX8+BA8+BD8+BG8+BJ8+BM8+BP8+BS8+BV8+BY8+CB8+CE8+CH8+CK8+CN8+CZ8+CQ8+CT8+CW8 -> 0 | DD8: =+C8+F8+I8+L8+O8+R8+U8+X8+AA8+AD8+AG8+AJ8+AM8+AP8+AS8+AV8+AY8+BB8+BE8+BH8+BK8+BN8+BQ8+BT8+BW8+BZ8+CC8+CF8+CI8+CL8+CO8+DA8+CR8+CU8+CX8 -> 0 | DE8: =+D8+G8+J8+M8+P8+S8+V8+Y8+AE8+AH8+AK8+AQ8+AT8+AW8+AZ8+BC8+BF8+BI8+BL8+BO8+BR8+BU8+BX8+CA8+CD8+CG8+CJ8+CM8+CP8+DB8+AB8+AN8+CS8+CV8+CY8 -> 0
A9: 2 | DC9: =+B9+E9+H9+K9+N9+Q9+T9+W9+Z9+AC9+AF9+AI9+AL9+AO9+AR9+AU9+AX9+BA9+BD9+BG9+BJ9+BM9+BP9+BS9+BV9+BY9+CB9+CE9+CH9+CK9+CN9+CZ9+CQ9+CT9+CW9 -> 0 | DD9: =+C9+F9+I9+L9+O9+R9+U9+X9+AA9+AD9+AG9+AJ9+AM9+AP9+AS9+AV9+AY9+BB9+BE9+BH9+BK9+BN9+BQ9+BT9+BW9+BZ9+CC9+CF9+CI9+CL9+CO9+DA9+CR9+CU9+CX9 -> 0 | DE9: =+D9+G9+J9+M9+P9+S9+V9+Y9+AE9+AH9+AK9+AQ9+AT9+AW9+AZ9+BC9+BF9+BI9+BL9+BO9+BR9+BU9+BX9+CA9+CD9+CG9+CJ9+CM9+CP9+DB9+AB9+AN9+CS9+CV9+CY9 -> 0
A10: 3 | DC10: =+B10+E10+H10+K10+N10+Q10+T10+W10+Z10+AC10+AF10+AI10+AL10+AO10+AR10+AU10+AX10+BA10+BD10+BG10+BJ10+BM10+BP10+BS10+BV10+BY10+CB10+CE10+CH10+CK10+CN10+CZ10+CQ10+CT10+CW10 -> 0 | DD10: =+C10+F10+I10+L10+O10+R10+U10+X10+AA10+AD10+AG10+AJ10+AM10+AP10+AS10+AV10+AY10+BB10+BE10+BH10+BK10+BN10+BQ10+BT10+BW10+BZ10+CC10+CF10+CI10+CL10+CO10+DA10+CR10+CU10+CX10 -> 0 | DE10: =+D10+G10+J10+M10+P10+S10+V10+Y10+AE10+AH10+AK10+AQ10+AT10+AW10+AZ10+BC10+BF10+BI10+BL10+BO10+BR10+BU10+BX10+CA10+CD10+CG10+CJ10+CM10+CP10+DB10+AB10+AN10+CS10+CV10+CY10 -> 0
A11: 4 | DC11: =+B11+E11+H11+K11+N11+Q11+T11+W11+Z11+AC11+AF11+AI11+AL11+AO11+AR11+AU11+AX11+BA11+BD11+BG11+BJ11+BM11+BP11+BS11+BV11+BY11+CB11+CE11+CH11+CK11+CN11+CZ11+CQ11+CT11+CW11 -> 0 | DD11: =+C11+F11+I11+L11+O11+R11+U11+X11+AA11+AD11+AG11+AJ11+AM11+AP11+AS11+AV11+AY11+BB11+BE11+BH11+BK11+BN11+BQ11+BT11+BW11+BZ11+CC11+CF11+CI11+CL11+CO11+DA11+CR11+CU11+CX11 -> 0 | DE11: =+D11+G11+J11+M11+P11+S11+V11+Y11+AE11+AH11+AK11+AQ11+AT11+AW11+AZ11+BC11+BF11+BI11+BL11+BO11+BR11+BU11+BX11+CA11+CD11+CG11+CJ11+CM11+CP11+DB11+AB11+AN11+CS11+CV11+CY11 -> 0
A12: 5 | DC12: =+B12+E12+H12+K12+N12+Q12+T12+W12+Z12+AC12+AF12+AI12+AL12+AO12+AR12+AU12+AX12+BA12+BD12+BG12+BJ12+BM12+BP12+BS12+BV12+BY12+CB12+CE12+CH12+CK12+CN12+CZ12+CQ12+CT12+CW12 -> 0 | DD12: =+C12+F12+I12+L12+O12+R12+U12+X12+AA12+AD12+AG12+AJ12+AM12+AP12+AS12+AV12+AY12+BB12+BE12+BH12+BK12+BN12+BQ12+BT12+BW12+BZ12+CC12+CF12+CI12+CL12+CO12+DA12+CR12+CU12+CX12 -> 0 | DE12: =+D12+G12+J12+M12+P12+S12+V12+Y12+AE12+AH12+AK12+AQ12+AT12+AW12+AZ12+BC12+BF12+BI12+BL12+BO12+BR12+BU12+BX12+CA12+CD12+CG12+CJ12+CM12+CP12+DB12+AB12+AN12+CS12+CV12+CY12 -> 0
A13: 6 | DC13: =+B13+E13+H13+K13+N13+Q13+T13+W13+Z13+AC13+AF13+AI13+AL13+AO13+AR13+AU13+AX13+BA13+BD13+BG13+BJ13+BM13+BP13+BS13+BV13+BY13+CB13+CE13+CH13+CK13+CN13+CZ13+CQ13+CT13+CW13 -> 0 | DD13: =+C13+F13+I13+L13+O13+R13+U13+X13+AA13+AD13+AG13+AJ13+AM13+AP13+AS13+AV13+AY13+BB13+BE13+BH13+BK13+BN13+BQ13+BT13+BW13+BZ13+CC13+CF13+CI13+CL13+CO13+DA13+CR13+CU13+CX13 -> 0 | DE13: =+D13+G13+J13+M13+P13+S13+V13+Y13+AE13+AH13+AK13+AQ13+AT13+AW13+AZ13+BC13+BF13+BI13+BL13+BO13+BR13+BU13+BX13+CA13+CD13+CG13+CJ13+CM13+CP13+DB13+AB13+AN13+CS13+CV13+CY13 -> 0
A14: 7 | DC14: =+B14+E14+H14+K14+N14+Q14+T14+W14+Z14+AC14+AF14+AI14+AL14+AO14+AR14+AU14+AX14+BA14+BD14+BG14+BJ14+BM14+BP14+BS14+BV14+BY14+CB14+CE14+CH14+CK14+CN14+CZ14+CQ14+CT14+CW14 -> 0 | DD14: =+C14+F14+I14+L14+O14+R14+U14+X14+AA14+AD14+AG14+AJ14+AM14+AP14+AS14+AV14+AY14+BB14+BE14+BH14+BK14+BN14+BQ14+BT14+BW14+BZ14+CC14+CF14+CI14+CL14+CO14+DA14+CR14+CU14+CX14 -> 0 | DE14: =+D14+G14+J14+M14+P14+S14+V14+Y14+AE14+AH14+AK14+AQ14+AT14+AW14+AZ14+BC14+BF14+BI14+BL14+BO14+BR14+BU14+BX14+CA14+CD14+CG14+CJ14+CM14+CP14+DB14+AB14+AN14+CS14+CV14+CY14 -> 0
A15: 8 | DC15: =+B15+E15+H15+K15+N15+Q15+T15+W15+Z15+AC15+AF15+AI15+AL15+AO15+AR15+AU15+AX15+BA15+BD15+BG15+BJ15+BM15+BP15+BS15+BV15+BY15+CB15+CE15+CH15+CK15+CN15+CZ15+CQ15+CT15+CW15 -> 0 | DD15: =+C15+F15+I15+L15+O15+R15+U15+X15+AA15+AD15+AG15+AJ15+AM15+AP15+AS15+AV15+AY15+BB15+BE15+BH15+BK15+BN15+BQ15+BT15+BW15+BZ15+CC15+CF15+CI15+CL15+CO15+DA15+CR15+CU15+CX15 -> 0 | DE15: =+D15+G15+J15+M15+P15+S15+V15+Y15+AE15+AH15+AK15+AQ15+AT15+AW15+AZ15+BC15+BF15+BI15+BL15+BO15+BR15+BU15+BX15+CA15+CD15+CG15+CJ15+CM15+CP15+DB15+AB15+AN15+CS15+CV15+CY15 -> 0
A16: 9 | DC16: =+B16+E16+H16+K16+N16+Q16+T16+W16+Z16+AC16+AF16+AI16+AL16+AO16+AR16+AU16+AX16+BA16+BD16+BG16+BJ16+BM16+BP16+BS16+BV16+BY16+CB16+CE16+CH16+CK16+CN16+CZ16+CQ16+CT16+CW16 -> 0 | DD16: =+C16+F16+I16+L16+O16+R16+U16+X16+AA16+AD16+AG16+AJ16+AM16+AP16+AS16+AV16+AY16+BB16+BE16+BH16+BK16+BN16+BQ16+BT16+BW16+BZ16+CC16+CF16+CI16+CL16+CO16+DA16+CR16+CU16+CX16 -> 0 | DE16: =+D16+G16+J16+M16+P16+S16+V16+Y16+AE16+AH16+AK16+AQ16+AT16+AW16+AZ16+BC16+BF16+BI16+BL16+BO16+BR16+BU16+BX16+CA16+CD16+CG16+CJ16+CM16+CP16+DB16+AB16+AN16+CS16+CV16+CY16 -> 0
A17: 10 | DC17: =+B17+E17+H17+K17+N17+Q17+T17+W17+Z17+AC17+AF17+AI17+AL17+AO17+AR17+AU17+AX17+BA17+BD17+BG17+BJ17+BM17+BP17+BS17+BV17+BY17+CB17+CE17+CH17+CK17+CN17+CZ17+CQ17+CT17+CW17 -> 0 | DD17: =+C17+F17+I17+L17+O17+R17+U17+X17+AA17+AD17+AG17+AJ17+AM17+AP17+AS17+AV17+AY17+BB17+BE17+BH17+BK17+BN17+BQ17+BT17+BW17+BZ17+CC17+CF17+CI17+CL17+CO17+DA17+CR17+CU17+CX17 -> 0 | DE17: =+D17+G17+J17+M17+P17+S17+V17+Y17+AE17+AH17+AK17+AQ17+AT17+AW17+AZ17+BC17+BF17+BI17+BL17+BO17+BR17+BU17+BX17+CA17+CD17+CG17+CJ17+CM17+CP17+DB17+AB17+AN17+CS17+CV17+CY17 -> 0
A18: 11 | DC18: =+B18+E18+H18+K18+N18+Q18+T18+W18+Z18+AC18+AF18+AI18+AL18+AO18+AR18+AU18+AX18+BA18+BD18+BG18+BJ18+BM18+BP18+BS18+BV18+BY18+CB18+CE18+CH18+CK18+CN18+CZ18+CQ18+CT18+CW18 -> 0 | DD18: =+C18+F18+I18+L18+O18+R18+U18+X18+AA18+AD18+AG18+AJ18+AM18+AP18+AS18+AV18+AY18+BB18+BE18+BH18+BK18+BN18+BQ18+BT18+BW18+BZ18+CC18+CF18+CI18+CL18+CO18+DA18+CR18+CU18+CX18 -> 0 | DE18: =+D18+G18+J18+M18+P18+S18+V18+Y18+AE18+AH18+AK18+AQ18+AT18+AW18+AZ18+BC18+BF18+BI18+BL18+BO18+BR18+BU18+BX18+CA18+CD18+CG18+CJ18+CM18+CP18+DB18+AB18+AN18+CS18+CV18+CY18 -> 0
A19: 12 | DC19: =+B19+E19+H19+K19+N19+Q19+T19+W19+Z19+AC19+AF19+AI19+AL19+AO19+AR19+AU19+AX19+BA19+BD19+BG19+BJ19+BM19+BP19+BS19+BV19+BY19+CB19+CE19+CH19+CK19+CN19+CZ19+CQ19+CT19+CW19 -> 0 | DD19: =+C19+F19+I19+L19+O19+R19+U19+X19+AA19+AD19+AG19+AJ19+AM19+AP19+AS19+AV19+AY19+BB19+BE19+BH19+BK19+BN19+BQ19+BT19+BW19+BZ19+CC19+CF19+CI19+CL19+CO19+DA19+CR19+CU19+CX19 -> 0 | DE19: =+D19+G19+J19+M19+P19+S19+V19+Y19+AE19+AH19+AK19+AQ19+AT19+AW19+AZ19+BC19+BF19+BI19+BL19+BO19+BR19+BU19+BX19+CA19+CD19+CG19+CJ19+CM19+CP19+DB19+AB19+AN19+CS19+CV19+CY19 -> 0
... A33: 26 | DC33: =+B33+E33+H33+K33+N33+Q33+T33+W33+Z33+AC33+AF33+AI33+AL33+AO33+AR33+AU33+AX33+BA33+BD33+BG33+BJ33+BM33+BP33+BS33+BV33+BY33+CB33+CE33+CH33+CK33+CN33+CZ33+CQ33+CT33+CW33 -> 0 | DD33: =+C33+F33+I33+L33+O33+R33+U33+X33+AA33+AD33+AG33+AJ33+AM33+AP33+AS33+AV33+AY33+BB33+BE33+BH33+BK33+BN33+BQ33+BT33+BW33+BZ33+CC33+CF33+CI33+CL33+CO33+DA33+CR33+CU33+CX33 -> 0 | DE33: =+D33+G33+J33+M33+P33+S33+V33+Y33+AE33+AH33+AK33+AQ33+AT33+AW33+AZ33+BC33+BF33+BI33+BL33+BO33+BR33+BU33+BX33+CA33+CD33+CG33+CJ33+CM33+CP33+DB33+AB33+AN33+CS33+CV33+CY33 -> 0
A34: 27 | DC34: =+B34+E34+H34+K34+N34+Q34+T34+W34+Z34+AC34+AF34+AI34+AL34+AO34+AR34+AU34+AX34+BA34+BD34+BG34+BJ34+BM34+BP34+BS34+BV34+BY34+CB34+CE34+CH34+CK34+CN34+CZ34+CQ34+CT34+CW34 -> 0 | DD34: =+C34+F34+I34+L34+O34+R34+U34+X34+AA34+AD34+AG34+AJ34+AM34+AP34+AS34+AV34+AY34+BB34+BE34+BH34+BK34+BN34+BQ34+BT34+BW34+BZ34+CC34+CF34+CI34+CL34+CO34+DA34+CR34+CU34+CX34 -> 0 | DE34: =+D34+G34+J34+M34+P34+S34+V34+Y34+AE34+AH34+AK34+AQ34+AT34+AW34+AZ34+BC34+BF34+BI34+BL34+BO34+BR34+BU34+BX34+CA34+CD34+CG34+CJ34+CM34+CP34+DB34+AB34+AN34+CS34+CV34+CY34 -> 0 | DF34: =SUM(B34:DB34) -> 0
A35: 28 | DC35: =+B35+E35+H35+K35+N35+Q35+T35+W35+Z35+AC35+AF35+AI35+AL35+AO35+AR35+AU35+AX35+BA35+BD35+BG35+BJ35+BM35+BP35+BS35+BV35+BY35+CB35+CE35+CH35+CK35+CN35+CZ35+CQ35+CT35+CW35 -> 0 | DD35: =+C35+F35+I35+L35+O35+R35+U35+X35+AA35+AD35+AG35+AJ35+AM35+AP35+AS35+AV35+AY35+BB35+BE35+BH35+BK35+BN35+BQ35+BT35+BW35+BZ35+CC35+CF35+CI35+CL35+CO35+DA35+CR35+CU35+CX35 -> 0 | DE35: =+D35+G35+J35+M35+P35+S35+V35+Y35+AE35+AH35+AK35+AQ35+AT35+AW35+AZ35+BC35+BF35+BI35+BL35+BO35+BR35+BU35+BX35+CA35+CD35+CG35+CJ35+CM35+CP35+DB35+AB35+AN35+CS35+CV35+CY35 -> 0 | DF35: =SUM(B35:DB35) -> 0
A36: 29 | DC36: =+B36+E36+H36+K36+N36+Q36+T36+W36+Z36+AC36+AF36+AI36+AL36+AO36+AR36+AU36+AX36+BA36+BD36+BG36+BJ36+BM36+BP36+BS36+BV36+BY36+CB36+CE36+CH36+CK36+CN36+CZ36+CQ36+CT36+CW36 -> 0 | DD36: =+C36+F36+I36+L36+O36+R36+U36+X36+AA36+AD36+AG36+AJ36+AM36+AP36+AS36+AV36+AY36+BB36+BE36+BH36+BK36+BN36+BQ36+BT36+BW36+BZ36+CC36+CF36+CI36+CL36+CO36+DA36+CR36+CU36+CX36 -> 0 | DE36: =+D36+G36+J36+M36+P36+S36+V36+Y36+AE36+AH36+AK36+AQ36+AT36+AW36+AZ36+BC36+BF36+BI36+BL36+BO36+BR36+BU36+BX36+CA36+CD36+CG36+CJ36+CM36+CP36+DB36+AB36+AN36+CS36+CV36+CY36 -> 0 | DF36: =SUM(B36:DB36) -> 0
A37: 30 | DC37: =+B37+E37+H37+K37+N37+Q37+T37+W37+Z37+AC37+AF37+AI37+AL37+AO37+AR37+AU37+AX37+BA37+BD37+BG37+BJ37+BM37+BP37+BS37+BV37+BY37+CB37+CE37+CH37+CK37+CN37+CZ37+CQ37+CT37+CW37 -> 0 | DD37: =+C37+F37+I37+L37+O37+R37+U37+X37+AA37+AD37+AG37+AJ37+AM37+AP37+AS37+AV37+AY37+BB37+BE37+BH37+BK37+BN37+BQ37+BT37+BW37+BZ37+CC37+CF37+CI37+CL37+CO37+DA37+CR37+CU37+CX37 -> 0 | DE37: =+D37+G37+J37+M37+P37+S37+V37+Y37+AE37+AH37+AK37+AQ37+AT37+AW37+AZ37+BC37+BF37+BI37+BL37+BO37+BR37+BU37+BX37+CA37+CD37+CG37+CJ37+CM37+CP37+DB37+AB37+AN37+CS37+CV37+CY37 -> 0 | DF37: =SUM(B37:DB37) -> 0
A38: 31 | DC38: =+B38+E38+H38+K38+N38+Q38+T38+W38+Z38+AC38+AF38+AI38+AL38+AO38+AR38+AU38+AX38+BA38+BD38+BG38+BJ38+BM38+BP38+BS38+BV38+BY38+CB38+CE38+CH38+CK38+CN38+CZ38+CQ38+CT38+CW38 -> 0 | DD38: =+C38+F38+I38+L38+O38+R38+U38+X38+AA38+AD38+AG38+AJ38+AM38+AP38+AS38+AV38+AY38+BB38+BE38+BH38+BK38+BN38+BQ38+BT38+BW38+BZ38+CC38+CF38+CI38+CL38+CO38+DA38+CR38+CU38+CX38 -> 0 | DE38: =+D38+G38+J38+M38+P38+S38+V38+Y38+AE38+AH38+AK38+AQ38+AT38+AW38+AZ38+BC38+BF38+BI38+BL38+BO38+BR38+BU38+BX38+CA38+CD38+CG38+CJ38+CM38+CP38+DB38+AB38+AN38+CS38+CV38+CY38 -> 0
B39: =SUM(B8:B38) -> 0 | C39: =SUM(C8:C38) -> 0 | D39: =SUM(D8:D38) -> 0 | E39: =SUM(E8:E38) -> 0 | F39: =SUM(F8:F38) -> 0 | G39: =SUM(G8:G38) -> 0 | H39: =SUM(H8:H38) -> 0 | I39: =SUM(I8:I38) -> 0 | ... DE39: =SUM(DE8:DE38) -> 0
D41: soir
A42: JOUR | B42: A01 | E42: A02 | H42: A03 | K42: A04 | N42: A05 | Q42: A06 | T42: A07 | W42: A08 | Z42: A09 | AC42: A10 | AF42: A11 | AI42: A12 | AL42: A13 | AO42: A14 | AR42: A15 | AU42: A16 | AX42: A17 | BA42: A18 | BD42: A19 | BG42: A20 | BJ42: A21 | BM42: A22 | BP42: A23 | BS42: A24 | BV42: A25 | BY42: A26 | CB42: A27 | CE42: A28 | CH42: A29 | CK42: A30 | CN42: A31 | CQ42: A32 | CT42: A33 | CW42: A34 | CZ42: A35 | DC42: TOTAL PAR TARIF
B43: 20DA | C43: 25DA | D43: 30DA | E43: 20DA | F43: 25DA | G43: 30DA | H43: 20DA | I43: 25DA | J43: 30DA | K43: 20DA | L43: 25DA | M43: 30DA | N43: 20DA | O43: 25DA | P43: 30DA | Q43: 20DA | R43: 25DA | S43: 30DA | T43: 20DA | U43: 25DA | V43: 30DA | W43: 20DA | X43: 25DA | Y43: 30DA | Z43: 20DA | AA43: 25DA | AB43: 30DA | AC43: 20DA | AD43: 25DA | AE43: 30DA | AF43: 20DA | AG43: 25DA | AH43: 30DA | AI43: 20DA | AJ43: 25DA | AK43: 30DA | AL43: 20DA | AM43: 25DA | AN43: 30DA | AO43: 20DA | AP43: 25DA | AQ43: 30DA | AR43: 20DA | AS43: 25DA | AT43: 30DA | AU43: 20DA | AV43: 25DA | AW43: 30DA | AX43: 20DA | AY43: 25DA | AZ43: 30DA | BA43: 20DA | BB43: 25DA | BC43: 30DA | BD43: 20DA | BE43: 25DA | BF43: 30DA | BG43: 20DA | BH43: 25DA | BI43: 30DA | BJ43: 20DA | BK43: 25DA | BL43: 30DA | BM43: 20DA | BN43: 25DA | BO43: 30DA | BP43: 20DA | BQ43: 25DA | BR43: 30DA | BS43: 20DA | BT43: 25DA | BU43: 30DA | BV43: 20DA | BW43: 25DA | BX43: 30DA | BY43: 20DA | BZ43: 25DA | CA43: 30DA | CB43: 20DA | CC43: 25DA | CD43: 30DA | CE43: 20DA | CF43: 25DA | CG43: 30DA | CH43: 20DA | CI43: 25DA | CJ43: 30DA | CK43: 20DA | CL43: 25DA | CM43: 30DA | CN43: 20DA | CO43: 25DA | CP43: 30DA | CQ43: 20DA | CR43: 25DA | CS43: 30DA | CT43: 20DA | CU43: 25DA | CV43: 30DA | CW43: 20DA | CX43: 25DA | CY43: 30DA | CZ43: 20DA | DA43: 25DA | DB43: 30DA | DC43: 20DA | DD43: 25DA | DE43: 30DA
A44: 1 | DC44: =+B44+E44+H44+K44+N44+Q44+T44+W44+Z44+AC44+AF44+AI44+AL44+AO44+AR44+AU44+AX44+BA44+BD44+BG44+BJ44+BM44+BP44+BS44+BV44+BY44+CB44+CE44+CH44+CK44+CN44+CZ44+CQ44+CT44+CW44 -> 0 | DD44: =+C44+F44+I44+L44+O44+R44+U44+X44+AA44+AD44+AG44+AJ44+AM44+AP44+AS44+AV44+AY44+BB44+BE44+BH44+BK44+BN44+BQ44+BT44+BW44+BZ44+CC44+CF44+CI44+CL44+CO44+DA44+CR44+CU44+CX44 -> 0 | DE44: =+D44+G44+J44+M44+P44+S44+V44+Y44+AB44+AE44+AH44+AK44+AN44+AQ44+AT44+AW44+AZ44+BC44+BF44+BI44+BL44+BO44+BR44+BU44+BX44+CA44+CD44+CG44+CJ44+CM44+CP44+DB44+CS44+CV44+CY44 -> 0
A45: 2 | DC45: =+B45+E45+H45+K45+N45+Q45+T45+W45+Z45+AC45+AF45+AI45+AL45+AO45+AR45+AU45+AX45+BA45+BD45+BG45+BJ45+BM45+BP45+BS45+BV45+BY45+CB45+CE45+CH45+CK45+CN45+CZ45+CQ45+CT45+CW45 -> 0 | DD45: =+C45+F45+I45+L45+O45+R45+U45+X45+AA45+AD45+AG45+AJ45+AM45+AP45+AS45+AV45+AY45+BB45+BE45+BH45+BK45+BN45+BQ45+BT45+BW45+BZ45+CC45+CF45+CI45+CL45+CO45+DA45+CR45+CU45+CX45 -> 0 | DE45: =+D45+G45+J45+M45+P45+S45+V45+Y45+AB45+AE45+AH45+AK45+AN45+AQ45+AT45+AW45+AZ45+BC45+BF45+BI45+BL45+BO45+BR45+BU45+BX45+CA45+CD45+CG45+CJ45+CM45+CP45+DB45+CS45+CV45+CY45 -> 0
A46: 3 | DC46: =+B46+E46+H46+K46+N46+Q46+T46+W46+Z46+AC46+AF46+AI46+AL46+AO46+AR46+AU46+AX46+BA46+BD46+BG46+BJ46+BM46+BP46+BS46+BV46+BY46+CB46+CE46+CH46+CK46+CN46+CZ46+CQ46+CT46+CW46 -> 0 | DD46: =+C46+F46+I46+L46+O46+R46+U46+X46+AA46+AD46+AG46+AJ46+AM46+AP46+AS46+AV46+AY46+BB46+BE46+BH46+BK46+BN46+BQ46+BT46+BW46+BZ46+CC46+CF46+CI46+CL46+CO46+DA46+CR46+CU46+CX46 -> 0 | DE46: =+D46+G46+J46+M46+P46+S46+V46+Y46+AB46+AE46+AH46+AK46+AN46+AQ46+AT46+AW46+AZ46+BC46+BF46+BI46+BL46+BO46+BR46+BU46+BX46+CA46+CD46+CG46+CJ46+CM46+CP46+DB46+CS46+CV46+CY46 -> 0
A47: 4 | DC47: =+B47+E47+H47+K47+N47+Q47+T47+W47+Z47+AC47+AF47+AI47+AL47+AO47+AR47+AU47+AX47+BA47+BD47+BG47+BJ47+BM47+BP47+BS47+BV47+BY47+CB47+CE47+CH47+CK47+CN47+CZ47+CQ47+CT47+CW47 -> 0 | DD47: =+C47+F47+I47+L47+O47+R47+U47+X47+AA47+AD47+AG47+AJ47+AM47+AP47+AS47+AV47+AY47+BB47+BE47+BH47+BK47+BN47+BQ47+BT47+BW47+BZ47+CC47+CF47+CI47+CL47+CO47+DA47+CR47+CU47+CX47 -> 0 | DE47: =+D47+G47+J47+M47+P47+S47+V47+Y47+AB47+AE47+AH47+AK47+AN47+AQ47+AT47+AW47+AZ47+BC47+BF47+BI47+BL47+BO47+BR47+BU47+BX47+CA47+CD47+CG47+CJ47+CM47+CP47+DB47+CS47+CV47+CY47 -> 0
A48: 5 | DC48: =+B48+E48+H48+K48+N48+Q48+T48+W48+Z48+AC48+AF48+AI48+AL48+AO48+AR48+AU48+AX48+BA48+BD48+BG48+BJ48+BM48+BP48+BS48+BV48+BY48+CB48+CE48+CH48+CK48+CN48+CZ48+CQ48+CT48+CW48 -> 0 | DD48: =+C48+F48+I48+L48+O48+R48+U48+X48+AA48+AD48+AG48+AJ48+AM48+AP48+AS48+AV48+AY48+BB48+BE48+BH48+BK48+BN48+BQ48+BT48+BW48+BZ48+CC48+CF48+CI48+CL48+CO48+DA48+CR48+CU48+CX48 -> 0 | DE48: =+D48+G48+J48+M48+P48+S48+V48+Y48+AB48+AE48+AH48+AK48+AN48+AQ48+AT48+AW48+AZ48+BC48+BF48+BI48+BL48+BO48+BR48+BU48+BX48+CA48+CD48+CG48+CJ48+CM48+CP48+DB48+CS48+CV48+CY48 -> 0
A49: 6 | DC49: =+B49+E49+H49+K49+N49+Q49+T49+W49+Z49+AC49+AF49+AI49+AL49+AO49+AR49+AU49+AX49+BA49+BD49+BG49+BJ49+BM49+BP49+BS49+BV49+BY49+CB49+CE49+CH49+CK49+CN49+CZ49+CQ49+CT49+CW49 -> 0 | DD49: =+C49+F49+I49+L49+O49+R49+U49+X49+AA49+AD49+AG49+AJ49+AM49+AP49+AS49+AV49+AY49+BB49+BE49+BH49+BK49+BN49+BQ49+BT49+BW49+BZ49+CC49+CF49+CI49+CL49+CO49+DA49+CR49+CU49+CX49 -> 0 | DE49: =+D49+G49+J49+M49+P49+S49+V49+Y49+AB49+AE49+AH49+AK49+AN49+AQ49+AT49+AW49+AZ49+BC49+BF49+BI49+BL49+BO49+BR49+BU49+BX49+CA49+CD49+CG49+CJ49+CM49+CP49+DB49+CS49+CV49+CY49 -> 0
A50: 7 | DC50: =+B50+E50+H50+K50+N50+Q50+T50+W50+Z50+AC50+AF50+AI50+AL50+AO50+AR50+AU50+AX50+BA50+BD50+BG50+BJ50+BM50+BP50+BS50+BV50+BY50+CB50+CE50+CH50+CK50+CN50+CZ50+CQ50+CT50+CW50 -> 0 | DD50: =+C50+F50+I50+L50+O50+R50+U50+X50+AA50+AD50+AG50+AJ50+AM50+AP50+AS50+AV50+AY50+BB50+BE50+BH50+BK50+BN50+BQ50+BT50+BW50+BZ50+CC50+CF50+CI50+CL50+CO50+DA50+CR50+CU50+CX50 -> 0 | DE50: =+D50+G50+J50+M50+P50+S50+V50+Y50+AB50+AE50+AH50+AK50+AN50+AQ50+AT50+AW50+AZ50+BC50+BF50+BI50+BL50+BO50+BR50+BU50+BX50+CA50+CD50+CG50+CJ50+CM50+CP50+DB50+CS50+CV50+CY50 -> 0
A51: 8 | DC51: =+B51+E51+H51+K51+N51+Q51+T51+W51+Z51+AC51+AF51+AI51+AL51+AO51+AR51+AU51+AX51+BA51+BD51+BG51+BJ51+BM51+BP51+BS51+BV51+BY51+CB51+CE51+CH51+CK51+CN51+CZ51+CQ51+CT51+CW51 -> 0 | DD51: =+C51+F51+I51+L51+O51+R51+U51+X51+AA51+AD51+AG51+AJ51+AM51+AP51+AS51+AV51+AY51+BB51+BE51+BH51+BK51+BN51+BQ51+BT51+BW51+BZ51+CC51+CF51+CI51+CL51+CO51+DA51+CR51+CU51+CX51 -> 0 | DE51: =+D51+G51+J51+M51+P51+S51+V51+Y51+AB51+AE51+AH51+AK51+AN51+AQ51+AT51+AW51+AZ51+BC51+BF51+BI51+BL51+BO51+BR51+BU51+BX51+CA51+CD51+CG51+CJ51+CM51+CP51+DB51+CS51+CV51+CY51 -> 0
A52: 9 | DC52: =+B52+E52+H52+K52+N52+Q52+T52+W52+Z52+AC52+AF52+AI52+AL52+AO52+AR52+AU52+AX52+BA52+BD52+BG52+BJ52+BM52+BP52+BS52+BV52+BY52+CB52+CE52+CH52+CK52+CN52+CZ52+CQ52+CT52+CW52 -> 0 | DD52: =+C52+F52+I52+L52+O52+R52+U52+X52+AA52+AD52+AG52+AJ52+AM52+AP52+AS52+AV52+AY52+BB52+BE52+BH52+BK52+BN52+BQ52+BT52+BW52+BZ52+CC52+CF52+CI52+CL52+CO52+DA52+CR52+CU52+CX52 -> 0 | DE52: =+D52+G52+J52+M52+P52+S52+V52+Y52+AB52+AE52+AH52+AK52+AN52+AQ52+AT52+AW52+AZ52+BC52+BF52+BI52+BL52+BO52+BR52+BU52+BX52+CA52+CD52+CG52+CJ52+CM52+CP52+DB52+CS52+CV52+CY52 -> 0
A53: 10 | DC53: =+B53+E53+H53+K53+N53+Q53+T53+W53+Z53+AC53+AF53+AI53+AL53+AO53+AR53+AU53+AX53+BA53+BD53+BG53+BJ53+BM53+BP53+BS53+BV53+BY53+CB53+CE53+CH53+CK53+CN53+CZ53+CQ53+CT53+CW53 -> 0 | DD53: =+C53+F53+I53+L53+O53+R53+U53+X53+AA53+AD53+AG53+AJ53+AM53+AP53+AS53+AV53+AY53+BB53+BE53+BH53+BK53+BN53+BQ53+BT53+BW53+BZ53+CC53+CF53+CI53+CL53+CO53+DA53+CR53+CU53+CX53 -> 0 | DE53: =+D53+G53+J53+M53+P53+S53+V53+Y53+AB53+AE53+AH53+AK53+AN53+AQ53+AT53+AW53+AZ53+BC53+BF53+BI53+BL53+BO53+BR53+BU53+BX53+CA53+CD53+CG53+CJ53+CM53+CP53+DB53+CS53+CV53+CY53 -> 0
A54: 11 | DC54: =+B54+E54+H54+K54+N54+Q54+T54+W54+Z54+AC54+AF54+AI54+AL54+AO54+AR54+AU54+AX54+BA54+BD54+BG54+BJ54+BM54+BP54+BS54+BV54+BY54+CB54+CE54+CH54+CK54+CN54+CZ54+CQ54+CT54+CW54 -> 0 | DD54: =+C54+F54+I54+L54+O54+R54+U54+X54+AA54+AD54+AG54+AJ54+AM54+AP54+AS54+AV54+AY54+BB54+BE54+BH54+BK54+BN54+BQ54+BT54+BW54+BZ54+CC54+CF54+CI54+CL54+CO54+DA54+CR54+CU54+CX54 -> 0 | DE54: =+D54+G54+J54+M54+P54+S54+V54+Y54+AB54+AE54+AH54+AK54+AN54+AQ54+AT54+AW54+AZ54+BC54+BF54+BI54+BL54+BO54+BR54+BU54+BX54+CA54+CD54+CG54+CJ54+CM54+CP54+DB54+CS54+CV54+CY54 -> 0
A55: 12 | DC55: =+B55+E55+H55+K55+N55+Q55+T55+W55+Z55+AC55+AF55+AI55+AL55+AO55+AR55+AU55+AX55+BA55+BD55+BG55+BJ55+BM55+BP55+BS55+BV55+BY55+CB55+CE55+CH55+CK55+CN55+CZ55+CQ55+CT55+CW55 -> 0 | DD55: =+C55+F55+I55+L55+O55+R55+U55+X55+AA55+AD55+AG55+AJ55+AM55+AP55+AS55+AV55+AY55+BB55+BE55+BH55+BK55+BN55+BQ55+BT55+BW55+BZ55+CC55+CF55+CI55+CL55+CO55+DA55+CR55+CU55+CX55 -> 0 | DE55: =+D55+G55+J55+M55+P55+S55+V55+Y55+AB55+AE55+AH55+AK55+AN55+AQ55+AT55+AW55+AZ55+BC55+BF55+BI55+BL55+BO55+BR55+BU55+BX55+CA55+CD55+CG55+CJ55+CM55+CP55+DB55+CS55+CV55+CY55 -> 0
... A69: 26 | DC69: =+B69+E69+H69+K69+N69+Q69+T69+W69+Z69+AC69+AF69+AI69+AL69+AO69+AR69+AU69+AX69+BA69+BD69+BG69+BJ69+BM69+BP69+BS69+BV69+BY69+CB69+CE69+CH69+CK69+CN69+CZ69+CQ69+CT69+CW69 -> 0 | DD69: =+C69+F69+I69+L69+O69+R69+U69+X69+AA69+AD69+AG69+AJ69+AM69+AP69+AS69+AV69+AY69+BB69+BE69+BH69+BK69+BN69+BQ69+BT69+BW69+BZ69+CC69+CF69+CI69+CL69+CO69+DA69+CR69+CU69+CX69 -> 0 | DE69: =+D69+G69+J69+M69+P69+S69+V69+Y69+AB69+AE69+AH69+AK69+AN69+AQ69+AT69+AW69+AZ69+BC69+BF69+BI69+BL69+BO69+BR69+BU69+BX69+CA69+CD69+CG69+CJ69+CM69+CP69+DB69+CS69+CV69+CY69 -> 0
A70: 27 | DC70: =+B70+E70+H70+K70+N70+Q70+T70+W70+Z70+AC70+AF70+AI70+AL70+AO70+AR70+AU70+AX70+BA70+BD70+BG70+BJ70+BM70+BP70+BS70+BV70+BY70+CB70+CE70+CH70+CK70+CN70+CZ70+CQ70+CT70+CW70 -> 0 | DD70: =+C70+F70+I70+L70+O70+R70+U70+X70+AA70+AD70+AG70+AJ70+AM70+AP70+AS70+AV70+AY70+BB70+BE70+BH70+BK70+BN70+BQ70+BT70+BW70+BZ70+CC70+CF70+CI70+CL70+CO70+DA70+CR70+CU70+CX70 -> 0 | DE70: =+D70+G70+J70+M70+P70+S70+V70+Y70+AB70+AE70+AH70+AK70+AN70+AQ70+AT70+AW70+AZ70+BC70+BF70+BI70+BL70+BO70+BR70+BU70+BX70+CA70+CD70+CG70+CJ70+CM70+CP70+DB70+CS70+CV70+CY70 -> 0 | DF70: =SUM(B70:DA70) -> 0
...

Sheet LIGNE
A1: matin
A2: JOUR | B2: LIGNE 1B | E2: LIGNE 16 | J2: LIGNE 09 | N2: LIGNE 11 | S2: LIGNE 27 | X2: LIGNE 26 | AH2: LIGNE 28 | AP2: LIGNE 03 | AT2: LIGNE 25 | AZ2: LAC | BL2: LIGNE4B | BR2: TOTAL
B3: 20DA | C3: 20DA | D3: 20DA | E3: 20DA | F3: 20DA | G3: 20DA | H3: 20DA | I3: 20DA | J3: 20DA | K3: 20DA | L3: 20DA | M3: 20DA | N3: 20DA | O3: 20DA | P3: 20DA | Q3: 20DA | R3: 20DA | S3: 20DA | T3: 20DA | U3: 20DA | V3: 20DA | W3: 20DA | X3: 20DA | Y3: 30DA | Z3: 20DA | AA3: 30DA | AB3: 20DA | AC3: 30DA | AD3: 20DA | AE3: 30DA | AF3: 20DA | AG3: 30DA | AH3: 20DA | AI3: 25DA | AJ3: 20DA | AK3: 25DA | AL3: 20DA | AM3: 25DA | AN3: 20DA | AO3: 25DA | AP3: 20DA | AQ3: 20DA | AR3: 20DA | AS3: 20DA | AT3: 20DA | AU3: 20DA | AV3: 20DA | AW3: 20DA | AX3: 20DA | AY3: 20DA | AZ3: 20DA | BA3: 25DA | BB3: 30DA | BC3: 20DA | BD3: 25DA | BE3: 30DA | BF3: 20DA | BG3: 25DA | BH3: 30DA | BI3: 20DA | BJ3: 25DA | BK3: 30DA | BL3: 20DA | BM3: 20DA | BN3: 20DA | BO3: 20DA | BP3: 20DA | BQ3: 20DA
A4: 1 | BR4: =SUM(B4:BQ4) -> 0
A5: 2 | BR5: =SUM(B5:BQ5) -> 0
A6: 3 | BR6: =SUM(B6:BQ6) -> 0
A7: 4 | BR7: =SUM(B7:BQ7) -> 0
A8: 5 | BR8: =SUM(B8:BQ8) -> 0
A9: 6 | BR9: =SUM(B9:BQ9) -> 0
A10: 7 | BR10: =SUM(B10:BQ10) -> 0
A11: 8 | BR11: =SUM(B11:BQ11) -> 0
A12: 9 | BR12: =SUM(B12:BQ12) -> 0
A13: 10 | BR13: =SUM(B13:BQ13) -> 0
A14: 11 | BR14: =SUM(B14:BQ14) -> 0
A15: 12 | BR15: =SUM(B15:BQ15) -> 0
... A34: 31 | BR34: =SUM(B34:BQ34) -> 0
B35: =SUM(B4:B34) -> 0 | C35: =SUM(C4:C34) -> 0 | D35: =SUM(D4:D34) -> 0 | E35: =SUM(E4:E34) -> 0 | F35: =SUM(F4:F34) -> 0 | G35: =SUM(G4:G34) -> 0 | H35: =SUM(H4:H34) -> 0 | I35: =SUM(I4:I34) -> 0 | ... BR35: =SUM(BR4:BR34) -> 0
E37: soir
A38: JOUR | B38: LIGNE 1B | E38: LIGNE 16 | J38: LIGNE 09 | N38: LIGNE 11 | S38: LIGNE 27 | X38: LIGNE 26 | AH38: LIGNE 28 | AP38: LIGNE 03 | AT38: LIGNE 25 | AZ38: LAC | BL38: LIGNE4B | BR38: TOTAL
B39: 20DA | C39: 20DA | D39: 20DA | E39: 20DA | F39: 20DA | G39: 20DA | H39: 20DA | I39: 20DA | J39: 20DA | K39: 20DA | L39: 20DA | M39: 20DA | N39: 20DA | O39: 20DA | P39: 20DA | Q39: 20DA | R39: 20DA | S39: 20DA | T39: 20DA | U39: 20DA | V39: 20DA | W39: 20DA | X39: 20DA | Y39: 30DA | Z39: 20DA | AA39: 30DA | AB39: 20DA | AC39: 30DA | AD39: 20DA | AE39: 30DA | AF39: 20DA | AG39: 30DA | AH39: 20DA | AI39: 25DA | AJ39: 20DA | AK39: 25DA | AL39: 20DA | AM39: 25DA | AN39: 20DA | AO39: 25DA | AP39: 20DA | AQ39: 20DA | AR39: 20DA | AS39: 20DA | AT39: 20DA | AU39: 20DA | AV39: 20DA | AW39: 20DA | AX39: 20DA | AY39: 20DA | AZ39: 20DA | BA39: 25DA | BB39: 30DA | BC39: 20DA | BD39: 25DA | BE39: 30DA | BF39: 20DA | BG39: 25DA | BH39: 30DA | BI39: 20DA | BJ39: 25DA | BK39: 30DA | BL39: 20DA | BM39: 20DA | BN39: 20DA | BO39: 20DA | BP39: 20DA | BQ39: 20DA
A40: 1 | BR40: =SUM(B40:BQ40) -> 0
A41: 2 | BR41: =SUM(B41:BQ41) -> 0
A42: 3 | BR42: =SUM(B42:BQ42) -> 0
A43: 4 | BR43: =SUM(B43:BQ43) -> 0
A44: 5 | BR44: =SUM(B44:BQ44) -> 0
A45: 6 | BR45: =SUM(B45:BQ45) -> 0
A46: 7 | BR46: =SUM(B46:BQ46) -> 0
A47: 8 | BR47: =SUM(B47:BQ47) -> 0
A48: 9 | BR48: =SUM(B48:BQ48) -> 0
A49: 10 | BR49: =SUM(B49:BQ49) -> 0
A50: 11 | BR50: =SUM(B50:BQ50) -> 0
A51: 12 | BR51: =SUM(B51:BQ51) -> 0
... A70: 31 | BR70: =SUM(B70:BQ70) -> 0
B71: =SUM(B40:B70) -> 0 | C71: =SUM(C40:C70) -> 0 | D71: =SUM(D40:D70) -> 0 | E71: =SUM(E40:E70) -> 0 | F71: =SUM(F40:F70) -> 0 | G71: =SUM(G40:G70) -> 0 | H71: =SUM(H40:H70) -> 0 | I71: =SUM(I40:I70) -> 0 | ... BR71: =SUM(BR40:BR70) -> 0
E72: nuit
A73: JOUR | B73: LIGNE 1B | E73: LIGNE 16 | J73: LIGNE 09 | N73: LIGNE 11 | S73: LIGNE 27 | X73: LIGNE 26 | AH73: LIGNE 28 | AP73: LIGNE 03 | AT73: LIGNE 25 | AZ73: LAC | BL73: LIGNE4B | BR73: TOTAL
B74: 20DA | C74: 20DA | D74: 20DA | E74: 20DA | F74: 20DA | G74: 20DA | H74: 20DA | I74: 20DA | J74: 20DA | K74: 20DA | L74: 20DA | M74: 20DA | N74: 20DA | O74: 20DA | P74: 20DA | Q74: 20DA | R74: 20DA | S74: 20DA | T74: 20DA | U74: 20DA | V74: 20DA | W74: 20DA | X74: 20DA | Y74: 30DA | Z74: 20DA | AA74: 30DA | AB74: 20DA | AC74: 30DA | AD74: 20DA | AE74: 30DA | AF74: 20DA | AG74: 30DA | AH74: 20DA | AI74: 25DA | AJ74: 20DA | AK74: 25DA | AL74: 20DA | AM74: 25DA | AN74: 20DA | AO74: 25DA | AP74: 20DA | AQ74: 20DA | AR74: 20DA | AS74: 20DA | AT74: 20DA | AU74: 20DA | AV74: 20DA | AW74: 20DA | AX74: 20DA | AY74: 20DA | AZ74: 20DA | BA74: 25DA | BB74: 30DA | BC74: 20DA | BD74: 25DA | BE74: 30DA | BF74: 20DA | BG74: 25DA | BH74: 30DA | BI74: 20DA | BJ74: 25DA | BK74: 30DA | BL74: 20DA | BM74: 20DA | BN74: 20DA | BO74: 20DA | BP74: 20DA | BQ74: 20DA
A75: 1 | BR75: =SUM(B75:BQ75) -> 0
A76: 2 | BR76: =SUM(B76:BQ76) -> 0
A77: 3 | BR77: =SUM(B77:BQ77) -> 0
...

Sheet RETAION-BUS
A3: MATIN | AL3: soir | BW3: NUIT
A4: JOUR | B4: A01 | C4: A02 | D4: A03 | E4: A04 | F4: A05 | G4: A06 | H4: A07 | I4: A08 | J4: A09 | K4: A10 | L4: A11 | M4: A12 | N4: A13 | O4: A14 | P4: A15 | Q4: A16 | R4: A17 | S4: A18 | T4: A19 | U4: A20 | V4: A21 | W4: A22 | X4: A23 | Y4: A24 | Z4: A25 | AA4: A26 | AB4: A27 | AC4: A28 | AD4: A29 | AE4: A30 | AF4: A31 | AG4: A32 | AH4: A33 | AI4: A34 | AJ4: A35 | AK4: TOTAL | AL4: JOUR | AM4: A01 | AN4: A02 | AO4: A03 | AP4: A04 | AQ4: A05 | AR4: A06 | AS4: A07 | AT4: A08 | AU4: A09 | AV4: A10 | AW4: A11 | AX4: A12 | AY4: A13 | AZ4: A14 | BA4: A15 | BB4: A16 | BC4: A17 | BD4: A18 | BE4: A19 | BF4: A20 | BG4: A21 | BH4: A22 | BI4: A23 | BJ4: A24 | BK4: A25 | BL4: A26 | BM4: A27 | BN4: A28 | BO4: A29 | BP4: A30 | BQ4: A31 | BR4: A32 | BS4: A33 | BT4: A34 | BU4: A35 | BV4: TOTAL | BW4: JOUR | BX4: A01 | BY4: A02 | BZ4: A03 | CA4: A04 | CB4: A05 | CC4: A06 | CD4: A07 | CE4: A08 | CF4: A09 | CG4: A10 | CH4: A11 | CI4: A12 | CJ4: A13 | CK4: A14 | CL4: A15 | CM4: A16 | CN4: A17 | CO4: A18 | CP4: A19 | CQ4: A20 | CR4: A21 | CS4: A22 | CT4: A23 | CU4: A24 | CV4: A25 | CW4: A26 | CX4: A27 | CY4: A28 | CZ4: A29 | DA4: A30 | DB4: A31 | DC4: A32 | DD4: A33 | DE4: A34 | DF4: A35 | DG4: TOTAL
A5: 1 | AK5: =SUM(B5:AJ5) -> 0 | AL5: 1 | BV5: =SUM(AM5:BU5) -> 0 | BW5: 1 | DG5: =SUM(BX5:DF5) -> 0
A6: 2 | AK6: =SUM(B6:AJ6) -> 0 | AL6: 2 | BV6: =SUM(AM6:BU6) -> 0 | BW6: 2 | DG6: =SUM(BX6:DF6) -> 0
A7: 3 | AK7: =SUM(B7:AJ7) -> 0 | AL7: 3 | BV7: =SUM(AM7:BU7) -> 0 | BW7: 3 | DG7: =SUM(BX7:DF7) -> 0
A8: 4 | AK8: =SUM(B8:AJ8) -> 0 | AL8: 4 | BV8: =SUM(AM8:BU8) -> 0 | BW8: 4 | DG8: =SUM(BX8:DF8) -> 0
A9: 5 | AK9: =SUM(B9:AJ9) -> 0 | AL9: 5 | BV9: =SUM(AM9:BU9) -> 0 | BW9: 5 | DG9: =SUM(BX9:DF9) -> 0
A10: 6 | AK10: =SUM(B10:AJ10) -> 0 | AL10: 6 | BV10: =SUM(AM10:BU10) -> 0 | BW10: 6 | DG10: =SUM(BX10:DF10) -> 0
A11: 7 | AK11: =SUM(B11:AJ11) -> 0 | AL11: 7 | BV11: =SUM(AM11:BU11) -> 0 | BW11: 7 | DG11: =SUM(BX11:DF11) -> 0
A12: 8 | AK12: =SUM(B12:AJ12) -> 0 | AL12: 8 | BV12: =SUM(AM12:BU12) -> 0 | BW12: 8 | DG12: =SUM(BX12:DF12) -> 0
A13: 9 | AK13: =SUM(B13:AJ13) -> 0 | AL13: 9 | BV13: =SUM(AM13:BU13) -> 0 | BW13: 9 | DG13: =SUM(BX13:DF13) -> 0
A14: 10 | AK14: =SUM(B14:AJ14) -> 0 | AL14: 10 | BV14: =SUM(AM14:BU14) -> 0 | BW14: 10 | DG14: =SUM(BX14:DF14) -> 0
A15: 11 | AK15: =SUM(B15:AJ15) -> 0 | AL15: 11 | BV15: =SUM(AM15:BU15) -> 0 | BW15: 11 | DG15: =SUM(BX15:DF15) -> 0
A16: 12 | AK16: =SUM(B16:AJ16) -> 0 | AL16: 12 | BV16: =SUM(AM16:BU16) -> 0 | BW16: 12 | DG16: =SUM(BX16:DF16) -> 0
... A35: 31 | AK35: =SUM(B35:AJ35) -> 0 | AL35: 31 | BV35: =SUM(AM35:BU35) -> 0 | BW35: 31 | DG35: =SUM(BX35:DF35) -> 0
A36: T | B36: =SUM(B5:B35) -> 0 | C36: =SUM(C5:C35) -> 0 | D36: =SUM(D5:D35) -> 0 | E36: =SUM(E5:E35) -> 0 | F36: =SUM(F5:F35) -> 0 | G36: =SUM(G5:G35) -> 0 | H36: =SUM(H5:H35) -> 0 | I36: =SUM(I5:I35) -> 0 | ... AK36: =SUM(AK5:AK35) -> 0 | AL36: T | AM36: =SUM(AM5:AM35) -> 0 | AN36: =SUM(AN5:AN35) -> 0 | AO36: =SUM(AO5:AO35) -> 0 | AP36: =SUM(AP5:AP35) -> 0 | AQ36: =SUM(AQ5:AQ35) -> 0 | AR36: =SUM(AR5:AR35) -> 0 | AS36: =SUM(AS5:AS35) -> 0 | AT36: =SUM(AT5:AT35) -> 0 | ... BV36: =SUM(BV5:BV35) -> 0 | BW36: T | BX36: =SUM(BX5:BX35) -> 0 | BY36: =SUM(BY5:BY35) -> 0 | BZ36: =SUM(BZ5:BZ35) -> 0 | CA36: =SUM(CA5:CA35) -> 0 | CB36: =SUM(CB5:CB35) -> 0 | CC36: =SUM(CC5:CC35) -> 0 | CD36: =SUM(CD5:CD35) -> 0 | CE36: =SUM(CE5:CE35) -> 0 | ... DG36: =SUM(DG5:DG35) -> 0
D38: NOMBRE DE ROTATIONS | M38: =+AK36+BV36+DG36 -> 0
D40: NOMBRE DE PLACES OFFERTES | M40: =+M38*200 -> 0

Sheet ROTATION-LIGNE
A2: MATIN | BB2: SOIR | DC2: NUIT
A3: JOUR | B3: LIGNE 1B | E3: LIGNE 16 | J3: LIGNE 09 | N3: LIGNE 11 | S3: LIGNE 27 | X3: LIGNE 26 | AC3: LIGNE 28 | AG3: LIGNE 03b | AK3: LIGNE 25 | AQ3: LAC | AW3: LIGNE 4b | BA3: TOTAL | BB3: JOUR | BC3: LIGNE 1B | BF3: LIGNE 16 | BK3: LIGNE 09 | BO3: LIGNE 11 | BT3: LIGNE 27 | BY3: LIGNE 26 | CD3: LIGNE 28 | CH3: LIGNE 03b | CL3: LIGNE25 | CR3: lac | CX3: LIGNE 4b | DB3: TOTAL | DC3: JOUR | DD3: LIGNE 1B | DG3: LIGNE 16 | DK3: LIGNE 09 | DO3: LIGNE 11 | DS3: LIGNE 27 | DV3: LIGNE 26 | EA3: LIGNE 28 | EE3: LIGNE 03b | EH3: LIGNE 25 | EK3: LAC | EN3: LIGNE 4B | EQ3: TOTAL | ES3: TOTAL BUS | ET3: TOTAL LIGNE | EU3: ECART
B4: BUS 01 | C4: BUS 02 | D4: BUS 03 | E4: BUS 01 | F4: BUS 02 | G4: BUS 03 | H4: BUS 04 | I4: BUS 05 | J4: BUS 01 | K4: BUS 02 | L4: BUS 03 | M4: BUS 04 | N4: BUS 01 | O4: BUS 02 | P4: BUS 03 | Q4: BUS 04 | R4: BUS 05 | S4: BUS 01 | T4: BUS 02 | U4: BUS 03 | V4: BUS 04 | W4: BUS 05 | X4: BUS 01 | Y4: BUS 02 | Z4: BUS 03 | AA4: BUS 04 | AB4: BUS 05 | AC4: BUS 01 | AD4: BUS 02 | AE4: BUS 03 | AF4: BUS 04 | AG4: BUS 01 | AH4: BUS 02 | AI4: BUS 03 | AJ4: BUS 04 | AK4: BUS 01 | AL4: BUS 02 | AM4: BUS 03 | AN4: BUS 04 | AO4: BUS 05 | AP4: BUS 06 | AQ4: BUS 01 | AR4: BUS 02 | AS4: BUS 03 | AT4: BUS 04 | AU4: BUS 05 | AV4: BUS 06 | AW4: BUS 01 | AX4: BUS 02 | AY4: BUS 03 | AZ4: BUS 04 | BC4: BUS 01 | BD4: BUS 02 | BE4: BUS 03 | BF4: BUS 01 | BG4: BUS 02 | BH4: BUS 03 | BI4: BUS 04 | BJ4: BUS 04 | BK4: BUS 01 | BL4: BUS 02 | BM4: BUS 03 | BN4: BUS 04 | BO4: BUS 01 | BP4: BUS 02 | BQ4: BUS 03 | BR4: BUS 04 | BS4: BUS05 | BT4: BUS 01 | BU4: BUS 02 | BV4: BUS 03 | BW4: BUS 04 | BX4: BUS 05 | BY4: BUS 01 | BZ4: BUS 02 | CA4: BUS 03 | CB4: BUS 04 | CC4: BUS 05 | CD4: BUS 01 | CE4: BUS 02 | CF4: BUS 03 | CG4: BUS 04 | CH4: BUS 01 | CI4: BUS 02 | CJ4: BUS 03 | CK4: BUS 04 | CL4: BUS 01 | CM4: BUS 02 | CN4: BUS 03 | CO4: BUS 04 | CP4: BUS 05 | CQ4: BUS 06 | CR4: BUS 01 | CS4: BUS 02 | CT4: BUS 03 | CU4: BUS 04 | CV4: BUS 05 | CW4: BUS 06 | CX4: BUS 01 | CY4: BUS 02 | CZ4: BUS 03 | DA4: BUS 04 | DD4: BUS 01 | DE4: BUS 02 | DF4: BUS 03 | DG4: BUS 01 | DH4: BUS 02 | DI4: BUS 03 | DJ4: BUS 04 | DK4: BUS 01 | DL4: BUS 02 | DM4: BUS 03 | DN4: BUS 04 | DO4: BUS 01 | DP4: BUS 02 | DQ4: BUS 03 | DR4: BUS 04 | DS4: BUS 01 | DT4: BUS 02 | DU4: BUS 03 | DV4: BUS 01 | DW4: BUS 02 | DX4: BUS 03 | DZ4: BUS 04 | EA4: BUS 01 | EB4: BUS 02 | EC4: BUS 03 | ED4: BUS 04 | EE4: BUS 01 | EF4: BUS 02 | EG4: BUS 03 | EH4: BUS 01 | EI4: BUS 02 | EJ4: BUS 03 | EK4: BUS 01 | EL4: BUS 02 | EM4: BUS 03 | EN4: BUS 01 | EO4: BUS 02 | EP4: BUS 03
A5: 1 | BA5: =SUM(B5:AV5) -> 0 | BB5: 1 | DB5: =SUM(BC5:CW5) -> 0 | DC5: 1 | EQ5: =SUM(DD5:EP5) -> 0 | ES5: =+'RETAION-BUS'!AK5+'RETAION-BUS'!BV5+'RETAION-BUS'!DG5 -> 0 | ET5: =+DB5+BA5+EQ5 -> 0 | EU5: =+ES5-ET5 -> 0
A6: 2 | BA6: =SUM(B6:AV6) -> 0 | BB6: 2 | DB6: =SUM(BC6:CW6) -> 0 | DC6: 2 | EQ6: =SUM(DD6:EP6) -> 0 | ES6: =+'RETAION-BUS'!AK6+'RETAION-BUS'!BV6+'RETAION-BUS'!DG6 -> 0 | ET6: =+DB6+BA6+EQ6 -> 0 | EU6: =+ES6-ET6 -> 0
A7: 3 | BA7: =SUM(B7:AV7) -> 0 | BB7: 3 | DB7: =SUM(BC7:CW7) -> 0 | DC7: 3 | EQ7: =SUM(DD7:EP7) -> 0 | ES7: =+'RETAION-BUS'!AK7+'RETAION-BUS'!BV7+'RETAION-BUS'!DG7 -> 0 | ET7: =+DB7+BA7+EQ7 -> 0 | EU7: =+ES7-ET7 -> 0
A8: 4 | BA8: =SUM(B8:AV8) -> 0 | BB8: 4 | DB8: =SUM(BC8:CW8) -> 0 | DC8: 4 | EQ8: =SUM(DD8:EP8) -> 0 | ES8: =+'RETAION-BUS'!AK8+'RETAION-BUS'!BV8+'RETAION-BUS'!DG8 -> 0 | ET8: =+DB8+BA8+EQ8 -> 0 | EU8: =+ES8-ET8 -> 0
A9: 5 | BA9: =SUM(B9:AV9) -> 0 | BB9: 5 | DB9: =SUM(BC9:CW9) -> 0 | DC9: 5 | EQ9: =SUM(DD9:EP9) -> 0 | ES9: =+'RETAION-BUS'!AK9+'RETAION-BUS'!BV9+'RETAION-BUS'!DG9 -> 0 | ET9: =+DB9+BA9+EQ9 -> 0 | EU9: =+ES9-ET9 -> 0
A10: 6 | BA10: =SUM(B10:AV10) -> 0 | BB10: 6 | DB10: =SUM(BC10:CW10) -> 0 | DC10: 6 | EQ10: =SUM(DD10:EP10) -> 0 | ES10: =+'RETAION-BUS'!AK10+'RETAION-BUS'!BV10+'RETAION-BUS'!DG10 -> 0 | ET10: =+DB10+BA10+EQ10 -> 0 | EU10: =+ES10-ET10 -> 0
A11: 7 | BA11: =SUM(B11:AV11) -> 0 | BB11: 7 | DB11: =SUM(BC11:CW11) -> 0 | DC11: 7 | EQ11: =SUM(DD11:EP11) -> 0 | ES11: =+'RETAION-BUS'!AK11+'RETAION-BUS'!BV11+'RETAION-BUS'!DG11 -> 0 | ET11: =+DB11+BA11+EQ11 -> 0 | EU11: =+ES11-ET11 -> 0
A12: 8 | BA12: =SUM(B12:AV12) -> 0 | BB12: 8 | DB12: =SUM(BC12:CW12) -> 0 | DC12: 8 | EQ12: =SUM(DD12:EP12) -> 0 | ES12: =+'RETAION-BUS'!AK12+'RETAION-BUS'!BV12+'RETAION-BUS'!DG12 -> 0 | ET12: =+DB12+BA12+EQ12 -> 0 | EU12: =+ES12-ET12 -> 0
A13: 9 | BA13: =SUM(B13:AV13) -> 0 | BB13: 9 | DB13: =SUM(BC13:CW13) -> 0 | DC13: 9 | EQ13: =SUM(DD13:EP13) -> 0 | ES13: =+'RETAION-BUS'!AK13+'RETAION-BUS'!BV13+'RETAION-BUS'!DG13 -> 0 | ET13: =+DB13+BA13+EQ13 -> 0 | EU13: =+ES13-ET13 -> 0
A14: 10 | BA14: =SUM(B14:AV14) -> 0 | BB14: 10 | DB14: =SUM(BC14:CW14) -> 0 | DC14: 10 | EQ14: =SUM(DD14:EP14) -> 0 | ES14: =+'RETAION-BUS'!AK14+'RETAION-BUS'!BV14+'RETAION-BUS'!DG14 -> 0 | ET14: =+DB14+BA14+EQ14 -> 0 | EU14: =+ES14-ET14 -> 0
A15: 11 | BA15: =SUM(B15:AV15) -> 0 | BB15: 11 | DB15: =SUM(BC15:CW15) -> 0 | DC15: 11 | EQ15: =SUM(DD15:EP15) -> 0 | ES15: =+'RETAION-BUS'!AK15+'RETAION-BUS'!BV15+'RETAION-BUS'!DG15 -> 0 | ET15: =+DB15+BA15+EQ15 -> 0 | EU15: =+ES15-ET15 -> 0
A16: 12 | BA16: =SUM(B16:AV16) -> 0 | BB16: 12 | DB16: =SUM(BC16:CW16) -> 0 | DC16: 12 | EQ16: =SUM(DD16:EP16) -> 0 | ES16: =+'RETAION-BUS'!AK16+'RETAION-BUS'!BV16+'RETAION-BUS'!DG16 -> 0 | ET16: =+DB16+BA16+EQ16 -> 0 | EU16: =+ES16-ET16 -> 0
... A35: 31 | BA35: =SUM(B35:AV35) -> 0 | BB35: 31 | DB35: =SUM(BC35:CW35) -> 0 | DC35: 31 | EQ35: =SUM(DD35:EP35) -> 0 | ES35: =+'RETAION-BUS'!AK35+'RETAION-BUS'!BV35+'RETAION-BUS'!DG35 -> 0 | ET35: =+DB35+BA35+EQ35 -> 0 | EU35: =+ES35-ET35 -> 0
B36: =SUM(B5:D35) -> 0 | E36: =SUM(E5:I35) -> 0 | J36: =SUM(J5:M35) -> 0 | N36: =SUM(N5:R35) -> 0 | S36: =SUM(S5:W35) -> 0 | X36: =SUM(X5:AB35) -> 0 | AC36: =SUM(AC5:AF35) -> 0 | AG36: =SUM(AG5:AJ35) -> 0 | AK36: =SUM(AK5:AP35) -> 0 | AQ36: =SUM(AQ5:AV35) -> 0 | AW36: =SUM(AW5:AZ35) -> 0 | BA36: =SUM(BA5:BA35) -> 0 | BC36: =SUM(BC5:BE35) -> 0 | BF36: =SUM(BF5:BJ35) -> 0 | BK36: =SUM(BK5:BN35) -> 0 | BO36: =SUM(BO5:BS35) -> 0 | BT36: =SUM(BT5:BX35) -> 0 | BY36: =SUM(BY5:CC35) -> 0 | CD36: =SUM(CD5:CG35) -> 0 | CH36: =SUM(CH5:CK35) -> 0 | CL36: =SUM(CL5:CQ35) -> 0 | CR36: =SUM(CR5:CW35) -> 0 | CX36: =SUM(CX5:DA35) -> 0 | DB36: =SUM(DB5:DB35) -> 0 | DD36: =SUM(DD5:DF35) -> 0 | DG36: =SUM(DG5:DJ35) -> 0 | DK36: =SUM(DK5:DN35) -> 0 | DO36: =SUM(DO5:DR35) -> 0 | DS36: =SUM(DS5:DU35) -> 0 | DV36: =SUM(DV5:DZ35) -> 0 | EA36: =SUM(EA5:ED35) -> 0 | EE36: =SUM(EE5:EG35) -> 0 | EH36: =SUM(EH5:EJ35) -> 0 | EK36: =SUM(EK5:EM35) -> 0 | EN36: =SUM(EN5:EP35) -> 0 | EQ36: =SUM(EQ5:EQ35) -> 0 | ET36: =+DB36+BA36 -> 0
Y64: +

Sheet RECAP1
A3: JOUR | B3: A01 | C3: A02 | D3: A03 | E3: A04 | F3: A05 | G3: A06 | H3: A07 | I3: A08 | J3: A09 | K3: A10 | L3: A11 | M3: A12 | N3: A13 | O3: A14 | P3: A15 | Q3: A16 | R3: A17 | S3: A18 | T3: A19 | U3: A20 | V3: A21 | W3: A22 | X3: A23 | Y3: A24 | Z3: A25 | AA3: A26 | AB3: A27 | AC3: A28 | AD3: A29 | AE3: A30 | AF3: A31 | AG3: A32 | AH3: A33 | AI3: A34 | AJ3: A35 | AK3: TOTAL
A4: 1 | B4: =+BUS!B115+BUS!C115+BUS!D115 -> 0 | C4: =+BUS!E115+BUS!F115+BUS!G115 -> 0 | D4: =+BUS!H115+BUS!I115+BUS!J115 -> 0 | E4: =+BUS!K115+BUS!L115+BUS!M115 -> 0 | F4: =+BUS!N115+BUS!O115+BUS!P115 -> 0 | G4: =+BUS!Q115+BUS!R115+BUS!S115 -> 0 | H4: =+BUS!T115+BUS!U115+BUS!V115 -> 0 | I4: =+BUS!W115+BUS!X115+BUS!Y115 -> 0 | J4: =+BUS!Z115+BUS!AA115+BUS!AB115 -> 0 | K4: =+BUS!AC115+BUS!AD115+BUS!AE115 -> 0 | L4: =+BUS!AF115+BUS!AG115+BUS!AH115 -> 0 | M4: =+BUS!AI115+BUS!AJ115+BUS!AK115 -> 0 | N4: =+BUS!AL115+BUS!AM115+BUS!AN115 -> 0 | O4: =+BUS!AO115+BUS!AP115+BUS!AQ115 -> 0 | P4: =+BUS!AR115+BUS!AS115+BUS!AT115 -> 0 | Q4: =+BUS!AU115+BUS!AV115+BUS!AW115 -> 0 | R4: =+BUS!AX115+BUS!AY115+BUS!AZ115 -> 0 | S4: =+BUS!BA115+BUS!BB115+BUS!BC115 -> 0 | T4: =+BUS!BD115+BUS!BE115+BUS!BF115 -> 0 | U4: =+BUS!BG115+BUS!BH115+BUS!BI115 -> 0 | V4: =+BUS!BJ115+BUS!BK115+BUS!BL115 -> 0 | W4: =+BUS!BM115+BUS!BN115+BUS!BO115 -> 0 | X4: =+BUS!BP115+BUS!BQ115+BUS!BR115 -> 0 | Y4: =+BUS!BS115+BUS!BT115+BUS!BU115 -> 0 | Z4: =+BUS!BV115+BUS!BW115+BUS!BX115 -> 0 | AA4: =+BUS!BY115+BUS!BZ115+BUS!CA115 -> 0 | AB4: =+BUS!CB115+BUS!CC115+BUS!CD115 -> 0 | AC4: =+BUS!CE115+BUS!CF115+BUS!CG115 -> 0 | AD4: =+BUS!CH115+BUS!CI115+BUS!CJ115 -> 0 | AE4: =+BUS!CK115+BUS!CL115+BUS!CM115 -> 0 | AF4: =+BUS!CN115+BUS!CO115+BUS!CP115 -> 0 | AG4: =+BUS!CQ115+BUS!CR115+BUS!CS115 -> 0 | AH4: =+BUS!CT115+BUS!CU115+BUS!CV115 -> 0 | AI4: =+BUS!CW115+BUS!CX115+BUS!CY115 -> 0 | AJ4: =+BUS!CZ115+BUS!DA115+BUS!DB115 -> 0 | AK4: =SUM(B4:AJ4) -> 0
A5: 2 | B5: =+BUS!B116+BUS!C116+BUS!D116 -> 0 | C5: =+BUS!E116+BUS!F116+BUS!G116 -> 0 | D5: =+BUS!H116+BUS!I116+BUS!J116 -> 0 | E5: =+BUS!K116+BUS!L116+BUS!M116 -> 0 | F5: =+BUS!N116+BUS!O116+BUS!P116 -> 0 | G5: =+BUS!Q116+BUS!R116+BUS!S116 -> 0 | H5: =+BUS!T116+BUS!U116+BUS!V116 -> 0 | I5: =+BUS!W116+BUS!X116+BUS!Y116 -> 0 | J5: =+BUS!Z116+BUS!AA116+BUS!AB116 -> 0 | K5: =+BUS!AC116+BUS!AD116+BUS!AE116 -> 0 | L5: =+BUS!AF116+BUS!AG116+BUS!AH116 -> 0 | M5: =+BUS!AI116+BUS!AJ116+BUS!AK116 -> 0 | N5: =+BUS!AL116+BUS!AM116+BUS!AN116 -> 0 | O5: =+BUS!AO116+BUS!AP116+BUS!AQ116 -> 0 | P5: =+BUS!AR116+BUS!AS116+BUS!AT116 -> 0 | Q5: =+BUS!AU116+BUS!AV116+BUS!AW116 -> 0 | R5: =+BUS!AX116+BUS!AY116+BUS!AZ116 -> 0 | S5: =+BUS!BA116+BUS!BB116+BUS!BC116 -> 0 | T5: =+BUS!BD116+BUS!BE116+BUS!BF116 -> 0 | U5: =+BUS!BG116+BUS!BH116+BUS!BI116 -> 0 | V5: =+BUS!BJ116+BUS!BK116+BUS!BL116 -> 0 | W5: =+BUS!BM116+BUS!BN116+BUS!BO116 -> 0 | X5: =+BUS!BP116+BUS!BQ116+BUS!BR116 -> 0 | Y5: =+BUS!BS116+BUS!BT116+BUS!BU116 -> 0 | Z5: =+BUS!BV116+BUS!BW116+BUS!BX116 -> 0 | AA5: =+BUS!BY116+BUS!BZ116+BUS!CA116 -> 0 | AB5: =+BUS!CB116+BUS!CC116+BUS!CD116 -> 0 | AC5: =+BUS!CE116+BUS!CF116+BUS!CG116 -> 0 | AD5: =+BUS!CH116+BUS!CI116+BUS!CJ116 -> 0 | AE5: =+BUS!CK116+BUS!CL116+BUS!CM116 -> 0 | AF5: =+BUS!CN116+BUS!CO116+BUS!CP116 -> 0 | AG5: =+BUS!CQ116+BUS!CR116+BUS!CS116 -> 0 | AH5: =+BUS!CT116+BUS!CU116+BUS!CV116 -> 0 | AI5: =+BUS!CW116+BUS!CX116+BUS!CY116 -> 0 | AJ5: =+BUS!CZ116+BUS!DA116+BUS!DB116 -> 0 | AK5: =SUM(B5:AJ5) -> 0
A6: 3 | B6: =+BUS!B117+BUS!C117+BUS!D117 -> 0 | C6: =+BUS!E117+BUS!F117+BUS!G117 -> 0 | D6: =+BUS!H117+BUS!I117+BUS!J117 -> 0 | E6: =+BUS!K117+BUS!L117+BUS!M117 -> 0 | F6: =+BUS!N117+BUS!O117+BUS!P117 -> 0 | G6: =+BUS!Q117+BUS!R117+BUS!S117 -> 0 | H6: =+BUS!T117+BUS!U117+BUS!V117 -> 0 | I6: =+BUS!W117+BUS!X117+BUS!Y117 -> 0 | J6: =+BUS!Z117+BUS!AA117+BUS!AB117 -> 0 | K6: =+BUS!AC117+BUS!AD117+BUS!AE117 -> 0 | L6: =+BUS!AF117+BUS!AG117+BUS!AH117 -> 0 | M6: =+BUS!AI117+BUS!AJ117+BUS!AK117 -> 0 | N6: =+BUS!AL117+BUS!AM117+BUS!AN117 -> 0 | O6: =+BUS!AO117+BUS!AP117+BUS!AQ117 -> 0 | P6: =+BUS!AR117+BUS!AS117+BUS!AT117 -> 0 | Q6: =+BUS!AU117+BUS!AV117+BUS!AW117 -> 0 | R6: =+BUS!AX117+BUS!AY117+BUS!AZ117 -> 0 | S6: =+BUS!BA117+BUS!BB117+BUS!BC117 -> 0 | T6: =+BUS!BD117+BUS!BE117+BUS!BF117 -> 0 | U6: =+BUS!BG117+BUS!BH117+BUS!BI117 -> 0 | V6: =+BUS!BJ117+BUS!BK117+BUS!BL117 -> 0 | W6: =+BUS!BM117+BUS!BN117+BUS!BO117 -> 0 | X6: =+BUS!BP117+BUS!BQ117+BUS!BR117 -> 0 | Y6: =+BUS!BS117+BUS!BT117+BUS!BU117 -> 0 | Z6: =+BUS!BV117+BUS!BW117+BUS!BX117 -> 0 | AA6: =+BUS!BY117+BUS!BZ117+BUS!CA117 -> 0 | AB6: =+BUS!CB117+BUS!CC117+BUS!CD117 -> 0 | AC6: =+BUS!CE117+BUS!CF117+BUS!CG117 -> 0 | AD6: =+BUS!CH117+BUS!CI117+BUS!CJ117 -> 0 | AE6: =+BUS!CK117+BUS!CL117+BUS!CM117 -> 0 | AF6: =+BUS!CN117+BUS!CO117+BUS!CP117 -> 0 | AG6: =+BUS!CQ117+BUS!CR117+BUS!CS117 -> 0 | AH6: =+BUS!CT117+BUS!CU117+BUS!CV117 -> 0 | AI6: =+BUS!CW117+BUS!CX117+BUS!CY117 -> 0 | AJ6: =+BUS!CZ117+BUS!DA117+BUS!DB117 -> 0 | AK6: =SUM(B6:AJ6) -> 0
A7: 4 | B7: =+BUS!B118+BUS!C118+BUS!D118 -> 0 | C7: =+BUS!E118+BUS!F118+BUS!G118 -> 0 | D7: =+BUS!H118+BUS!I118+BUS!J118 -> 0 | E7: =+BUS!K118+BUS!L118+BUS!M118 -> 0 | F7: =+BUS!N118+BUS!O118+BUS!P118 -> 0 | G7: =+BUS!Q118+BUS!R118+BUS!S118 -> 0 | H7: =+BUS!T118+BUS!U118+BUS!V118 -> 0 | I7: =+BUS!W118+BUS!X118+BUS!Y118 -> 0 | J7: =+BUS!Z118+BUS!AA118+BUS!AB118 -> 0 | K7: =+BUS!AC118+BUS!AD118+BUS!AE118 -> 0 | L7: =+BUS!AF118+BUS!AG118+BUS!AH118 -> 0 | M7: =+BUS!AI118+BUS!AJ118+BUS!AK118 -> 0 | N7: =+BUS!AL118+BUS!AM118+BUS!AN118 -> 0 | O7: =+BUS!AO118+BUS!AP118+BUS!AQ118 -> 0 | P7: =+BUS!AR118+BUS!AS118+BUS!AT118 -> 0 | Q7: =+BUS!AU118+BUS!AV118+BUS!AW118 -> 0 | R7: =+BUS!AX118+BUS!AY118+BUS!AZ118 -> 0 | S7: =+BUS!BA118+BUS!BB118+BUS!BC118 -> 0 | T7: =+BUS!BD118+BUS!BE118+BUS!BF118 -> 0 | U7: =+BUS!BG118+BUS!BH118+BUS!BI118 -> 0 | V7: =+BUS!BJ118+BUS!BK118+BUS!BL118 -> 0 | W7: =+BUS!BM118+BUS!BN118+BUS!BO118 -> 0 | X7: =+BUS!BP118+BUS!BQ118+BUS!BR118 -> 0 | Y7: =+BUS!BS118+BUS!BT118+BUS!BU118 -> 0 | Z7: =+BUS!BV118+BUS!BW118+BUS!BX118 -> 0 | AA7: =+BUS!BY118+BUS!BZ118+BUS!CA118 -> 0 | AB7: =+BUS!CB118+BUS!CC118+BUS!CD118 -> 0 | AC7: =+BUS!CE118+BUS!CF118+BUS!CG118 -> 0 | AD7: =+BUS!CH118+BUS!CI118+BUS!CJ118 -> 0 | AE7: =+BUS!CK118+BUS!CL118+BUS!CM118 -> 0 | AF7: =+BUS!CN118+BUS!CO118+BUS!CP118 -> 0 | AG7: =+BUS!CQ118+BUS!CR118+BUS!CS118 -> 0 | AH7: =+BUS!CT118+BUS!CU118+BUS!CV118 -> 0 | AI7: =+BUS!CW118+BUS!CX118+BUS!CY118 -> 0 | AJ7: =+BUS!CZ118+BUS!DA118+BUS!DB118 -> 0 | AK7: =SUM(B7:AJ7) -> 0
A8: 5 | B8: =+BUS!B119+BUS!C119+BUS!D119 -> 0 | C8: =+BUS!E119+BUS!F119+BUS!G119 -> 0 | D8: =+BUS!H119+BUS!I119+BUS!J119 -> 0 | E8: =+BUS!K119+BUS!L119+BUS!M119 -> 0 | F8: =+BUS!N119+BUS!O119+BUS!P119 -> 0 | G8: =+BUS!Q119+BUS!R119+BUS!S119 -> 0 | H8: =+BUS!T119+BUS!U119+BUS!V119 -> 0 | I8: =+BUS!W119+BUS!X119+BUS!Y119 -> 0 | J8: =+BUS!Z119+BUS!AA119+BUS!AB119 -> 0 | K8: =+BUS!AC119+BUS!AD119+BUS!AE119 -> 0 | L8: =+BUS!AF119+BUS!AG119+BUS!AH119 -> 0 | M8: =+BUS!AI119+BUS!AJ119+BUS!AK119 -> 0 | N8: =+BUS!AL119+BUS!AM119+BUS!AN119 -> 0 | O8: =+BUS!AO119+BUS!AP119+BUS!AQ119 -> 0 | P8: =+BUS!AR119+BUS!AS119+BUS!AT119 -> 0 | Q8: =+BUS!AU119+BUS!AV119+BUS!AW119 -> 0 | R8: =+BUS!AX119+BUS!AY119+BUS!AZ119 -> 0 | S8: =+BUS!BA119+BUS!BB119+BUS!BC119 -> 0 | T8: =+BUS!BD119+BUS!BE119+BUS!BF119 -> 0 | U8: =+BUS!BG119+BUS!BH119+BUS!BI119 -> 0 | V8: =+BUS!BJ119+BUS!BK119+BUS!BL119 -> 0 | W8: =+BUS!BM119+BUS!BN119+BUS!BO119 -> 0 | X8: =+BUS!BP119+BUS!BQ119+BUS!BR119 -> 0 | Y8: =+BUS!BS119+BUS!BT119+BUS!BU119 -> 0 | Z8: =+BUS!BV119+BUS!BW119+BUS!BX119 -> 0 | AA8: =+BUS!BY119+BUS!BZ119+BUS!CA119 -> 0 | AB8: =+BUS!CB119+BUS!CC119+BUS!CD119 -> 0 | AC8: =+BUS!CE119+BUS!CF119+BUS!CG119 -> 0 | AD8: =+BUS!CH119+BUS!CI119+BUS!CJ119 -> 0 | AE8: =+BUS!CK119+BUS!CL119+BUS!CM119 -> 0 | AF8: =+BUS!CN119+BUS!CO119+BUS!CP119 -> 0 | AG8: =+BUS!CQ119+BUS!CR119+BUS!CS119 -> 0 | AH8: =+BUS!CT119+BUS!CU119+BUS!CV119 -> 0 | AI8: =+BUS!CW119+BUS!CX119+BUS!CY119 -> 0 | AJ8: =+BUS!CZ119+BUS!DA119+BUS!DB119 -> 0 | AK8: =SUM(B8:AJ8) -> 0
A9: 6 | B9: =+BUS!B120+BUS!C120+BUS!D120 -> 0 | C9: =+BUS!E120+BUS!F120+BUS!G120 -> 0 | D9: =+BUS!H120+BUS!I120+BUS!J120 -> 0 | E9: =+BUS!K120+BUS!L120+BUS!M120 -> 0 | F9: =+BUS!N120+BUS!O120+BUS!P120 -> 0 | G9: =+BUS!Q120+BUS!R120+BUS!S120 -> 0 | H9: =+BUS!T120+BUS!U120+BUS!V120 -> 0 | I9: =+BUS!W120+BUS!X120+BUS!Y120 -> 0 | J9: =+BUS!Z120+BUS!AA120+BUS!AB120 -> 0 | K9: =+BUS!AC120+BUS!AD120+BUS!AE120 -> 0 | L9: =+BUS!AF120+BUS!AG120+BUS!AH120 -> 0 | M9: =+BUS!AI120+BUS!AJ120+BUS!AK120 -> 0 | N9: =+BUS!AL120+BUS!AM120+BUS!AN120 -> 0 | O9: =+BUS!AO120+BUS!AP120+BUS!AQ120 -> 0 | P9: =+BUS!AR120+BUS!AS120+BUS!AT120 -> 0 | Q9: =+BUS!AU120+BUS!AV120+BUS!AW120 -> 0 | R9: =+BUS!AX120+BUS!AY120+BUS!AZ120 -> 0 | S9: =+BUS!BA120+BUS!BB120+BUS!BC120 -> 0 | T9: =+BUS!BD120+BUS!BE120+BUS!BF120 -> 0 | U9: =+BUS!BG120+BUS!BH120+BUS!BI120 -> 0 | V9: =+BUS!BJ120+BUS!BK120+BUS!BL120 -> 0 | W9: =+BUS!BM120+BUS!BN120+BUS!BO120 -> 0 | X9: =+BUS!BP120+BUS!BQ120+BUS!BR120 -> 0 | Y9: =+BUS!BS120+BUS!BT120+BUS!BU120 -> 0 | Z9: =+BUS!BV120+BUS!BW120+BUS!BX120 -> 0 | AA9: =+BUS!BY120+BUS!BZ120+BUS!CA120 -> 0 | AB9: =+BUS!CB120+BUS!CC120+BUS!CD120 -> 0 | AC9: =+BUS!CE120+BUS!CF120+BUS!CG120 -> 0 | AD9: =+BUS!CH120+BUS!CI120+BUS!CJ120 -> 0 | AE9: =+BUS!CK120+BUS!CL120+BUS!CM120 -> 0 | AF9: =+BUS!CN120+BUS!CO120+BUS!CP120 -> 0 | AG9: =+BUS!CQ120+BUS!CR120+BUS!CS120 -> 0 | AH9: =+BUS!CT120+BUS!CU120+BUS!CV120 -> 0 | AI9: =+BUS!CW120+BUS!CX120+BUS!CY120 -> 0 | AJ9: =+BUS!CZ120+BUS!DA120+BUS!DB120 -> 0 | AK9: =SUM(B9:AJ9) -> 0
A10: 7 | B10: =+BUS!B121+BUS!C121+BUS!D121 -> 0 | C10: =+BUS!E121+BUS!F121+BUS!G121 -> 0 | D10: =+BUS!H121+BUS!I121+BUS!J121 -> 0 | E10: =+BUS!K121+BUS!L121+BUS!M121 -> 0 | F10: =+BUS!N121+BUS!O121+BUS!P121 -> 0 | G10: =+BUS!Q121+BUS!R121+BUS!S121 -> 0 | H10: =+BUS!T121+BUS!U121+BUS!V121 -> 0 | I10: =+BUS!W121+BUS!X121+BUS!Y121 -> 0 | J10: =+BUS!Z121+BUS!AA121+BUS!AB121 -> 0 | K10: =+BUS!AC121+BUS!AD121+BUS!AE121 -> 0 | L10: =+BUS!AF121+BUS!AG121+BUS!AH121 -> 0 | M10: =+BUS!AI121+BUS!AJ121+BUS!AK121 -> 0 | N10: =+BUS!AL121+BUS!AM121+BUS!AN121 -> 0 | O10: =+BUS!AO121+BUS!AP121+BUS!AQ121 -> 0 | P10: =+BUS!AR121+BUS!AS121+BUS!AT121 -> 0 | Q10: =+BUS!AU121+BUS!AV121+BUS!AW121 -> 0 | R10: =+BUS!AX121+BUS!AY121+BUS!AZ121 -> 0 | S10: =+BUS!BA121+BUS!BB121+BUS!BC121 -> 0 | T10: =+BUS!BD121+BUS!BE121+BUS!BF121 -> 0 | U10: =+BUS!BG121+BUS!BH121+BUS!BI121 -> 0 | V10: =+BUS!BJ121+BUS!BK121+BUS!BL121 -> 0 | W10: =+BUS!BM121+BUS!BN121+BUS!BO121 -> 0 | X10: =+BUS!BP121+BUS!BQ121+BUS!BR121 -> 0 | Y10: =+BUS!BS121+BUS!BT121+BUS!BU121 -> 0 | Z10: =+BUS!BV121+BUS!BW121+BUS!BX121 -> 0 | AA10: =+BUS!BY121+BUS!BZ121+BUS!CA121 -> 0 | AB10: =+BUS!CB121+BUS!CC121+BUS!CD121 -> 0 | AC10: =+BUS!CE121+BUS!CF121+BUS!CG121 -> 0 | AD10: =+BUS!CH121+BUS!CI121+BUS!CJ121 -> 0 | AE10: =+BUS!CK121+BUS!CL121+BUS!CM121 -> 0 | AF10: =+BUS!CN121+BUS!CO121+BUS!CP121 -> 0 | AG10: =+BUS!CQ121+BUS!CR121+BUS!CS121 -> 0 | AH10: =+BUS!CT121+BUS!CU121+BUS!CV121 -> 0 | AI10: =+BUS!CW121+BUS!CX121+BUS!CY121 -> 0 | AJ10: =+BUS!CZ121+BUS!DA121+BUS!DB121 -> 0 | AK10: =SUM(B10:AJ10) -> 0
A11: 8 | B11: =+BUS!B122+BUS!C122+BUS!D122 -> 0 | C11: =+BUS!E122+BUS!F122+BUS!G122 -> 0 | D11: =+BUS!H122+BUS!I122+BUS!J122 -> 0 | E11: =+BUS!K122+BUS!L122+BUS!M122 -> 0 | F11: =+BUS!N122+BUS!O122+BUS!P122 -> 0 | G11: =+BUS!Q122+BUS!R122+BUS!S122 -> 0 | H11: =+BUS!T122+BUS!U122+BUS!V122 -> 0 | I11: =+BUS!W122+BUS!X122+BUS!Y122 -> 0 | J11: =+BUS!Z122+BUS!AA122+BUS!AB122 -> 0 | K11: =+BUS!AC122+BUS!AD122+BUS!AE122 -> 0 | L11: =+BUS!AF122+BUS!AG122+BUS!AH122 -> 0 | M11: =+BUS!AI122+BUS!AJ122+BUS!AK122 -> 0 | N11: =+BUS!AL122+BUS!AM122+BUS!AN122 -> 0 | O11: =+BUS!AO122+BUS!AP122+BUS!AQ122 -> 0 | P11: =+BUS!AR122+BUS!AS122+BUS!AT122 -> 0 | Q11: =+BUS!AU122+BUS!AV122+BUS!AW122 -> 0 | R11: =+BUS!AX122+BUS!AY122+BUS!AZ122 -> 0 | S11: =+BUS!BA122+BUS!BB122+BUS!BC122 -> 0 | T11: =+BUS!BD122+BUS!BE122+BUS!BF122 -> 0 | U11: =+BUS!BG122+BUS!BH122+BUS!BI122 -> 0 | V11: =+BUS!BJ122+BUS!BK122+BUS!BL122 -> 0 | W11: =+BUS!BM122+BUS!BN122+BUS!BO122 -> 0 | X11: =+BUS!BP122+BUS!BQ122+BUS!BR122 -> 0 | Y11: =+BUS!BS122+BUS!BT122+BUS!BU122 -> 0 | Z11: =+BUS!BV122+BUS!BW122+BUS!BX122 -> 0 | AA11: =+BUS!BY122+BUS!BZ122+BUS!CA122 -> 0 | AB11: =+BUS!CB122+BUS!CC122+BUS!CD122 -> 0 | AC11: =+BUS!CE122+BUS!CF122+BUS!CG122 -> 0 | AD11: =+BUS!CH122+BUS!CI122+BUS!CJ122 -> 0 | AE11: =+BUS!CK122+BUS!CL122+BUS!CM122 -> 0 | AF11: =+BUS!CN122+BUS!CO122+BUS!CP122 -> 0 | AG11: =+BUS!CQ122+BUS!CR122+BUS!CS122 -> 0 | AH11: =+BUS!CT122+BUS!CU122+BUS!CV122 -> 0 | AI11: =+BUS!CW122+BUS!CX122+BUS!CY122 -> 0 | AJ11: =+BUS!CZ122+BUS!DA122+BUS!DB122 -> 0 | AK11: =SUM(B11:AJ11) -> 0
A12: 9 | B12: =+BUS!B123+BUS!C123+BUS!D123 -> 0 | C12: =+BUS!E123+BUS!F123+BUS!G123 -> 0 | D12: =+BUS!H123+BUS!I123+BUS!J123 -> 0 | E12: =+BUS!K123+BUS!L123+BUS!M123 -> 0 | F12: =+BUS!N123+BUS!O123+BUS!P123 -> 0 | G12: =+BUS!Q123+BUS!R123+BUS!S123 -> 0 | H12: =+BUS!T123+BUS!U123+BUS!V123 -> 0 | I12: =+BUS!W123+BUS!X123+BUS!Y123 -> 0 | J12: =+BUS!Z123+BUS!AA123+BUS!AB123 -> 0 | K12: =+BUS!AC123+BUS!AD123+BUS!AE123 -> 0 | L12: =+BUS!AF123+BUS!AG123+BUS!AH123 -> 0 | M12: =+BUS!AI123+BUS!AJ123+BUS!AK123 -> 0 | N12: =+BUS!AL123+BUS!AM123+BUS!AN123 -> 0 | O12: =+BUS!AO123+BUS!AP123+BUS!AQ123 -> 0 | P12: =+BUS!AR123+BUS!AS123+BUS!AT123 -> 0 | Q12: =+BUS!AU123+BUS!AV123+BUS!AW123 -> 0 | R12: =+BUS!AX123+BUS!AY123+BUS!AZ123 -> 0 | S12: =+BUS!BA123+BUS!BB123+BUS!BC123 -> 0 | T12: =+BUS!BD123+BUS!BE123+BUS!BF123 -> 0 | U12: =+BUS!BG123+BUS!BH123+BUS!BI123 -> 0 | V12: =+BUS!BJ123+BUS!BK123+BUS!BL123 -> 0 | W12: =+BUS!BM123+BUS!BN123+BUS!BO123 -> 0 | X12: =+BUS!BP123+BUS!BQ123+BUS!BR123 -> 0 | Y12: =+BUS!BS123+BUS!BT123+BUS!BU123 -> 0 | Z12: =+BUS!BV123+BUS!BW123+BUS!BX123 -> 0 | AA12: =+BUS!BY123+BUS!BZ123+BUS!CA123 -> 0 | AB12: =+BUS!CB123+BUS!CC123+BUS!CD123 -> 0 | AC12: =+BUS!CE123+BUS!CF123+BUS!CG123 -> 0 | AD12: =+BUS!CH123+BUS!CI123+BUS!CJ123 -> 0 | AE12: =+BUS!CK123+BUS!CL123+BUS!CM123 -> 0 | AF12: =+BUS!CN123+BUS!CO123+BUS!CP123 -> 0 | AG12: =+BUS!CQ123+BUS!CR123+BUS!CS123 -> 0 | AH12: =+BUS!CT123+BUS!CU123+BUS!CV123 -> 0 | AI12: =+BUS!CW123+BUS!CX123+BUS!CY123 -> 0 | AJ12: =+BUS!CZ123+BUS!DA123+BUS!DB123 -> 0 | AK12: =SUM(B12:AJ12) -> 0
A13: 10 | B13: =+BUS!B124+BUS!C124+BUS!D124 -> 0 | C13: =+BUS!E124+BUS!F124+BUS!G124 -> 0 | D13: =+BUS!H124+BUS!I124+BUS!J124 -> 0 | E13: =+BUS!K124+BUS!L124+BUS!M124 -> 0 | F13: =+BUS!N124+BUS!O124+BUS!P124 -> 0 | G13: =+BUS!Q124+BUS!R124+BUS!S124 -> 0 | H13: =+BUS!T124+BUS!U124+BUS!V124 -> 0 | I13: =+BUS!W124+BUS!X124+BUS!Y124 -> 0 | J13: =+BUS!Z124+BUS!AA124+BUS!AB124 -> 0 | K13: =+BUS!AC124+BUS!AD124+BUS!AE124 -> 0 | L13: =+BUS!AF124+BUS!AG124+BUS!AH124 -> 0 | M13: =+BUS!AI124+BUS!AJ124+BUS!AK124 -> 0 | N13: =+BUS!AL124+BUS!AM124+BUS!AN124 -> 0 | O13: =+BUS!AO124+BUS!AP124+BUS!AQ124 -> 0 | P13: =+BUS!AR124+BUS!AS124+BUS!AT124 -> 0 | Q13: =+BUS!AU124+BUS!AV124+BUS!AW124 -> 0 | R13: =+BUS!AX124+BUS!AY124+BUS!AZ124 -> 0 | S13: =+BUS!BA124+BUS!BB124+BUS!BC124 -> 0 | T13: =+BUS!BD124+BUS!BE124+BUS!BF124 -> 0 | U13: =+BUS!BG124+BUS!BH124+BUS!BI124 -> 0 | V13: =+BUS!BJ124+BUS!BK124+BUS!BL124 -> 0 | W13: =+BUS!BM124+BUS!BN124+BUS!BO124 -> 0 | X13: =+BUS!BP124+BUS!BQ124+BUS!BR124 -> 0 | Y13: =+BUS!BS124+BUS!BT124+BUS!BU124 -> 0 | Z13: =+BUS!BV124+BUS!BW124+BUS!BX124 -> 0 | AA13: =+BUS!BY124+BUS!BZ124+BUS!CA124 -> 0 | AB13: =+BUS!CB124+BUS!CC124+BUS!CD124 -> 0 | AC13: =+BUS!CE124+BUS!CF124+BUS!CG124 -> 0 | AD13: =+BUS!CH124+BUS!CI124+BUS!CJ124 -> 0 | AE13: =+BUS!CK124+BUS!CL124+BUS!CM124 -> 0 | AF13: =+BUS!CN124+BUS!CO124+BUS!CP124 -> 0 | AG13: =+BUS!CQ124+BUS!CR124+BUS!CS124 -> 0 | AH13: =+BUS!CT124+BUS!CU124+BUS!CV124 -> 0 | AI13: =+BUS!CW124+BUS!CX124+BUS!CY124 -> 0 | AJ13: =+BUS!CZ124+BUS!DA124+BUS!DB124 -> 0 | AK13: =SUM(B13:AJ13) -> 0
A14: 11 | B14: =+BUS!B125+BUS!C125+BUS!D125 -> 0 | C14: =+BUS!E125+BUS!F125+BUS!G125 -> 0 | D14: =+BUS!H125+BUS!I125+BUS!J125 -> 0 | E14: =+BUS!K125+BUS!L125+BUS!M125 -> 0 | F14: =+BUS!N125+BUS!O125+BUS!P125 -> 0 | G14: =+BUS!Q125+BUS!R125+BUS!S125 -> 0 | H14: =+BUS!T125+BUS!U125+BUS!V125 -> 0 | I14: =+BUS!W125+BUS!X125+BUS!Y125 -> 0 | J14: =+BUS!Z125+BUS!AA125+BUS!AB125 -> 0 | K14: =+BUS!AC125+BUS!AD125+BUS!AE125 -> 0 | L14: =+BUS!AF125+BUS!AG125+BUS!AH125 -> 0 | M14: =+BUS!AI125+BUS!AJ125+BUS!AK125 -> 0 | N14: =+BUS!AL125+BUS!AM125+BUS!AN125 -> 0 | O14: =+BUS!AO125+BUS!AP125+BUS!AQ125 -> 0 | P14: =+BUS!AR125+BUS!AS125+BUS!AT125 -> 0 | Q14: =+BUS!AU125+BUS!AV125+BUS!AW125 -> 0 | R14: =+BUS!AX125+BUS!AY125+BUS!AZ125 -> 0 | S14: =+BUS!BA125+BUS!BB125+BUS!BC125 -> 0 | T14: =+BUS!BD125+BUS!BE125+BUS!BF125 -> 0 | U14: =+BUS!BG125+BUS!BH125+BUS!BI125 -> 0 | V14: =+BUS!BJ125+BUS!BK125+BUS!BL125 -> 0 | W14: =+BUS!BM125+BUS!BN125+BUS!BO125 -> 0 | X14: =+BUS!BP125+BUS!BQ125+BUS!BR125 -> 0 | Y14: =+BUS!BS125+BUS!BT125+BUS!BU125 -> 0 | Z14: =+BUS!BV125+BUS!BW125+BUS!BX125 -> 0 | AA14: =+BUS!BY125+BUS!BZ125+BUS!CA125 -> 0 | AB14: =+BUS!CB125+BUS!CC125+BUS!CD125 -> 0 | AC14: =+BUS!CE125+BUS!CF125+BUS!CG125 -> 0 | AD14: =+BUS!CH125+BUS!CI125+BUS!CJ125 -> 0 | AE14: =+BUS!CK125+BUS!CL125+BUS!CM125 -> 0 | AF14: =+BUS!CN125+BUS!CO125+BUS!CP125 -> 0 | AG14: =+BUS!CQ125+BUS!CR125+BUS!CS125 -> 0 | AH14: =+BUS!CT125+BUS!CU125+BUS!CV125 -> 0 | AI14: =+BUS!CW125+BUS!CX125+BUS!CY125 -> 0 | AJ14: =+BUS!CZ125+BUS!DA125+BUS!DB125 -> 0 | AK14: =SUM(B14:AJ14) -> 0
A15: 12 | B15: =+BUS!B126+BUS!C126+BUS!D126 -> 0 | C15: =+BUS!E126+BUS!F126+BUS!G126 -> 0 | D15: =+BUS!H126+BUS!I126+BUS!J126 -> 0 | E15: =+BUS!K126+BUS!L126+BUS!M126 -> 0 | F15: =+BUS!N126+BUS!O126+BUS!P126 -> 0 | G15: =+BUS!Q126+BUS!R126+BUS!S126 -> 0 | H15: =+BUS!T126+BUS!U126+BUS!V126 -> 0 | I15: =+BUS!W126+BUS!X126+BUS!Y126 -> 0 | J15: =+BUS!Z126+BUS!AA126+BUS!AB126 -> 0 | K15: =+BUS!AC126+BUS!AD126+BUS!AE126 -> 0 | L15: =+BUS!AF126+BUS!AG126+BUS!AH126 -> 0 | M15: =+BUS!AI126+BUS!AJ126+BUS!AK126 -> 0 | N15: =+BUS!AL126+BUS!AM126+BUS!AN126 -> 0 | O15: =+BUS!AO126+BUS!AP126+BUS!AQ126 -> 0 | P15: =+BUS!AR126+BUS!AS126+BUS!AT126 -> 0 | Q15: =+BUS!AU126+BUS!AV126+BUS!AW126 -> 0 | R15: =+BUS!AX126+BUS!AY126+BUS!AZ126 -> 0 | S15: =+BUS!BA126+BUS!BB126+BUS!BC126 -> 0 | T15: =+BUS!BD126+BUS!BE126+BUS!BF126 -> 0 | U15: =+BUS!BG126+BUS!BH126+BUS!BI126 -> 0 | V15: =+BUS!BJ126+BUS!BK126+BUS!BL126 -> 0 | W15: =+BUS!BM126+BUS!BN126+BUS!BO126 -> 0 | X15: =+BUS!BP126+BUS!BQ126+BUS!BR126 -> 0 | Y15: =+BUS!BS126+BUS!BT126+BUS!BU126 -> 0 | Z15: =+BUS!BV126+BUS!BW126+BUS!BX126 -> 0 | AA15: =+BUS!BY126+BUS!BZ126+BUS!CA126 -> 0 | AB15: =+BUS!CB126+BUS!CC126+BUS!CD126 -> 0 | AC15: =+BUS!CE126+BUS!CF126+BUS!CG126 -> 0 | AD15: =+BUS!CH126+BUS!CI126+BUS!CJ126 -> 0 | AE15: =+BUS!CK126+BUS!CL126+BUS!CM126 -> 0 | AF15: =+BUS!CN126+BUS!CO126+BUS!CP126 -> 0 | AG15: =+BUS!CQ126+BUS!CR126+BUS!CS126 -> 0 | AH15: =+BUS!CT126+BUS!CU126+BUS!CV126 -> 0 | AI15: =+BUS!CW126+BUS!CX126+BUS!CY126 -> 0 | AJ15: =+BUS!CZ126+BUS!DA126+BUS!DB126 -> 0 | AK15: =SUM(B15:AJ15) -> 0
... A34: 31 | B34: =+BUS!B145+BUS!C145+BUS!D145 -> 0 | C34: =+BUS!E145+BUS!F145+BUS!G145 -> 0 | D34: =+BUS!H145+BUS!I145+BUS!J145 -> 0 | E34: =+BUS!K145+BUS!L145+BUS!M145 -> 0 | F34: =+BUS!N145+BUS!O145+BUS!P145 -> 0 | G34: =+BUS!Q145+BUS!R145+BUS!S145 -> 0 | H34: =+BUS!T145+BUS!U145+BUS!V145 -> 0 | I34: =+BUS!W145+BUS!X145+BUS!Y145 -> 0 | J34: =+BUS!Z145+BUS!AA145+BUS!AB145 -> 0 | K34: =+BUS!AC145+BUS!AD145+BUS!AE145 -> 0 | L34: =+BUS!AF145+BUS!AG145+BUS!AH145 -> 0 | M34: =+BUS!AI145+BUS!AJ145+BUS!AK145 -> 0 | N34: =+BUS!AL145+BUS!AM145+BUS!AN145 -> 0 | O34: =+BUS!AO145+BUS!AP145+BUS!AQ145 -> 0 | P34: =+BUS!AR145+BUS!AS145+BUS!AT145 -> 0 | Q34: =+BUS!AU145+BUS!AV145+BUS!AW145 -> 0 | R34: =+BUS!AX145+BUS!AY145+BUS!AZ145 -> 0 | S34: =+BUS!BA145+BUS!BB145+BUS!BC145 -> 0 | T34: =+BUS!BD145+BUS!BE145+BUS!BF145 -> 0 | U34: =+BUS!BG145+BUS!BH145+BUS!BI145 -> 0 | V34: =+BUS!BJ145+BUS!BK145+BUS!BL145 -> 0 | W34: =+BUS!BM145+BUS!BN145+BUS!BO145 -> 0 | X34: =+BUS!BP145+BUS!BQ145+BUS!BR145 -> 0 | Y34: =+BUS!BS145+BUS!BT145+BUS!BU145 -> 0 | Z34: =+BUS!BV145+BUS!BW145+BUS!BX145 -> 0 | AA34: =+BUS!BY145+BUS!BZ145+BUS!CA145 -> 0 | AB34: =+BUS!CB145+BUS!CC145+BUS!CD145 -> 0 | AC34: =+BUS!CE145+BUS!CF145+BUS!CG145 -> 0 | AD34: =+BUS!CH145+BUS!CI145+BUS!CJ145 -> 0 | AE34: =+BUS!CK145+BUS!CL145+BUS!CM145 -> 0 | AF34: =+BUS!CN145+BUS!CO145+BUS!CP145 -> 0 | AG34: =+BUS!CQ145+BUS!CR145+BUS!CS145 -> 0 | AH34: =+BUS!CT145+BUS!CU145+BUS!CV145 -> 0 | AI34: =+BUS!CW145+BUS!CX145+BUS!CY145 -> 0 | AJ34: =+BUS!CZ145+BUS!DA145+BUS!DB145 -> 0 | AK34: =SUM(B34:AJ34) -> 0
B35: =SUM(B3:B34) -> 0 | C35: =SUM(C3:C34) -> 0 | D35: =SUM(D3:D34) -> 0 | E35: =SUM(E3:E34) -> 0 | F35: =SUM(F3:F34) -> 0 | G35: =SUM(G3:G34) -> 0 | H35: =SUM(H3:H34) -> 0 | I35: =SUM(I3:I34) -> 0 | ... AK35: =SUM(AK3:AK34) -> 0
B37: Nbr Des Passagers "15 DA" | M37: 0 | S37: TOTAL RECETTE MOIS | AA37: =+AK35 -> 0
B38: Nbr Des Passagers "20 DA" | M38: =+BUS!DC182 -> 0
B39: Nbr Des Passagers "25 DA" | M39: =+BUS!DD182 -> 0 | S39: TAUX DE REMPLISSAGE | AA39: =+M42/'RETAION-BUS'!M40 -> #DIV/0!
B40: Nbr Des Passagers "30 DA" | M40: =+BUS!DE182 -> 0
B41: Nbr Des Passagers "40 DA" | M41: 0 | S41: Taux de Réalisation / Mois | AA41: =+AA37/3386987 -> 0
B42: Total Nbr Des Passagers | M42: =SUM(M37:P41) -> 0
A47: JOUR | B47: A01 | C47: A02 | D47: A03 | E47: A04 | F47: A05 | G47: A06 | H47: A07 | I47: A08 | J47: A09 | K47: A10 | L47: A11 | M47: A12 | N47: A13 | O47: A14 | P47: A15 | Q47: A16 | R47: A17 | S47: A18 | T47: A19 | U47: A20 | V47: A21 | W47: A22 | X47: A23 | Y47: A24 | Z47: A25 | AA47: A26 | AB47: A27 | AC47: A28 | AD47: A29 | AE47: A30 | AF47: A31 | AG47: A32 | AH47: A33 | AI47: A34 | AJ47: A35 | AK47: TOTAL
A48: 1 | B48: =+BUS!B151+BUS!C151+BUS!D151 -> 0 | C48: =+BUS!E151+BUS!F151+BUS!G151 -> 0 | D48: =+BUS!H151+BUS!I151+BUS!J151 -> 0 | E48: =+BUS!K151+BUS!L151+BUS!M151 -> 0 | F48: =+BUS!N151+BUS!O151+BUS!P151 -> 0 | G48: =+BUS!Q151+BUS!R151+BUS!S151 -> 0 | H48: =+BUS!T151+BUS!U151+BUS!V151 -> 0 | I48: =+BUS!W151+BUS!X151+BUS!Y151 -> 0 | J48: =+BUS!Z151+BUS!AA151+BUS!AB151 -> 0 | K48: =+BUS!AC151+BUS!AD151+BUS!AE151 -> 0 | L48: =+BUS!AF151+BUS!AG151+BUS!AH151 -> 0 | M48: =+BUS!AI151+BUS!AJ151+BUS!AK151 -> 0 | N48: =+BUS!AL151+BUS!AM151+BUS!AN151 -> 0 | O48: =+BUS!AO151+BUS!AP151+BUS!AQ151 -> 0 | P48: =+BUS!AR151+BUS!AS151+BUS!AT151 -> 0 | Q48: =+BUS!AU151+BUS!AV151+BUS!AW151 -> 0 | R48: =+BUS!AX151+BUS!AY151+BUS!AZ151 -> 0 | S48: =+BUS!BA151+BUS!BB151+BUS!BC151 -> 0 | T48: =+BUS!BD151+BUS!BE151+BUS!BF151 -> 0 | U48: =+BUS!BG151+BUS!BH151+BUS!BI151 -> 0 | V48: =+BUS!BJ151+BUS!BK151+BUS!BL151 -> 0 | W48: =+BUS!BM151+BUS!BN151+BUS!BO151 -> 0 | X48: =+BUS!BP151+BUS!BQ151+BUS!BR151 -> 0 | Y48: =+BUS!BS151+BUS!BT151+BUS!BU151 -> 0 | Z48: =+BUS!BV151+BUS!BW151+BUS!BX151 -> 0 | AA48: =+BUS!BY151+BUS!BZ151+BUS!CA151 -> 0 | AB48: =+BUS!CB151+BUS!CC151+BUS!CD151 -> 0 | AC48: =+BUS!CE151+BUS!CF151+BUS!CG151 -> 0 | AD48: =+BUS!CH151+BUS!CI151+BUS!CJ151 -> 0 | AE48: =+BUS!CK151+BUS!CL151+BUS!CM151 -> 0 | AF48: =+BUS!CN151+BUS!CO151+BUS!CP151 -> 0 | AG48: =+BUS!CQ151+BUS!CR151+BUS!CS151 -> 0 | AH48: =+BUS!CT151+BUS!CU151+BUS!CV151 -> 0 | AI48: =+BUS!CW151+BUS!CX151+BUS!CY151 -> 0 | AJ48: =+BUS!CZ151+BUS!DA151+BUS!DB151 -> 0 | AK48: =SUM(B48:AJ48) -> 0
